Workbook

Sheet Trang bìa
E1: TẬP ĐOÀN CÔNG NGHIỆP VIỄN THÔNG QUÂN ĐỘI
E2: TỔNG CÔNG TY GIẢI PHÁP DOANH NGHIỆP VIETTEL
A9: <VOFFICE KHA>
A10: TÀI LIỆU KỊCH BẢN KIỂM THỬ CHỨC NĂNG
A11: NV_06 - Xem file văn bản trả lời nhắc việc
C16: Mã dự án | D16: :
C17: Mã tài liệu | D17: :
A20: Người lập:
C21: <Tên người nhập> | F21: <Ngày lập>
C22: <Chức vụ>
A26: Người kiểm tra:
C27: <Tên người kiểm tra | F27: <Ngày kiểm tra>
C28: <Chức vụ>
A32: Người phê duyệt:
C33: <Tên người phê duyệt> | F33: <Ngày phê duyệt>
C34: <Chức vụ>
A37: BẢNG GHI NHẬN THAY ĐỔI TÀI LIỆU
A39: Ngày thay đổi | B39: Vị trí thay đổi | C39: Lý do | D39: Nguồn gốc | E39: Phiên bản cũ | F39: Mô tả thay đổi | G39: Phiên bản mới

Sheet Giới thiệu
A1: GIỚI THIỆU
A3: 1 - Giới thiệu
A8: 2 - Tài liệu tham khảo
A9: STT | B9: Tên tài liệu | C9: Tên file | D9: Phiên bản | E9: Đường dẫn
A10: 1
A15: 3 - Môi trường kiểm thử
A16: STT | B16: Trình duyệt | C16: Phiên bản | E16: Viết tắt
B17: Chrome | C17: 131 | E17: C
B18: Microsoft Edge | C18: 131 | E18: ME
B19: Cấu hình server test
B20: CPU: 4G, Duecore, Ram 8G, HDD: 320G
B21: Tool test | C21: Phiên bản | E21: Mục đích

Sheet Tổng hợp
A1: TỔNG HỢP KẾT QUẢ
A3: STT | B3: Tên màn hình/chức năng | C3: Số trường hợp kiểm thử đạt (P) | D3: Số trường hợp kiểm thử không đạt (F) | E3: Số trường hợp kiểm thử đang xem xét (PE) | F3: Số trường hợp kiểm thử chưa thực hiện | G3: Tổng số trường hợp kiểm thử | H3: Tỉ lệ trường hợp kiểm thử đạt (%P) | I3: Tỉ lệ trường hợp kiểm thử không đạt (%F) | J3: Tỉ lệ trường hợp kiểm thử đã thực hiện (%Cover)
A4: 1 | B4: ='NV_06_Web'!D2&" - Web" | C4: ='NV_06_Web'!D4 | D4: ='NV_06_Web'!D5 | E4: ='NV_06_Web'!D6 | F4: ='NV_06_Web'!D7 | G4: ='NV_06_Web'!D8 | H4: =IFERROR(C4/G4,0) | I4: =IFERROR(D4/G4,0) | J4: =IFERROR((C4+D4)/G4,0)
A5: 2 | B5: ='NV_06_App'!D2&" - App" | C5: ='NV_06_App'!D4 | D5: ='NV_06_App'!D5 | E5: ='NV_06_App'!D6 | F5: ='NV_06_App'!D7 | G5: ='NV_06_App'!D8 | H5: =IFERROR(C5/G5,0) | I5: =IFERROR(D5/G5,0) | J5: =IFERROR((C5+D5)/G5,0)
A12: Total | C12: =SUM(C4:C11) | D12: =SUM(D4:D11) | E12: =SUM(E4:E11) | F12: =SUM(F4:F11) | G12: =SUM(G4:G11) | H12: =IFERROR(C12/G12,0) | I12: =IFERROR(D12/G12,0) | J12: =IFERROR((C12+D12)/G12,0)

Sheet NV_06_Web
C1: KỊCH BẢN KIỂM THỬ *
C2: Tên màn hình/Tên chức năng | D2: NV_06_Xem file văn bản trả lời nhắc việc
C3: Mã trường hợp kiểm thử | D3: NV_06
C4: Số trường hợp kiểm thử đạt (P) | D4: =COUNTIF($E$13:$E$64,"P")
C5: Số trường hợp kiểm thử không đạt (F) | D5: =COUNTIF($E$13:$E$64,"F")
C6: Số trường hợp kiểm thử đang xem xét (PE) | D6: =COUNTIF($Q$13:$Q$64,"PE")
C7: Số trường hợp kiểm thử chưa thực hiện | D7: =D8-D4-D5-D6
C8: Tổng số trường hợp kiểm thử | D8: =COUNTA($Q$13:$Q$64)
A10: Mã trường hợp kiểm thử | B10: Mục đích kiểm thử | C10: Các bước thực hiện | D10: Kết quả mong muốn | E10: PC | H10: Firefox | K10: <Tên trình duyệt 3> | N10: <Tên trình duyệt 4> | Q10: Kết quả hiện tại | R10: Mã lỗi | S10: Ghi chú
E11: Lần 1 | F11: Lần 2 | G11: Lần 3 | H11: Lần 1 | I11: Lần 2 | J11: Lần 3 | K11: Lần 1 | L11: Lần 2 | M11: Lần 3 | N11: Lần 1 | O11: Lần 2 | P11: Lần 3
B12: NV_06_Xem file văn bản trả lời nhắc việc_Web
B13: A: Các bước thực hiện Pre- condition: 1. Truy cập link: <link môi trường test> 2. Login acc có vai trò lãnh đạo (at_ld/123), Văn thư (at_vt/123), Chuyên viên ( at_cv/123) — cùng thuộc đơn vị A (đơn vị giao nhắc việc). Cần thêm (người dùng điền tài khoản thật của môi trường test): - <TK_VT_X>: văn thư đơn vị X (đơn vị được nhắc, chủ trì) - <TK_VT_Y>: văn thư đơn vị Y (đơn vị được nhắc, phối hợp) - <TK_CV_X>: chuyên viên đơn vị X (dùng làm người được gán xử lý) - <TK_KLQ>: tài khoản không liên quan tới các nhắc việc dưới đây 3. Phạm vi: VĂN BẢN ĐI >> Theo dõi nhắc việc >> lưới "Danh sách nhắc việc" >> cột mới "File văn bản" (cuối bảng) và popup "Xem thêm" 4. Dữ liệu chuẩn bị (tạo bằng chức năng Văn bản đi / Tạo nhắc việc / Trả lời nhắc việc, ghi lại số ký hiệu và tên file để dùng lại): - VBG1: văn bản đi do đơn vị A ban hành, đã chuyển cho đơn vị X, Y, Z - NV1: at_vt tạo nhắc việc trên VBG1 (VĂN BẢN ĐI >> Theo dõi nhắc việc >> nút +): CT = đơn vị X, PH = đơn vị Y và đơn vị Z, hạn = hôm nay + 7 ngày, lãnh đạo theo dõi = at_ld, chuyên viên theo dõi = at_cv - VBTL1: văn bản đi do đơn vị X ban hành, có đúng 1 file "VBTL1_file_chinh.pdf", đã chuyển cho đơn vị A. <TK_VT_X> trả lời NV1 (nhập nội dung + chọn văn bản trả lời VBTL1) → dòng X ở "Chờ duyệt" - VBTL2: văn bản đi do đơn vị Y ban hành, có 4 file: 1 file chính tên dài trên 60 ký tự (ví dụ "VBTL2_bao_cao_ket_qua_thuc_hien_nhac_viec_quy_III_nam_2026_ban_chinh_thuc.pdf") + 3 phụ lục "VBTL2_PL1.docx", "VBTL2_PL2.xlsx", "VBTL2_PL3.pdf", đã chuyển cho đơn vị A. <TK_VT_Y> trả lời NV1 kèm VBTL2 → dòng Y ở "Chờ duyệt" - Dòng đơn vị Z của NV1: chưa trả lời → "Chưa trả lời" - NV2: at_vt tạo trên VBG1, CT = đơn vị X. <TK_VT_X> trả lời chỉ nhập nội dung, KHÔNG chọn văn bản trả lời → "Chờ duyệt" - NV3: at_vt tạo trên VBG1, CT = đơn vị X. <TK_VT_X> trả lời kèm VBTL3 (1 file "VBTL3.pdf", đã chuyển cho đơn vị A), at_ld Phê duyệt → "Hoàn thành" - NV4: at_vt tạo trên VBG1, CT = đơn vị X. <TK_VT_X> trả lời kèm VBTL4 (1 file), at_ld Trả lại (nhập ý kiến) → "Xử lý lại" - NV5: at_vt tạo trên VBG1, CT = đơn vị X, gán người xử lý = <TK_CV_X>. <TK_CV_X> trả lời kèm VBTL5 (1 file "VBTL5.pdf", đã chuyển cho đơn vị A) → "Chờ duyệt" - VBTL6 (chỉ khi hệ thống cho ban hành văn bản không có file): văn bản đi đơn vị X không có file nào; NV6 CT = đơn vị X, <TK_VT_X> trả lời kèm VBTL6 - Nhóm "Giao đi/Theo dõi" >> "Tất cả" của at_vt có ít nhất 51 dòng (dùng lại nhắc việc sẵn có trên môi trường test, càng nhiều dòng có văn bản trả lời càng tốt) - Lưu ý: at_cv KHÔNG có tên trong danh sách người nhận VBTL1, VBTL2 (văn bản trả lời chỉ chuyển cho đơn vị A) B: Mô tả chức năng Bổ sung cột "File văn bản" ở cuối lưới "Danh sách nhắc việc" (sau cột "Ngày tạo"). Mỗi dòng hiện file của đúng văn bản đang ở cột "Số VB trả lời" cùng dòng: tên file chính kèm biểu tượng tải; văn bản có hơn 1 file thì có thêm liên kết "Xem thêm" mở popup liệt kê mọi file. Bấm tên file để xem, bấm biểu tượng để tải file gốc. Dòng không kèm văn bản trả lời hoặc văn bản không có file thì ô để trống. Cột hiện ở mọi nhóm, mọi tab; ai thấy dòng thì xem / tải được file. Cột "Số VB trả lời" giữ nguyên. C: Các bảng tác động - REMINDER_REPLY (chỉ đọc) - REMINDER_DOCUMENT_RELATIONS, OBJECT_TYPE = 2 = văn bản trả lời (chỉ đọc) - DOCUMENT (chỉ đọc) - FILES_ATTACHMENT, cột DOCUMENT_ID, NAME, TYPE, FILE_ORDER (chỉ đọc) Không thêm bảng, không thêm cột, không cần migration.
A14: =IF(AND(C14="",C14=""),"",$D$3&"_"&ROW()-12-COUNTBLANK($C$13:C14)) | B14: Giao diện (Phần này viết các trường hợp kiểm thử cho giao diên chung và các giao diện cho các control)
A15: =IF(AND(C15="",C15=""),"",$D$3&"_"&ROW()-12-COUNTBLANK($C$13:C15)) | B15: Kiểm tra tổng thể giao diện lưới sau khi thêm cột | C15: 1. Đăng nhập vào at_vt/123 2. VĂN BẢN ĐI >> Theo dõi nhắc việc >> Giao đi/Theo dõi >> Tất cả 3. Kiểm tra title, bố cục, font chữ, cỡ chữ, màu chữ, chính tả của lưới "Danh sách nhắc việc" | D15: 1. Bố cục - Form được bố trí hợp lý và dễ sử dụng 2. Font chữ và màu chữ: - Các text sử dụng cùng 1 loại font chữ, cỡ chữ - Màu chữ giống giao diện prototype 3. Chính tả: Không có lỗi về chính tả, cấu trúc câu, ngữ pháp trên màn hình | Q15: =IF(OR(IF(G15="",IF(F15="",IF(E15="","",E15),F15),G15)="F",IF(J15="",IF(I15="",IF(H15="","",H15),I15),J15)="F",IF(M15="",IF(L15="",IF(K15="","",K15),L15),M15)="F",IF(P15="",IF(O15="",IF(N15="","",N15),O15),P15)="F")=TRUE,"F",IF(OR(IF(G15="",IF(F15="",IF(E15="","",E15),F15),G15)="PE",IF(J15="",IF(I15="",IF(H15="","",H15),I15),J15)="PE",IF(M15="",IF(L15="",IF(K15="","",K15),L15),M15)="PE",IF(P15="",IF(O15="",IF(N15="","",N15),O15),P15)="PE")=TRUE,"PE",IF(AND(IF(G15="",IF(F15="",IF(E15="","",E15),F15),G15)="",IF(J15="",IF(I15="",IF(H15="","",H15),I15),J15)="",IF(M15="",IF(L15="",IF(K15="","",K15),L15),M15)="",IF(P15="",IF(O15="",IF(N15="","",N15),O15),P15)="")=TRUE,"","P")))
A16: =IF(AND(C16="",C16=""),"",$D$3&"_"&ROW()-12-COUNTBLANK($C$13:C16)) | B16: Kiểm tra vị trí và nhãn của cột File văn bản | C16: 1. Đăng nhập vào at_vt/123 2. VĂN BẢN ĐI >> Theo dõi nhắc việc >> Giao đi/Theo dõi >> Tất cả 3. Đếm số cột và kiểm tra tên, thứ tự các cột từ trái sang phải | D16: Lưới hiển thị 10 cột theo thứ tự: Thao tác · Số, Ký hiệu · Trích yếu · Nội dung giao việc · Đơn vị xử lý · Trạng thái · Số VB trả lời · Hạn xử lý · Ngày tạo · File văn bản. Cột mới tên đúng "File văn bản", nằm cuối cùng, sau cột "Ngày tạo". 9 cột cũ giữ nguyên tên và thứ tự; cột "Số VB trả lời" vẫn ở vị trí thứ 7. | Q16: =IF(OR(IF(G16="",IF(F16="",IF(E16="","",E16),F16),G16)="F",IF(J16="",IF(I16="",IF(H16="","",H16),I16),J16)="F",IF(M16="",IF(L16="",IF(K16="","",K16),L16),M16)="F",IF(P16="",IF(O16="",IF(N16="","",N16),O16),P16)="F")=TRUE,"F",IF(OR(IF(G16="",IF(F16="",IF(E16="","",E16),F16),G16)="PE",IF(J16="",IF(I16="",IF(H16="","",H16),I16),J16)="PE",IF(M16="",IF(L16="",IF(K16="","",K16),L16),M16)="PE",IF(P16="",IF(O16="",IF(N16="","",N16),O16),P16)="PE")=TRUE,"PE",IF(AND(IF(G16="",IF(F16="",IF(E16="","",E16),F16),G16)="",IF(J16="",IF(I16="",IF(H16="","",H16),I16),J16)="",IF(M16="",IF(L16="",IF(K16="","",K16),L16),M16)="",IF(P16="",IF(O16="",IF(N16="","",N16),O16),P16)="")=TRUE,"","P"))) | S16: BR-01. Nhãn cột theo TBD-03 (mặc định "File văn bản")
A17: =IF(AND(C17="",C17=""),"",$D$3&"_"&ROW()-12-COUNTBLANK($C$13:C17)) | B17: Kiểm tra hiển thị ô khi văn bản trả lời có đúng 1 file | C17: 1. Đăng nhập vào at_vt/123 2. VĂN BẢN ĐI >> Theo dõi nhắc việc >> Giao đi/Theo dõi >> Tất cả 3. Tìm dòng NV1 - đơn vị X 4. Quan sát ô cột "File văn bản" | D17: Ô hiển thị tên file "VBTL1_file_chinh.pdf" dạng liên kết, kèm biểu tượng tải ngay cạnh tên file. KHÔNG hiển thị liên kết "Xem thêm". | Q17: =IF(OR(IF(G17="",IF(F17="",IF(E17="","",E17),F17),G17)="F",IF(J17="",IF(I17="",IF(H17="","",H17),I17),J17)="F",IF(M17="",IF(L17="",IF(K17="","",K17),L17),M17)="F",IF(P17="",IF(O17="",IF(N17="","",N17),O17),P17)="F")=TRUE,"F",IF(OR(IF(G17="",IF(F17="",IF(E17="","",E17),F17),G17)="PE",IF(J17="",IF(I17="",IF(H17="","",H17),I17),J17)="PE",IF(M17="",IF(L17="",IF(K17="","",K17),L17),M17)="PE",IF(P17="",IF(O17="",IF(N17="","",N17),O17),P17)="PE")=TRUE,"PE",IF(AND(IF(G17="",IF(F17="",IF(E17="","",E17),F17),G17)="",IF(J17="",IF(I17="",IF(H17="","",H17),I17),J17)="",IF(M17="",IF(L17="",IF(K17="","",K17),L17),M17)="",IF(P17="",IF(O17="",IF(N17="","",N17),O17),P17)="")=TRUE,"","P"))) | S17: BR-03, AC-03
A18: =IF(AND(C18="",C18=""),"",$D$3&"_"&ROW()-12-COUNTBLANK($C$13:C18)) | B18: Kiểm tra hiển thị ô khi văn bản trả lời có nhiều file | C18: 1. Đăng nhập vào at_vt/123 2. VĂN BẢN ĐI >> Theo dõi nhắc việc >> Giao đi/Theo dõi >> Tất cả 3. Tìm dòng NV1 - đơn vị Y 4. Quan sát ô cột "File văn bản" | D18: Ô hiển thị tên file chính của VBTL2 kèm biểu tượng tải. Dưới tên file có liên kết "Xem thêm", chữ nghiêng, gạch chân (giống cột File văn bản ở danh sách văn bản đi). Ô KHÔNG liệt kê cả 4 file ra ngoài lưới. | Q18: =IF(OR(IF(G18="",IF(F18="",IF(E18="","",E18),F18),G18)="F",IF(J18="",IF(I18="",IF(H18="","",H18),I18),J18)="F",IF(M18="",IF(L18="",IF(K18="","",K18),L18),M18)="F",IF(P18="",IF(O18="",IF(N18="","",N18),O18),P18)="F")=TRUE,"F",IF(OR(IF(G18="",IF(F18="",IF(E18="","",E18),F18),G18)="PE",IF(J18="",IF(I18="",IF(H18="","",H18),I18),J18)="PE",IF(M18="",IF(L18="",IF(K18="","",K18),L18),M18)="PE",IF(P18="",IF(O18="",IF(N18="","",N18),O18),P18)="PE")=TRUE,"PE",IF(AND(IF(G18="",IF(F18="",IF(E18="","",E18),F18),G18)="",IF(J18="",IF(I18="",IF(H18="","",H18),I18),J18)="",IF(M18="",IF(L18="",IF(K18="","",K18),L18),M18)="",IF(P18="",IF(O18="",IF(N18="","",N18),O18),P18)="")=TRUE,"","P"))) | S18: BR-03, AC-04
A19: =IF(AND(C19="",C19=""),"",$D$3&"_"&ROW()-12-COUNTBLANK($C$13:C19)) | B19: Kiểm tra tên file dài | C19: 1. Đăng nhập vào at_vt/123 2. VĂN BẢN ĐI >> Theo dõi nhắc việc >> Giao đi/Theo dõi >> Tất cả 3. Tìm dòng NV1 - đơn vị Y 4. Quan sát tên file chính của VBTL2 trong ô | D19: Tên file dài tự xuống dòng trong ô, hiển thị đủ cả phần đuôi ".pdf". Không bị cắt mất chữ, không đè lên cột khác, biểu tượng tải vẫn nhìn thấy và bấm được. | Q19: =IF(OR(IF(G19="",IF(F19="",IF(E19="","",E19),F19),G19)="F",IF(J19="",IF(I19="",IF(H19="","",H19),I19),J19)="F",IF(M19="",IF(L19="",IF(K19="","",K19),L19),M19)="F",IF(P19="",IF(O19="",IF(N19="","",N19),O19),P19)="F")=TRUE,"F",IF(OR(IF(G19="",IF(F19="",IF(E19="","",E19),F19),G19)="PE",IF(J19="",IF(I19="",IF(H19="","",H19),I19),J19)="PE",IF(M19="",IF(L19="",IF(K19="","",K19),L19),M19)="PE",IF(P19="",IF(O19="",IF(N19="","",N19),O19),P19)="PE")=TRUE,"PE",IF(AND(IF(G19="",IF(F19="",IF(E19="","",E19),F19),G19)="",IF(J19="",IF(I19="",IF(H19="","",H19),I19),J19)="",IF(M19="",IF(L19="",IF(K19="","",K19),L19),M19)="",IF(P19="",IF(O19="",IF(N19="","",N19),O19),P19)="")=TRUE,"","P"))) | S19: NFR-06
A20: =IF(AND(C20="",C20=""),"",$D$3&"_"&ROW()-12-COUNTBLANK($C$13:C20)) | B20: Kiểm tra lưới không tràn ngang ở độ phân giải 1366 px | C20: 1. Đăng nhập vào at_vt/123 2. Đặt cửa sổ trình duyệt rộng 1366 px 3. VĂN BẢN ĐI >> Theo dõi nhắc việc >> Giao đi/Theo dõi >> Tất cả 4. Quan sát lưới | D20: Lưới hiển thị đủ 10 cột trong khung, không xuất hiện thanh cuộn ngang của trang. Các cột "Trạng thái", "Hạn xử lý", "Ngày tạo" không bị thu hẹp tới mức cắt chữ. | Q20: =IF(OR(IF(G20="",IF(F20="",IF(E20="","",E20),F20),G20)="F",IF(J20="",IF(I20="",IF(H20="","",H20),I20),J20)="F",IF(M20="",IF(L20="",IF(K20="","",K20),L20),M20)="F",IF(P20="",IF(O20="",IF(N20="","",N20),O20),P20)="F")=TRUE,"F",IF(OR(IF(G20="",IF(F20="",IF(E20="","",E20),F20),G20)="PE",IF(J20="",IF(I20="",IF(H20="","",H20),I20),J20)="PE",IF(M20="",IF(L20="",IF(K20="","",K20),L20),M20)="PE",IF(P20="",IF(O20="",IF(N20="","",N20),O20),P20)="PE")=TRUE,"PE",IF(AND(IF(G20="",IF(F20="",IF(E20="","",E20),F20),G20)="",IF(J20="",IF(I20="",IF(H20="","",H20),I20),J20)="",IF(M20="",IF(L20="",IF(K20="","",K20),L20),M20)="",IF(P20="",IF(O20="",IF(N20="","",N20),O20),P20)="")=TRUE,"","P"))) | S20: NFR-06
A21: =IF(AND(C21="",C21=""),"",$D$3&"_"&ROW()-12-COUNTBLANK($C$13:C21)) | B21: Kiểm tra giao diện popup Xem thêm | C21: 1. Đăng nhập vào at_vt/123 2. VĂN BẢN ĐI >> Theo dõi nhắc việc >> Giao đi/Theo dõi >> Tất cả 3. Tìm dòng NV1 - đơn vị Y 4. Bấm "Xem thêm" ở cột "File văn bản" 5. Quan sát popup | D21: Popup mở tại chỗ, tiêu đề kèm số file "(4)". Liệt kê đủ 4 file của VBTL2, đánh số thứ tự 1 đến 4; mỗi dòng có tên file dạng liên kết và biểu tượng tải. Góc phải tiêu đề có nút đóng (×). | Q21: =IF(OR(IF(G21="",IF(F21="",IF(E21="","",E21),F21),G21)="F",IF(J21="",IF(I21="",IF(H21="","",H21),I21),J21)="F",IF(M21="",IF(L21="",IF(K21="","",K21),L21),M21)="F",IF(P21="",IF(O21="",IF(N21="","",N21),O21),P21)="F")=TRUE,"F",IF(OR(IF(G21="",IF(F21="",IF(E21="","",E21),F21),G21)="PE",IF(J21="",IF(I21="",IF(H21="","",H21),I21),J21)="PE",IF(M21="",IF(L21="",IF(K21="","",K21),L21),M21)="PE",IF(P21="",IF(O21="",IF(N21="","",N21),O21),P21)="PE")=TRUE,"PE",IF(AND(IF(G21="",IF(F21="",IF(E21="","",E21),F21),G21)="",IF(J21="",IF(I21="",IF(H21="","",H21),I21),J21)="",IF(M21="",IF(L21="",IF(K21="","",K21),L21),M21)="",IF(P21="",IF(O21="",IF(N21="","",N21),O21),P21)="")=TRUE,"","P"))) | S21: BR-03, UI-05, AC-04
A22: =IF(AND(C22="",C22=""),"",$D$3&"_"&ROW()-12-COUNTBLANK($C$13:C22)) | B22: Kiểm tra di chuyển bằng phím Tab / Shift+Tab và Enter | C22: 1. Đăng nhập vào at_vt/123 2. VĂN BẢN ĐI >> Theo dõi nhắc việc >> Giao đi/Theo dõi >> Tất cả 3. Nhấn Tab liên tục tới liên kết tên file ở cột "File văn bản" của dòng NV1 - đơn vị X 4. Nhấn Shift+Tab để quay lại phần tử trước 5. Nhấn Tab tới lại liên kết tên file rồi nhấn Enter | D22: Con trỏ di chuyển lần lượt qua các phần tử theo thứ tự từ trái sang phải, trên xuống dưới; Shift+Tab đi ngược lại. Nhấn Enter trên liên kết tên file thì mở file giống như bấm chuột. | Q22: =IF(OR(IF(G22="",IF(F22="",IF(E22="","",E22),F22),G22)="F",IF(J22="",IF(I22="",IF(H22="","",H22),I22),J22)="F",IF(M22="",IF(L22="",IF(K22="","",K22),L22),M22)="F",IF(P22="",IF(O22="",IF(N22="","",N22),O22),P22)="F")=TRUE,"F",IF(OR(IF(G22="",IF(F22="",IF(E22="","",E22),F22),G22)="PE",IF(J22="",IF(I22="",IF(H22="","",H22),I22),J22)="PE",IF(M22="",IF(L22="",IF(K22="","",K22),L22),M22)="PE",IF(P22="",IF(O22="",IF(N22="","",N22),O22),P22)="PE")=TRUE,"PE",IF(AND(IF(G22="",IF(F22="",IF(E22="","",E22),F22),G22)="",IF(J22="",IF(I22="",IF(H22="","",H22),I22),J22)="",IF(M22="",IF(L22="",IF(K22="","",K22),L22),M22)="",IF(P22="",IF(O22="",IF(N22="","",N22),O22),P22)="")=TRUE,"","P"))) | S22: ui-ux-rule: bộ common GUI
A23: =IF(AND(C23="",C23=""),"",$D$3&"_"&ROW()-12-COUNTBLANK($C$13:C23)) | B23: Kiểm tra phóng to / thu nhỏ trình duyệt | C23: 1. Đăng nhập vào at_vt/123 2. VĂN BẢN ĐI >> Theo dõi nhắc việc >> Giao đi/Theo dõi >> Tất cả 3. Nhấn Ctrl+= 2 lần, quan sát lưới 4. Nhấn Ctrl+- 4 lần, quan sát lưới | D23: Ở mọi mức phóng, cột "File văn bản" vẫn hiển thị đúng vị trí cuối bảng, tên file và biểu tượng tải không bị vỡ hay chồng lên nhau. | Q23: =IF(OR(IF(G23="",IF(F23="",IF(E23="","",E23),F23),G23)="F",IF(J23="",IF(I23="",IF(H23="","",H23),I23),J23)="F",IF(M23="",IF(L23="",IF(K23="","",K23),L23),M23)="F",IF(P23="",IF(O23="",IF(N23="","",N23),O23),P23)="F")=TRUE,"F",IF(OR(IF(G23="",IF(F23="",IF(E23="","",E23),F23),G23)="PE",IF(J23="",IF(I23="",IF(H23="","",H23),I23),J23)="PE",IF(M23="",IF(L23="",IF(K23="","",K23),L23),M23)="PE",IF(P23="",IF(O23="",IF(N23="","",N23),O23),P23)="PE")=TRUE,"PE",IF(AND(IF(G23="",IF(F23="",IF(E23="","",E23),F23),G23)="",IF(J23="",IF(I23="",IF(H23="","",H23),I23),J23)="",IF(M23="",IF(L23="",IF(K23="","",K23),L23),M23)="",IF(P23="",IF(O23="",IF(N23="","",N23),O23),P23)="")=TRUE,"","P"))) | S23: ui-ux-rule: bộ common GUI
A24: =IF(AND(C24="",C24=""),"",$D$3&"_"&ROW()-12-COUNTBLANK($C$13:C24)) | B24: Kiểm tra cột hiển thị đúng khi đổi số dòng / trang và chuyển trang | C24: 1. Đăng nhập vào at_vt/123 2. VĂN BẢN ĐI >> Theo dõi nhắc việc >> Giao đi/Theo dõi >> Tất cả 3. Đổi số dòng / trang lần lượt sang 20 rồi 50 4. Chuyển sang trang 2 5. Quan sát cột "File văn bản" ở mỗi lần đổi | D24: Ở mọi trang và mọi lựa chọn 10 / 20 / 50 dòng, cột "File văn bản" đều hiển thị. Mỗi dòng hiện file của đúng văn bản ở cột "Số VB trả lời" cùng dòng, không còn file của trang trước. | Q24: =IF(OR(IF(G24="",IF(F24="",IF(E24="","",E24),F24),G24)="F",IF(J24="",IF(I24="",IF(H24="","",H24),I24),J24)="F",IF(M24="",IF(L24="",IF(K24="","",K24),L24),M24)="F",IF(P24="",IF(O24="",IF(N24="","",N24),O24),P24)="F")=TRUE,"F",IF(OR(IF(G24="",IF(F24="",IF(E24="","",E24),F24),G24)="PE",IF(J24="",IF(I24="",IF(H24="","",H24),I24),J24)="PE",IF(M24="",IF(L24="",IF(K24="","",K24),L24),M24)="PE",IF(P24="",IF(O24="",IF(N24="","",N24),O24),P24)="PE")=TRUE,"PE",IF(AND(IF(G24="",IF(F24="",IF(E24="","",E24),F24),G24)="",IF(J24="",IF(I24="",IF(H24="","",H24),I24),J24)="",IF(M24="",IF(L24="",IF(K24="","",K24),L24),M24)="",IF(P24="",IF(O24="",IF(N24="","",N24),O24),P24)="")=TRUE,"","P"))) | S24: EC-11
A25: =IF(AND(C25="",C25=""),"",$D$3&"_"&ROW()-12-COUNTBLANK($C$13:C25)) | B25: Chức năng (Phần này viết các trường hợp kiểm thử kiểm tra các ràng buộc trong cơ sở dữ liệu và cho các luồng nghiệp vụ trong tài liệu giải pháp, tích hợp với các chức năng khác)
A26: =IF(AND(C26="",C26=""),"",$D$3&"_"&ROW()-12-COUNTBLANK($C$13:C26)) | B26: Hiển thị file theo từng dòng
A27: =IF(AND(C27="",C27=""),"",$D$3&"_"&ROW()-12-COUNTBLANK($C$13:C27)) | B27: Kiểm tra mỗi dòng hiện file của đúng văn bản trả lời cùng dòng | C27: 1. Đăng nhập vào at_vt/123 2. VĂN BẢN ĐI >> Theo dõi nhắc việc >> Giao đi/Theo dõi >> Tất cả 3. Nhập trích yếu của VBG1 vào ô tìm kiếm nhanh >> bấm tìm 4. Xem 3 dòng của NV1: đơn vị X, đơn vị Y, đơn vị Z 5. So sánh cột "Số VB trả lời" và cột "File văn bản" của từng dòng | D27: Dòng X: Số VB trả lời = VBTL1, File văn bản = "VBTL1_file_chinh.pdf". Dòng Y: Số VB trả lời = VBTL2, File văn bản = file chính của VBTL2 + "Xem thêm". Dòng Z: cả hai cột để trống. Không dòng nào hiện file của dòng khác, không dòng nào hiện file của văn bản giao việc VBG1. | Q27: =IF(OR(IF(G27="",IF(F27="",IF(E27="","",E27),F27),G27)="F",IF(J27="",IF(I27="",IF(H27="","",H27),I27),J27)="F",IF(M27="",IF(L27="",IF(K27="","",K27),L27),M27)="F",IF(P27="",IF(O27="",IF(N27="","",N27),O27),P27)="F")=TRUE,"F",IF(OR(IF(G27="",IF(F27="",IF(E27="","",E27),F27),G27)="PE",IF(J27="",IF(I27="",IF(H27="","",H27),I27),J27)="PE",IF(M27="",IF(L27="",IF(K27="","",K27),L27),M27)="PE",IF(P27="",IF(O27="",IF(N27="","",N27),O27),P27)="PE")=TRUE,"PE",IF(AND(IF(G27="",IF(F27="",IF(E27="","",E27),F27),G27)="",IF(J27="",IF(I27="",IF(H27="","",H27),I27),J27)="",IF(M27="",IF(L27="",IF(K27="","",K27),L27),M27)="",IF(P27="",IF(O27="",IF(N27="","",N27),O27),P27)="")=TRUE,"","P"))) | S27: BR-02, AC-05
A28: =IF(AND(C28="",C28=""),"",$D$3&"_"&ROW()-12-COUNTBLANK($C$13:C28)) | B28: Kiểm tra dòng chưa trả lời | C28: 1. Đăng nhập vào at_vt/123 2. VĂN BẢN ĐI >> Theo dõi nhắc việc >> Giao đi/Theo dõi >> Tất cả 3. Tìm dòng NV1 - đơn vị Z (trạng thái "Chưa trả lời") 4. Quan sát ô cột "File văn bản" | D28: Ô để trống hoàn toàn: không có tên file, không có biểu tượng tải, không có "Xem thêm", không hiện chữ thay thế. | Q28: =IF(OR(IF(G28="",IF(F28="",IF(E28="","",E28),F28),G28)="F",IF(J28="",IF(I28="",IF(H28="","",H28),I28),J28)="F",IF(M28="",IF(L28="",IF(K28="","",K28),L28),M28)="F",IF(P28="",IF(O28="",IF(N28="","",N28),O28),P28)="F")=TRUE,"F",IF(OR(IF(G28="",IF(F28="",IF(E28="","",E28),F28),G28)="PE",IF(J28="",IF(I28="",IF(H28="","",H28),I28),J28)="PE",IF(M28="",IF(L28="",IF(K28="","",K28),L28),M28)="PE",IF(P28="",IF(O28="",IF(N28="","",N28),O28),P28)="PE")=TRUE,"PE",IF(AND(IF(G28="",IF(F28="",IF(E28="","",E28),F28),G28)="",IF(J28="",IF(I28="",IF(H28="","",H28),I28),J28)="",IF(M28="",IF(L28="",IF(K28="","",K28),L28),M28)="",IF(P28="",IF(O28="",IF(N28="","",N28),O28),P28)="")=TRUE,"","P"))) | S28: BR-05, AC-07
A29: =IF(AND(C29="",C29=""),"",$D$3&"_"&ROW()-12-COUNTBLANK($C$13:C29)) | B29: Kiểm tra dòng Xử lý lại sau khi bị trả lại | C29: 1. Đăng nhập vào at_vt/123 2. VĂN BẢN ĐI >> Theo dõi nhắc việc >> Giao đi/Theo dõi >> Tất cả 3. Tìm dòng NV4 - đơn vị X (trạng thái "Xử lý lại") 4. Quan sát cột "Số VB trả lời" và "File văn bản" | D29: Cột "Số VB trả lời" trống (văn bản trả lời đã bị gỡ khi trả lại). Ô "File văn bản" để trống, không còn file của VBTL4. | Q29: =IF(OR(IF(G29="",IF(F29="",IF(E29="","",E29),F29),G29)="F",IF(J29="",IF(I29="",IF(H29="","",H29),I29),J29)="F",IF(M29="",IF(L29="",IF(K29="","",K29),L29),M29)="F",IF(P29="",IF(O29="",IF(N29="","",N29),O29),P29)="F")=TRUE,"F",IF(OR(IF(G29="",IF(F29="",IF(E29="","",E29),F29),G29)="PE",IF(J29="",IF(I29="",IF(H29="","",H29),I29),J29)="PE",IF(M29="",IF(L29="",IF(K29="","",K29),L29),M29)="PE",IF(P29="",IF(O29="",IF(N29="","",N29),O29),P29)="PE")=TRUE,"PE",IF(AND(IF(G29="",IF(F29="",IF(E29="","",E29),F29),G29)="",IF(J29="",IF(I29="",IF(H29="","",H29),I29),J29)="",IF(M29="",IF(L29="",IF(K29="","",K29),L29),M29)="",IF(P29="",IF(O29="",IF(N29="","",N29),O29),P29)="")=TRUE,"","P"))) | S29: BR-05, AC-07
A30: =IF(AND(C30="",C30=""),"",$D$3&"_"&ROW()-12-COUNTBLANK($C$13:C30)) | B30: Kiểm tra trả lời không kèm văn bản | C30: 1. Đăng nhập vào at_vt/123 2. VĂN BẢN ĐI >> Theo dõi nhắc việc >> Giao đi/Theo dõi >> Tất cả 3. Tìm dòng NV2 - đơn vị X (trạng thái "Chờ duyệt", trả lời không chọn văn bản) 4. Quan sát ô cột "File văn bản" | D30: Ô để trống: không tên file, không biểu tượng tải, không "Xem thêm", không hiện chữ thay thế. | Q30: =IF(OR(IF(G30="",IF(F30="",IF(E30="","",E30),F30),G30)="F",IF(J30="",IF(I30="",IF(H30="","",H30),I30),J30)="F",IF(M30="",IF(L30="",IF(K30="","",K30),L30),M30)="F",IF(P30="",IF(O30="",IF(N30="","",N30),O30),P30)="F")=TRUE,"F",IF(OR(IF(G30="",IF(F30="",IF(E30="","",E30),F30),G30)="PE",IF(J30="",IF(I30="",IF(H30="","",H30),I30),J30)="PE",IF(M30="",IF(L30="",IF(K30="","",K30),L30),M30)="PE",IF(P30="",IF(O30="",IF(N30="","",N30),O30),P30)="PE")=TRUE,"PE",IF(AND(IF(G30="",IF(F30="",IF(E30="","",E30),F30),G30)="",IF(J30="",IF(I30="",IF(H30="","",H30),I30),J30)="",IF(M30="",IF(L30="",IF(K30="","",K30),L30),M30)="",IF(P30="",IF(O30="",IF(N30="","",N30),O30),P30)="")=TRUE,"","P"))) | S30: BR-05
A31: =IF(AND(C31="",C31=""),"",$D$3&"_"&ROW()-12-COUNTBLANK($C$13:C31)) | B31: Kiểm tra văn bản trả lời không có file nào | C31: 1. Đăng nhập vào at_vt/123 2. VĂN BẢN ĐI >> Theo dõi nhắc việc >> Giao đi/Theo dõi >> Tất cả 3. Tìm dòng NV6 - đơn vị X 4. Quan sát ô cột "File văn bản" | D31: Cột "Số VB trả lời" hiện VBTL6; ô "File văn bản" để trống, không biểu tượng tải, không "Xem thêm". | Q31: =IF(OR(IF(G31="",IF(F31="",IF(E31="","",E31),F31),G31)="F",IF(J31="",IF(I31="",IF(H31="","",H31),I31),J31)="F",IF(M31="",IF(L31="",IF(K31="","",K31),L31),M31)="F",IF(P31="",IF(O31="",IF(N31="","",N31),O31),P31)="F")=TRUE,"F",IF(OR(IF(G31="",IF(F31="",IF(E31="","",E31),F31),G31)="PE",IF(J31="",IF(I31="",IF(H31="","",H31),I31),J31)="PE",IF(M31="",IF(L31="",IF(K31="","",K31),L31),M31)="PE",IF(P31="",IF(O31="",IF(N31="","",N31),O31),P31)="PE")=TRUE,"PE",IF(AND(IF(G31="",IF(F31="",IF(E31="","",E31),F31),G31)="",IF(J31="",IF(I31="",IF(H31="","",H31),I31),J31)="",IF(M31="",IF(L31="",IF(K31="","",K31),L31),M31)="",IF(P31="",IF(O31="",IF(N31="","",N31),O31),P31)="")=TRUE,"","P"))) | S31: BR-05, EC-02. Chỉ chạy được nếu hệ thống cho ban hành văn bản không có file; không dựng được VBTL6 thì ghi BLOCKED kèm lý do
A32: =IF(AND(C32="",C32=""),"",$D$3&"_"&ROW()-12-COUNTBLANK($C$13:C32)) | B32: Kiểm tra dòng đã Hoàn thành vẫn hiện file | C32: 1. Đăng nhập vào at_vt/123 2. VĂN BẢN ĐI >> Theo dõi nhắc việc >> Giao đi/Theo dõi >> Đã hoàn thành 3. Tìm dòng NV3 - đơn vị X 4. Quan sát ô cột "File văn bản" | D32: Ô hiển thị tên file "VBTL3.pdf" kèm biểu tượng tải, giống dòng Chờ duyệt. | Q32: =IF(OR(IF(G32="",IF(F32="",IF(E32="","",E32),F32),G32)="F",IF(J32="",IF(I32="",IF(H32="","",H32),I32),J32)="F",IF(M32="",IF(L32="",IF(K32="","",K32),L32),M32)="F",IF(P32="",IF(O32="",IF(N32="","",N32),O32),P32)="F")=TRUE,"F",IF(OR(IF(G32="",IF(F32="",IF(E32="","",E32),F32),G32)="PE",IF(J32="",IF(I32="",IF(H32="","",H32),I32),J32)="PE",IF(M32="",IF(L32="",IF(K32="","",K32),L32),M32)="PE",IF(P32="",IF(O32="",IF(N32="","",N32),O32),P32)="PE")=TRUE,"PE",IF(AND(IF(G32="",IF(F32="",IF(E32="","",E32),F32),G32)="",IF(J32="",IF(I32="",IF(H32="","",H32),I32),J32)="",IF(M32="",IF(L32="",IF(K32="","",K32),L32),M32)="",IF(P32="",IF(O32="",IF(N32="","",N32),O32),P32)="")=TRUE,"","P"))) | S32: BR-02, BR-04
A33: =IF(AND(C33="",C33=""),"",$D$3&"_"&ROW()-12-COUNTBLANK($C$13:C33)) | B33: Hiển thị ở mọi nhóm, mọi tab và mọi đường vào
A34: =IF(AND(C34="",C34=""),"",$D$3&"_"&ROW()-12-COUNTBLANK($C$13:C34)) | B34: Kiểm tra nhóm Giao đi/Theo dõi - các tab | C34: 1. Đăng nhập vào at_vt/123 2. VĂN BẢN ĐI >> Theo dõi nhắc việc >> Giao đi/Theo dõi >> Chưa hoàn thành, tìm dòng NV1 - đơn vị X 3. Giao đi/Theo dõi >> Đã hoàn thành, tìm dòng NV3 - đơn vị X 4. Giao đi/Theo dõi >> Tất cả, tìm lại hai dòng trên | D34: Ở cả 3 tab, lưới đều có cột "File văn bản". Dòng NV1 - X hiện "VBTL1_file_chinh.pdf"; dòng NV3 - X hiện "VBTL3.pdf"; nội dung giống nhau giữa các tab. | Q34: =IF(OR(IF(G34="",IF(F34="",IF(E34="","",E34),F34),G34)="F",IF(J34="",IF(I34="",IF(H34="","",H34),I34),J34)="F",IF(M34="",IF(L34="",IF(K34="","",K34),L34),M34)="F",IF(P34="",IF(O34="",IF(N34="","",N34),O34),P34)="F")=TRUE,"F",IF(OR(IF(G34="",IF(F34="",IF(E34="","",E34),F34),G34)="PE",IF(J34="",IF(I34="",IF(H34="","",H34),I34),J34)="PE",IF(M34="",IF(L34="",IF(K34="","",K34),L34),M34)="PE",IF(P34="",IF(O34="",IF(N34="","",N34),O34),P34)="PE")=TRUE,"PE",IF(AND(IF(G34="",IF(F34="",IF(E34="","",E34),F34),G34)="",IF(J34="",IF(I34="",IF(H34="","",H34),I34),J34)="",IF(M34="",IF(L34="",IF(K34="","",K34),L34),M34)="",IF(P34="",IF(O34="",IF(N34="","",N34),O34),P34)="")=TRUE,"","P"))) | S34: BR-04, AC-06
A35: =IF(AND(C35="",C35=""),"",$D$3&"_"&ROW()-12-COUNTBLANK($C$13:C35)) | B35: Kiểm tra nhóm Cần xử lý của lãnh đạo theo dõi | C35: 1. Đăng nhập vào at_ld/123 2. VĂN BẢN ĐI >> Theo dõi nhắc việc >> Cần xử lý >> Chờ duyệt, tìm dòng NV1 - đơn vị X và NV1 - đơn vị Y 3. Cần xử lý >> Hoàn thành, tìm dòng NV3 - đơn vị X 4. Cần xử lý >> Tất cả, tìm lại các dòng trên | D35: Ở mọi tab, cột "File văn bản" hiển thị; dòng NV1 - X hiện "VBTL1_file_chinh.pdf", dòng NV1 - Y hiện file chính của VBTL2 + "Xem thêm", dòng NV3 - X hiện "VBTL3.pdf". | Q35: =IF(OR(IF(G35="",IF(F35="",IF(E35="","",E35),F35),G35)="F",IF(J35="",IF(I35="",IF(H35="","",H35),I35),J35)="F",IF(M35="",IF(L35="",IF(K35="","",K35),L35),M35)="F",IF(P35="",IF(O35="",IF(N35="","",N35),O35),P35)="F")=TRUE,"F",IF(OR(IF(G35="",IF(F35="",IF(E35="","",E35),F35),G35)="PE",IF(J35="",IF(I35="",IF(H35="","",H35),I35),J35)="PE",IF(M35="",IF(L35="",IF(K35="","",K35),L35),M35)="PE",IF(P35="",IF(O35="",IF(N35="","",N35),O35),P35)="PE")=TRUE,"PE",IF(AND(IF(G35="",IF(F35="",IF(E35="","",E35),F35),G35)="",IF(J35="",IF(I35="",IF(H35="","",H35),I35),J35)="",IF(M35="",IF(L35="",IF(K35="","",K35),L35),M35)="",IF(P35="",IF(O35="",IF(N35="","",N35),O35),P35)="")=TRUE,"","P"))) | S35: BR-04, AC-03, AC-06
A36: =IF(AND(C36="",C36=""),"",$D$3&"_"&ROW()-12-COUNTBLANK($C$13:C36)) | B36: Kiểm tra nhóm Cần xử lý của đơn vị được nhắc | C36: 1. Đăng nhập vào <TK_VT_X> 2. VĂN BẢN ĐI >> Theo dõi nhắc việc >> Cần xử lý >> Chờ duyệt 3. Tìm dòng NV1 của đơn vị mình 4. Bấm tên file "VBTL1_file_chinh.pdf" | D36: Lưới có cột "File văn bản"; dòng NV1 hiện "VBTL1_file_chinh.pdf" kèm biểu tượng tải. Bấm tên file mở được file văn bản trả lời của đơn vị mình. | Q36: =IF(OR(IF(G36="",IF(F36="",IF(E36="","",E36),F36),G36)="F",IF(J36="",IF(I36="",IF(H36="","",H36),I36),J36)="F",IF(M36="",IF(L36="",IF(K36="","",K36),L36),M36)="F",IF(P36="",IF(O36="",IF(N36="","",N36),O36),P36)="F")=TRUE,"F",IF(OR(IF(G36="",IF(F36="",IF(E36="","",E36),F36),G36)="PE",IF(J36="",IF(I36="",IF(H36="","",H36),I36),J36)="PE",IF(M36="",IF(L36="",IF(K36="","",K36),L36),M36)="PE",IF(P36="",IF(O36="",IF(N36="","",N36),O36),P36)="PE")=TRUE,"PE",IF(AND(IF(G36="",IF(F36="",IF(E36="","",E36),F36),G36)="",IF(J36="",IF(I36="",IF(H36="","",H36),I36),J36)="",IF(M36="",IF(L36="",IF(K36="","",K36),L36),M36)="",IF(P36="",IF(O36="",IF(N36="","",N36),O36),P36)="")=TRUE,"","P"))) | S36: BR-04, BR-07, AC-11
A37: =IF(AND(C37="",C37=""),"",$D$3&"_"&ROW()-12-COUNTBLANK($C$13:C37)) | B37: Kiểm tra kết quả tìm kiếm nhanh và tìm kiếm nâng cao | C37: 1. Đăng nhập vào at_vt/123 2. VĂN BẢN ĐI >> Theo dõi nhắc việc >> Giao đi/Theo dõi >> Tất cả 3. Nhập số ký hiệu VBG1 vào ô tìm kiếm nhanh >> bấm tìm, quan sát cột "File văn bản" 4. Bấm "Tìm kiếm nâng cao" >> chọn Đơn vị chủ trì = đơn vị X, chọn khoảng Ngày tạo chứa ngày tạo NV1 >> Tìm kiếm 5. Quan sát cột "File văn bản" của kết quả | D37: Ở cả hai cách tìm, lưới kết quả có cột "File văn bản". Dòng NV1 - X hiện "VBTL1_file_chinh.pdf"; các dòng khác hiện đúng file của văn bản trả lời cùng dòng. | Q37: =IF(OR(IF(G37="",IF(F37="",IF(E37="","",E37),F37),G37)="F",IF(J37="",IF(I37="",IF(H37="","",H37),I37),J37)="F",IF(M37="",IF(L37="",IF(K37="","",K37),L37),M37)="F",IF(P37="",IF(O37="",IF(N37="","",N37),O37),P37)="F")=TRUE,"F",IF(OR(IF(G37="",IF(F37="",IF(E37="","",E37),F37),G37)="PE",IF(J37="",IF(I37="",IF(H37="","",H37),I37),J37)="PE",IF(M37="",IF(L37="",IF(K37="","",K37),L37),M37)="PE",IF(P37="",IF(O37="",IF(N37="","",N37),O37),P37)="PE")=TRUE,"PE",IF(AND(IF(G37="",IF(F37="",IF(E37="","",E37),F37),G37)="",IF(J37="",IF(I37="",IF(H37="","",H37),I37),J37)="",IF(M37="",IF(L37="",IF(K37="","",K37),L37),M37)="",IF(P37="",IF(O37="",IF(N37="","",N37),O37),P37)="")=TRUE,"","P"))) | S37: BR-04, AC-06
A38: =IF(AND(C38="",C38=""),"",$D$3&"_"&ROW()-12-COUNTBLANK($C$13:C38)) | B38: Kiểm tra mở màn từ ô Nhắc việc ở trang chủ | C38: 1. Đăng nhập vào at_ld/123 2. Trang chủ >> ô "Nhắc việc" >> bấm ô "Chờ duyệt" 3. Tìm dòng NV1 - đơn vị X trong màn vừa mở | D38: Màn Theo dõi nhắc việc mở đúng tab Chờ duyệt, lưới có cột "File văn bản", dòng NV1 - X hiện "VBTL1_file_chinh.pdf". | Q38: =IF(OR(IF(G38="",IF(F38="",IF(E38="","",E38),F38),G38)="F",IF(J38="",IF(I38="",IF(H38="","",H38),I38),J38)="F",IF(M38="",IF(L38="",IF(K38="","",K38),L38),M38)="F",IF(P38="",IF(O38="",IF(N38="","",N38),O38),P38)="F")=TRUE,"F",IF(OR(IF(G38="",IF(F38="",IF(E38="","",E38),F38),G38)="PE",IF(J38="",IF(I38="",IF(H38="","",H38),I38),J38)="PE",IF(M38="",IF(L38="",IF(K38="","",K38),L38),M38)="PE",IF(P38="",IF(O38="",IF(N38="","",N38),O38),P38)="PE")=TRUE,"PE",IF(AND(IF(G38="",IF(F38="",IF(E38="","",E38),F38),G38)="",IF(J38="",IF(I38="",IF(H38="","",H38),I38),J38)="",IF(M38="",IF(L38="",IF(K38="","",K38),L38),M38)="",IF(P38="",IF(O38="",IF(N38="","",N38),O38),P38)="")=TRUE,"","P"))) | S38: BR-04, AC-06
A39: =IF(AND(C39="",C39=""),"",$D$3&"_"&ROW()-12-COUNTBLANK($C$13:C39)) | B39: Kiểm tra mở danh sách từ Báo cáo nhắc việc | C39: 1. Đăng nhập vào at_vt/123 2. VĂN BẢN ĐI >> Báo cáo nhắc việc 3. Bấm vào ô số của đơn vị X (cột có nhắc việc NV1) 4. Quan sát lưới danh sách vừa mở | D39: Danh sách mở ra có cột "File văn bản"; dòng NV1 - X hiện "VBTL1_file_chinh.pdf". | Q39: =IF(OR(IF(G39="",IF(F39="",IF(E39="","",E39),F39),G39)="F",IF(J39="",IF(I39="",IF(H39="","",H39),I39),J39)="F",IF(M39="",IF(L39="",IF(K39="","",K39),L39),M39)="F",IF(P39="",IF(O39="",IF(N39="","",N39),O39),P39)="F")=TRUE,"F",IF(OR(IF(G39="",IF(F39="",IF(E39="","",E39),F39),G39)="PE",IF(J39="",IF(I39="",IF(H39="","",H39),I39),J39)="PE",IF(M39="",IF(L39="",IF(K39="","",K39),L39),M39)="PE",IF(P39="",IF(O39="",IF(N39="","",N39),O39),P39)="PE")=TRUE,"PE",IF(AND(IF(G39="",IF(F39="",IF(E39="","",E39),F39),G39)="",IF(J39="",IF(I39="",IF(H39="","",H39),I39),J39)="",IF(M39="",IF(L39="",IF(K39="","",K39),L39),M39)="",IF(P39="",IF(O39="",IF(N39="","",N39),O39),P39)="")=TRUE,"","P"))) | S39: Phạm vi 1.4 mục 4 của đặc tả: ⚠ chưa xác minh báo cáo mở cùng lưới, kiểm ở vòng kiểm lớp 3
A40: =IF(AND(C40="",C40=""),"",$D$3&"_"&ROW()-12-COUNTBLANK($C$13:C40)) | B40: Xem và tải file
A41: =IF(AND(C41="",C41=""),"",$D$3&"_"&ROW()-12-COUNTBLANK($C$13:C41)) | B41: Kiểm tra bấm tên file để xem | C41: 1. Đăng nhập vào at_vt/123 2. VĂN BẢN ĐI >> Theo dõi nhắc việc >> Giao đi/Theo dõi >> Tất cả 3. Tìm dòng NV1 - đơn vị X 4. Bấm tên file "VBTL1_file_chinh.pdf" ở cột "File văn bản" | D41: Hệ thống mở trình xem file, hiển thị đúng nội dung file VBTL1_file_chinh.pdf. Không mở popup chi tiết văn bản, không mở popup chi tiết nhắc việc. | Q41: =IF(OR(IF(G41="",IF(F41="",IF(E41="","",E41),F41),G41)="F",IF(J41="",IF(I41="",IF(H41="","",H41),I41),J41)="F",IF(M41="",IF(L41="",IF(K41="","",K41),L41),M41)="F",IF(P41="",IF(O41="",IF(N41="","",N41),O41),P41)="F")=TRUE,"F",IF(OR(IF(G41="",IF(F41="",IF(E41="","",E41),F41),G41)="PE",IF(J41="",IF(I41="",IF(H41="","",H41),I41),J41)="PE",IF(M41="",IF(L41="",IF(K41="","",K41),L41),M41)="PE",IF(P41="",IF(O41="",IF(N41="","",N41),O41),P41)="PE")=TRUE,"PE",IF(AND(IF(G41="",IF(F41="",IF(E41="","",E41),F41),G41)="",IF(J41="",IF(I41="",IF(H41="","",H41),I41),J41)="",IF(M41="",IF(L41="",IF(K41="","",K41),L41),M41)="",IF(P41="",IF(O41="",IF(N41="","",N41),O41),P41)="")=TRUE,"","P"))) | S41: BR-06, AC-08
...

Sheet NV_06_App
C1: KỊCH BẢN KIỂM THỬ *
C2: Tên màn hình/Tên chức năng | D2: NV_06_Xem file văn bản trả lời nhắc việc
C3: Mã trường hợp kiểm thử | D3: NV_06
C4: Số trường hợp kiểm thử đạt (P) | D4: =COUNTIF($E$13:$E$30,"P")
C5: Số trường hợp kiểm thử không đạt (F) | D5: =COUNTIF($E$13:$E$30,"F")
C6: Số trường hợp kiểm thử đang xem xét (PE) | D6: =COUNTIF($Q$13:$Q$30,"PE")
C7: Số trường hợp kiểm thử chưa thực hiện | D7: =D8-D4-D5-D6
C8: Tổng số trường hợp kiểm thử | D8: =COUNTA($Q$13:$Q$30)
A10: Mã trường hợp kiểm thử | B10: Mục đích kiểm thử | C10: Các bước thực hiện | D10: Kết quả mong muốn | E10: Mobile | H10: Tablet | K10: <Tên trình duyệt 3> | N10: <Tên trình duyệt 4> | Q10: Kết quả hiện tại | R10: Mã lỗi | S10: Ghi chú
E11: Lần 1 | F11: Lần 2 | G11: Lần 3 | H11: Lần 1 | I11: Lần 2 | J11: Lần 3 | K11: Lần 1 | L11: Lần 2 | M11: Lần 3 | N11: Lần 1 | O11: Lần 2 | P11: Lần 3
B12: NV_06_Xem file văn bản trả lời nhắc việc_App
B13: A: Các bước thực hiện Pre- condition: 1. Cài ứng dụng di động bản có hỗ trợ hiển thị file văn bản trả lời, trỏ về môi trường test: <link môi trường test> 2. Login acc có vai trò lãnh đạo (at_ld/123), Văn thư (at_vt/123), Chuyên viên ( at_cv/123) — cùng thuộc đơn vị A (đơn vị giao nhắc việc). Cần thêm (người dùng điền tài khoản thật của môi trường test): - <TK_VT_X>: văn thư đơn vị X (đơn vị được nhắc, chủ trì) - <TK_VT_Y>: văn thư đơn vị Y (đơn vị được nhắc, phối hợp) - <TK_CV_X>: chuyên viên đơn vị X (dùng làm người được gán xử lý) - <TK_KLQ>: tài khoản không liên quan tới các nhắc việc dưới đây 3. Phạm vi: ứng dụng di động >> Nhắc việc >> danh sách nhắc việc >> thông tin file văn bản trả lời của từng dòng (giao diện theo TBD-01) 4. Dữ liệu chuẩn bị (tạo bằng chức năng Văn bản đi / Tạo nhắc việc / Trả lời nhắc việc, ghi lại số ký hiệu và tên file để dùng lại): - VBG1: văn bản đi do đơn vị A ban hành, đã chuyển cho đơn vị X, Y, Z - NV1: at_vt tạo nhắc việc trên VBG1 (VĂN BẢN ĐI >> Theo dõi nhắc việc >> nút +): CT = đơn vị X, PH = đơn vị Y và đơn vị Z, hạn = hôm nay + 7 ngày, lãnh đạo theo dõi = at_ld, chuyên viên theo dõi = at_cv - VBTL1: văn bản đi do đơn vị X ban hành, có đúng 1 file "VBTL1_file_chinh.pdf", đã chuyển cho đơn vị A. <TK_VT_X> trả lời NV1 (nhập nội dung + chọn văn bản trả lời VBTL1) → dòng X ở "Chờ duyệt" - VBTL2: văn bản đi do đơn vị Y ban hành, có 4 file: 1 file chính tên dài trên 60 ký tự (ví dụ "VBTL2_bao_cao_ket_qua_thuc_hien_nhac_viec_quy_III_nam_2026_ban_chinh_thuc.pdf") + 3 phụ lục "VBTL2_PL1.docx", "VBTL2_PL2.xlsx", "VBTL2_PL3.pdf", đã chuyển cho đơn vị A. <TK_VT_Y> trả lời NV1 kèm VBTL2 → dòng Y ở "Chờ duyệt" - Dòng đơn vị Z của NV1: chưa trả lời → "Chưa trả lời" - NV2: at_vt tạo trên VBG1, CT = đơn vị X. <TK_VT_X> trả lời chỉ nhập nội dung, KHÔNG chọn văn bản trả lời → "Chờ duyệt" - NV3: at_vt tạo trên VBG1, CT = đơn vị X. <TK_VT_X> trả lời kèm VBTL3 (1 file "VBTL3.pdf", đã chuyển cho đơn vị A), at_ld Phê duyệt → "Hoàn thành" - NV4: at_vt tạo trên VBG1, CT = đơn vị X. <TK_VT_X> trả lời kèm VBTL4 (1 file), at_ld Trả lại (nhập ý kiến) → "Xử lý lại" - NV5: at_vt tạo trên VBG1, CT = đơn vị X, gán người xử lý = <TK_CV_X>. <TK_CV_X> trả lời kèm VBTL5 (1 file "VBTL5.pdf", đã chuyển cho đơn vị A) → "Chờ duyệt" - VBTL6 (chỉ khi hệ thống cho ban hành văn bản không có file): văn bản đi đơn vị X không có file nào; NV6 CT = đơn vị X, <TK_VT_X> trả lời kèm VBTL6 - Lưu ý: at_cv KHÔNG có tên trong danh sách người nhận VBTL1, VBTL2 (văn bản trả lời chỉ chuyển cho đơn vị A) B: Mô tả chức năng Bổ sung cột "File văn bản" ở cuối lưới "Danh sách nhắc việc" (sau cột "Ngày tạo"). Mỗi dòng hiện file của đúng văn bản đang ở cột "Số VB trả lời" cùng dòng: tên file chính kèm biểu tượng tải; văn bản có hơn 1 file thì có thêm liên kết "Xem thêm" mở popup liệt kê mọi file. Bấm tên file để xem, bấm biểu tượng để tải file gốc. Dòng không kèm văn bản trả lời hoặc văn bản không có file thì ô để trống. Cột hiện ở mọi nhóm, mọi tab; ai thấy dòng thì xem / tải được file. Cột "Số VB trả lời" giữ nguyên. C: Các bảng tác động - REMINDER_REPLY (chỉ đọc) - REMINDER_DOCUMENT_RELATIONS, OBJECT_TYPE = 2 = văn bản trả lời (chỉ đọc) - DOCUMENT (chỉ đọc) - FILES_ATTACHMENT, cột DOCUMENT_ID, NAME, TYPE, FILE_ORDER (chỉ đọc) Không thêm bảng, không thêm cột, không cần migration.
A14: =IF(AND(C14="",C14=""),"",$D$3&"_"&ROW()-12-COUNTBLANK($C$13:C14)) | B14: Giao diện (Phần này viết các trường hợp kiểm thử cho giao diên chung và các giao diện cho các control)
A15: =IF(AND(C15="",C15=""),"",$D$3&"_"&ROW()-12-COUNTBLANK($C$13:C15)) | B15: Kiểm tra tổng thể giao diện danh sách nhắc việc trên ứng dụng | C15: 1. Đăng nhập ứng dụng di động bằng at_vt/123 2. Nhắc việc >> danh sách nhắc việc (đường đi theo thiết kế màn hình di động đã duyệt) 3. Kiểm tra bố cục, font chữ, chính tả | D15: 1. Bố cục - Form được bố trí hợp lý và dễ sử dụng 2. Font chữ và màu chữ: - Các text sử dụng cùng 1 loại font chữ, cỡ chữ - Màu chữ giống giao diện prototype 3. Chính tả: Không có lỗi về chính tả, cấu trúc câu, ngữ pháp trên màn hình | Q15: =IF(OR(IF(G15="",IF(F15="",IF(E15="","",E15),F15),G15)="F",IF(J15="",IF(I15="",IF(H15="","",H15),I15),J15)="F",IF(M15="",IF(L15="",IF(K15="","",K15),L15),M15)="F",IF(P15="",IF(O15="",IF(N15="","",N15),O15),P15)="F")=TRUE,"F",IF(OR(IF(G15="",IF(F15="",IF(E15="","",E15),F15),G15)="PE",IF(J15="",IF(I15="",IF(H15="","",H15),I15),J15)="PE",IF(M15="",IF(L15="",IF(K15="","",K15),L15),M15)="PE",IF(P15="",IF(O15="",IF(N15="","",N15),O15),P15)="PE")=TRUE,"PE",IF(AND(IF(G15="",IF(F15="",IF(E15="","",E15),F15),G15)="",IF(J15="",IF(I15="",IF(H15="","",H15),I15),J15)="",IF(M15="",IF(L15="",IF(K15="","",K15),L15),M15)="",IF(P15="",IF(O15="",IF(N15="","",N15),O15),P15)="")=TRUE,"","P"))) | S15: Phụ thuộc TBD-01: chưa xác định màn nhắc việc trên ứng dụng di động (YC_NV_01 ghi nhận di động chưa có màn này) — chưa chạy được thì ghi BLOCKED
A16: =IF(AND(C16="",C16=""),"",$D$3&"_"&ROW()-12-COUNTBLANK($C$13:C16)) | B16: Kiểm tra vị trí hiển thị file văn bản trả lời | C16: 1. Đăng nhập ứng dụng di động bằng at_vt/123 2. Nhắc việc >> danh sách nhắc việc (đường đi theo thiết kế màn hình di động đã duyệt) 3. Tìm dòng NV1 - đơn vị X và NV1 - đơn vị Y | D16: Dòng X hiện tên file "VBTL1_file_chinh.pdf"; dòng Y hiện file chính của VBTL2 và lối mở danh sách đủ 4 file, theo đúng thiết kế màn hình di động đã duyệt. Tên file dài không bị cắt mất phần đuôi. | Q16: =IF(OR(IF(G16="",IF(F16="",IF(E16="","",E16),F16),G16)="F",IF(J16="",IF(I16="",IF(H16="","",H16),I16),J16)="F",IF(M16="",IF(L16="",IF(K16="","",K16),L16),M16)="F",IF(P16="",IF(O16="",IF(N16="","",N16),O16),P16)="F")=TRUE,"F",IF(OR(IF(G16="",IF(F16="",IF(E16="","",E16),F16),G16)="PE",IF(J16="",IF(I16="",IF(H16="","",H16),I16),J16)="PE",IF(M16="",IF(L16="",IF(K16="","",K16),L16),M16)="PE",IF(P16="",IF(O16="",IF(N16="","",N16),O16),P16)="PE")=TRUE,"PE",IF(AND(IF(G16="",IF(F16="",IF(E16="","",E16),F16),G16)="",IF(J16="",IF(I16="",IF(H16="","",H16),I16),J16)="",IF(M16="",IF(L16="",IF(K16="","",K16),L16),M16)="",IF(P16="",IF(O16="",IF(N16="","",N16),O16),P16)="")=TRUE,"","P"))) | S16: Phụ thuộc TBD-01: chưa xác định màn nhắc việc trên ứng dụng di động (YC_NV_01 ghi nhận di động chưa có màn này) — chưa chạy được thì ghi BLOCKED. BR-10
A17: =IF(AND(C17="",C17=""),"",$D$3&"_"&ROW()-12-COUNTBLANK($C$13:C17)) | B17: Chức năng (Phần này viết các trường hợp kiểm thử kiểm tra các ràng buộc trong cơ sở dữ liệu và cho các luồng nghiệp vụ trong tài liệu giải pháp, tích hợp với các chức năng khác)
A18: =IF(AND(C18="",C18=""),"",$D$3&"_"&ROW()-12-COUNTBLANK($C$13:C18)) | B18: Hiển thị và mở file
A19: =IF(AND(C19="",C19=""),"",$D$3&"_"&ROW()-12-COUNTBLANK($C$13:C19)) | B19: Kiểm tra file đúng của văn bản trả lời cùng dòng | C19: 1. Đăng nhập ứng dụng di động bằng at_vt/123 2. Nhắc việc >> danh sách nhắc việc (đường đi theo thiết kế màn hình di động đã duyệt) 3. Xem 3 dòng của NV1 (đơn vị X, Y, Z), so sánh với Web | D19: Dòng X: VBTL1_file_chinh.pdf; dòng Y: 4 file của VBTL2; dòng Z: không có file. Kết quả trùng với Web. | Q19: =IF(OR(IF(G19="",IF(F19="",IF(E19="","",E19),F19),G19)="F",IF(J19="",IF(I19="",IF(H19="","",H19),I19),J19)="F",IF(M19="",IF(L19="",IF(K19="","",K19),L19),M19)="F",IF(P19="",IF(O19="",IF(N19="","",N19),O19),P19)="F")=TRUE,"F",IF(OR(IF(G19="",IF(F19="",IF(E19="","",E19),F19),G19)="PE",IF(J19="",IF(I19="",IF(H19="","",H19),I19),J19)="PE",IF(M19="",IF(L19="",IF(K19="","",K19),L19),M19)="PE",IF(P19="",IF(O19="",IF(N19="","",N19),O19),P19)="PE")=TRUE,"PE",IF(AND(IF(G19="",IF(F19="",IF(E19="","",E19),F19),G19)="",IF(J19="",IF(I19="",IF(H19="","",H19),I19),J19)="",IF(M19="",IF(L19="",IF(K19="","",K19),L19),M19)="",IF(P19="",IF(O19="",IF(N19="","",N19),O19),P19)="")=TRUE,"","P"))) | S19: Phụ thuộc TBD-01: chưa xác định màn nhắc việc trên ứng dụng di động (YC_NV_01 ghi nhận di động chưa có màn này) — chưa chạy được thì ghi BLOCKED. BR-02, BR-10
A20: =IF(AND(C20="",C20=""),"",$D$3&"_"&ROW()-12-COUNTBLANK($C$13:C20)) | B20: Kiểm tra dòng không có văn bản trả lời | C20: 1. Đăng nhập ứng dụng di động bằng at_vt/123 2. Nhắc việc >> danh sách nhắc việc (đường đi theo thiết kế màn hình di động đã duyệt) 3. Xem dòng NV2 - đơn vị X (trả lời không kèm văn bản) và NV4 - đơn vị X (Xử lý lại) | D20: Cả hai dòng không hiện file, không hiện chữ thay thế, không lỗi hiển thị. | Q20: =IF(OR(IF(G20="",IF(F20="",IF(E20="","",E20),F20),G20)="F",IF(J20="",IF(I20="",IF(H20="","",H20),I20),J20)="F",IF(M20="",IF(L20="",IF(K20="","",K20),L20),M20)="F",IF(P20="",IF(O20="",IF(N20="","",N20),O20),P20)="F")=TRUE,"F",IF(OR(IF(G20="",IF(F20="",IF(E20="","",E20),F20),G20)="PE",IF(J20="",IF(I20="",IF(H20="","",H20),I20),J20)="PE",IF(M20="",IF(L20="",IF(K20="","",K20),L20),M20)="PE",IF(P20="",IF(O20="",IF(N20="","",N20),O20),P20)="PE")=TRUE,"PE",IF(AND(IF(G20="",IF(F20="",IF(E20="","",E20),F20),G20)="",IF(J20="",IF(I20="",IF(H20="","",H20),I20),J20)="",IF(M20="",IF(L20="",IF(K20="","",K20),L20),M20)="",IF(P20="",IF(O20="",IF(N20="","",N20),O20),P20)="")=TRUE,"","P"))) | S20: Phụ thuộc TBD-01: chưa xác định màn nhắc việc trên ứng dụng di động (YC_NV_01 ghi nhận di động chưa có màn này) — chưa chạy được thì ghi BLOCKED. BR-05
A21: =IF(AND(C21="",C21=""),"",$D$3&"_"&ROW()-12-COUNTBLANK($C$13:C21)) | B21: Kiểm tra xem danh sách nhiều file | C21: 1. Đăng nhập ứng dụng di động bằng at_vt/123 2. Nhắc việc >> danh sách nhắc việc (đường đi theo thiết kế màn hình di động đã duyệt) 3. Tại dòng NV1 - đơn vị Y, mở danh sách file | D21: Hiển thị đủ 4 file của VBTL2, đúng tên, đánh số thứ tự. | Q21: =IF(OR(IF(G21="",IF(F21="",IF(E21="","",E21),F21),G21)="F",IF(J21="",IF(I21="",IF(H21="","",H21),I21),J21)="F",IF(M21="",IF(L21="",IF(K21="","",K21),L21),M21)="F",IF(P21="",IF(O21="",IF(N21="","",N21),O21),P21)="F")=TRUE,"F",IF(OR(IF(G21="",IF(F21="",IF(E21="","",E21),F21),G21)="PE",IF(J21="",IF(I21="",IF(H21="","",H21),I21),J21)="PE",IF(M21="",IF(L21="",IF(K21="","",K21),L21),M21)="PE",IF(P21="",IF(O21="",IF(N21="","",N21),O21),P21)="PE")=TRUE,"PE",IF(AND(IF(G21="",IF(F21="",IF(E21="","",E21),F21),G21)="",IF(J21="",IF(I21="",IF(H21="","",H21),I21),J21)="",IF(M21="",IF(L21="",IF(K21="","",K21),L21),M21)="",IF(P21="",IF(O21="",IF(N21="","",N21),O21),P21)="")=TRUE,"","P"))) | S21: Phụ thuộc TBD-01: chưa xác định màn nhắc việc trên ứng dụng di động (YC_NV_01 ghi nhận di động chưa có màn này) — chưa chạy được thì ghi BLOCKED. BR-03
A22: =IF(AND(C22="",C22=""),"",$D$3&"_"&ROW()-12-COUNTBLANK($C$13:C22)) | B22: Kiểm tra mở file để xem | C22: 1. Đăng nhập ứng dụng di động bằng at_vt/123 2. Nhắc việc >> danh sách nhắc việc (đường đi theo thiết kế màn hình di động đã duyệt) 3. Tại dòng NV1 - đơn vị X, chạm vào tên file "VBTL1_file_chinh.pdf" | D22: Ứng dụng mở file, hiển thị đúng nội dung. | Q22: =IF(OR(IF(G22="",IF(F22="",IF(E22="","",E22),F22),G22)="F",IF(J22="",IF(I22="",IF(H22="","",H22),I22),J22)="F",IF(M22="",IF(L22="",IF(K22="","",K22),L22),M22)="F",IF(P22="",IF(O22="",IF(N22="","",N22),O22),P22)="F")=TRUE,"F",IF(OR(IF(G22="",IF(F22="",IF(E22="","",E22),F22),G22)="PE",IF(J22="",IF(I22="",IF(H22="","",H22),I22),J22)="PE",IF(M22="",IF(L22="",IF(K22="","",K22),L22),M22)="PE",IF(P22="",IF(O22="",IF(N22="","",N22),O22),P22)="PE")=TRUE,"PE",IF(AND(IF(G22="",IF(F22="",IF(E22="","",E22),F22),G22)="",IF(J22="",IF(I22="",IF(H22="","",H22),I22),J22)="",IF(M22="",IF(L22="",IF(K22="","",K22),L22),M22)="",IF(P22="",IF(O22="",IF(N22="","",N22),O22),P22)="")=TRUE,"","P"))) | S22: Phụ thuộc TBD-01: chưa xác định màn nhắc việc trên ứng dụng di động (YC_NV_01 ghi nhận di động chưa có màn này) — chưa chạy được thì ghi BLOCKED. BR-06
A23: =IF(AND(C23="",C23=""),"",$D$3&"_"&ROW()-12-COUNTBLANK($C$13:C23)) | B23: Kiểm tra tải file về thiết bị | C23: 1. Đăng nhập ứng dụng di động bằng at_vt/123 2. Nhắc việc >> danh sách nhắc việc (đường đi theo thiết kế màn hình di động đã duyệt) 3. Tại dòng NV1 - đơn vị X, chạm biểu tượng tải 4. Mở file vừa tải trong thư mục tải về của thiết bị | D23: File gốc VBTL1_file_chinh.pdf được tải về, mở được. | Q23: =IF(OR(IF(G23="",IF(F23="",IF(E23="","",E23),F23),G23)="F",IF(J23="",IF(I23="",IF(H23="","",H23),I23),J23)="F",IF(M23="",IF(L23="",IF(K23="","",K23),L23),M23)="F",IF(P23="",IF(O23="",IF(N23="","",N23),O23),P23)="F")=TRUE,"F",IF(OR(IF(G23="",IF(F23="",IF(E23="","",E23),F23),G23)="PE",IF(J23="",IF(I23="",IF(H23="","",H23),I23),J23)="PE",IF(M23="",IF(L23="",IF(K23="","",K23),L23),M23)="PE",IF(P23="",IF(O23="",IF(N23="","",N23),O23),P23)="PE")=TRUE,"PE",IF(AND(IF(G23="",IF(F23="",IF(E23="","",E23),F23),G23)="",IF(J23="",IF(I23="",IF(H23="","",H23),I23),J23)="",IF(M23="",IF(L23="",IF(K23="","",K23),L23),M23)="",IF(P23="",IF(O23="",IF(N23="","",N23),O23),P23)="")=TRUE,"","P"))) | S23: Phụ thuộc TBD-01: chưa xác định màn nhắc việc trên ứng dụng di động (YC_NV_01 ghi nhận di động chưa có màn này) — chưa chạy được thì ghi BLOCKED. BR-06
A24: =IF(AND(C24="",C24=""),"",$D$3&"_"&ROW()-12-COUNTBLANK($C$13:C24)) | B24: Kiểm tra chuyên viên theo dõi xem được file | C24: 1. Đăng nhập ứng dụng di động bằng at_cv/123 2. Nhắc việc >> danh sách nhắc việc (đường đi theo thiết kế màn hình di động đã duyệt) 3. Tại dòng NV1 - đơn vị X, chạm vào tên file | D24: Mở được file; không có thông báo không có quyền. | Q24: =IF(OR(IF(G24="",IF(F24="",IF(E24="","",E24),F24),G24)="F",IF(J24="",IF(I24="",IF(H24="","",H24),I24),J24)="F",IF(M24="",IF(L24="",IF(K24="","",K24),L24),M24)="F",IF(P24="",IF(O24="",IF(N24="","",N24),O24),P24)="F")=TRUE,"F",IF(OR(IF(G24="",IF(F24="",IF(E24="","",E24),F24),G24)="PE",IF(J24="",IF(I24="",IF(H24="","",H24),I24),J24)="PE",IF(M24="",IF(L24="",IF(K24="","",K24),L24),M24)="PE",IF(P24="",IF(O24="",IF(N24="","",N24),O24),P24)="PE")=TRUE,"PE",IF(AND(IF(G24="",IF(F24="",IF(E24="","",E24),F24),G24)="",IF(J24="",IF(I24="",IF(H24="","",H24),I24),J24)="",IF(M24="",IF(L24="",IF(K24="","",K24),L24),M24)="",IF(P24="",IF(O24="",IF(N24="","",N24),O24),P24)="")=TRUE,"","P"))) | S24: Phụ thuộc TBD-01: chưa xác định màn nhắc việc trên ứng dụng di động (YC_NV_01 ghi nhận di động chưa có màn này) — chưa chạy được thì ghi BLOCKED. BR-07
A25: =IF(AND(C25="",C25=""),"",$D$3&"_"&ROW()-12-COUNTBLANK($C$13:C25)) | B25: An toàn thông tin (Các trường hợp kiểm thử đảm bảo an toàn thông tin theo hướng dẫn kiểm thử an toàn thông tin)
A26: =IF(AND(C26="",C26=""),"",$D$3&"_"&ROW()-12-COUNTBLANK($C$13:C26)) | B26: Kiểm tra không lấy được file của dòng mình không thấy | C26: 1. Đăng nhập ứng dụng di động bằng at_vt/123, bật công cụ bắt gói tin (proxy Burp Suite trên thiết bị) 2. Nhắc việc >> danh sách nhắc việc (đường đi theo thiết kế màn hình di động đã duyệt) >> chạm tên file ở dòng NV1 - đơn vị X, ghi lại yêu cầu xem file 3. Đăng xuất, đăng nhập ứng dụng bằng <TK_KLQ> 4. Gửi lại yêu cầu ở bước 2 bằng phiên của <TK_KLQ> | D26: Hệ thống từ chối, không trả nội dung file. | Q26: =IF(OR(IF(G26="",IF(F26="",IF(E26="","",E26),F26),G26)="F",IF(J26="",IF(I26="",IF(H26="","",H26),I26),J26)="F",IF(M26="",IF(L26="",IF(K26="","",K26),L26),M26)="F",IF(P26="",IF(O26="",IF(N26="","",N26),O26),P26)="F")=TRUE,"F",IF(OR(IF(G26="",IF(F26="",IF(E26="","",E26),F26),G26)="PE",IF(J26="",IF(I26="",IF(H26="","",H26),I26),J26)="PE",IF(M26="",IF(L26="",IF(K26="","",K26),L26),M26)="PE",IF(P26="",IF(O26="",IF(N26="","",N26),O26),P26)="PE")=TRUE,"PE",IF(AND(IF(G26="",IF(F26="",IF(E26="","",E26),F26),G26)="",IF(J26="",IF(I26="",IF(H26="","",H26),I26),J26)="",IF(M26="",IF(L26="",IF(K26="","",K26),L26),M26)="",IF(P26="",IF(O26="",IF(N26="","",N26),O26),P26)="")=TRUE,"","P"))) | S26: Phụ thuộc TBD-01: chưa xác định màn nhắc việc trên ứng dụng di động (YC_NV_01 ghi nhận di động chưa có màn này) — chưa chạy được thì ghi BLOCKED. NFR-02
A27: =IF(AND(C27="",C27=""),"",$D$3&"_"&ROW()-12-COUNTBLANK($C$13:C27)) | B27: N/A - Kiểm tra SQL Injection / XSS trên ô nhập: yêu cầu không thêm ô nhập liệu nào trên ứng dụng.
A28: =IF(AND(C28="",C28=""),"",$D$3&"_"&ROW()-12-COUNTBLANK($C$13:C28)) | B28: Kiểm tra ảnh hưởng (Các trường hợp kiểm thử ảnh hưởng từ chức năng)
A29: =IF(AND(C29="",C29=""),"",$D$3&"_"&ROW()-12-COUNTBLANK($C$13:C29)) | B29: Kiểm tra tương thích với bản ứng dụng cũ | C29: 1. Đăng nhập ứng dụng di động bản hiện hành (chưa cập nhật) bằng at_vt/123 2. Nhắc việc >> danh sách nhắc việc (nếu bản cũ có màn này) 3. VB đến >> Chờ xử lý >> mở chi tiết một văn bản bất kỳ | D29: Ứng dụng chạy bình thường, không văng, không báo lỗi; chỉ không hiển thị file văn bản trả lời. | Q29: =IF(OR(IF(G29="",IF(F29="",IF(E29="","",E29),F29),G29)="F",IF(J29="",IF(I29="",IF(H29="","",H29),I29),J29)="F",IF(M29="",IF(L29="",IF(K29="","",K29),L29),M29)="F",IF(P29="",IF(O29="",IF(N29="","",N29),O29),P29)="F")=TRUE,"F",IF(OR(IF(G29="",IF(F29="",IF(E29="","",E29),F29),G29)="PE",IF(J29="",IF(I29="",IF(H29="","",H29),I29),J29)="PE",IF(M29="",IF(L29="",IF(K29="","",K29),L29),M29)="PE",IF(P29="",IF(O29="",IF(N29="","",N29),O29),P29)="PE")=TRUE,"PE",IF(AND(IF(G29="",IF(F29="",IF(E29="","",E29),F29),G29)="",IF(J29="",IF(I29="",IF(H29="","",H29),I29),J29)="",IF(M29="",IF(L29="",IF(K29="","",K29),L29),M29)="",IF(P29="",IF(O29="",IF(N29="","",N29),O29),P29)="")=TRUE,"","P"))) | S29: NFR-05, EC-07
A30: =IF(AND(C30="",C30=""),"",$D$3&"_"&ROW()-12-COUNTBLANK($C$13:C30)) | B30: Kiểm tra danh sách nhắc việc trên ứng dụng không đổi số dòng | C30: 1. Đăng nhập ứng dụng di động bằng at_ld/123 2. Nhắc việc >> danh sách nhắc việc (đường đi theo thiết kế màn hình di động đã duyệt) 3. Đếm số dòng, so sánh với Web cùng tài khoản, cùng bộ lọc | D30: Số dòng và nội dung các thông tin cũ trùng với Web, không bị lặp dòng. | Q30: =IF(OR(IF(G30="",IF(F30="",IF(E30="","",E30),F30),G30)="F",IF(J30="",IF(I30="",IF(H30="","",H30),I30),J30)="F",IF(M30="",IF(L30="",IF(K30="","",K30),L30),M30)="F",IF(P30="",IF(O30="",IF(N30="","",N30),O30),P30)="F")=TRUE,"F",IF(OR(IF(G30="",IF(F30="",IF(E30="","",E30),F30),G30)="PE",IF(J30="",IF(I30="",IF(H30="","",H30),I30),J30)="PE",IF(M30="",IF(L30="",IF(K30="","",K30),L30),M30)="PE",IF(P30="",IF(O30="",IF(N30="","",N30),O30),P30)="PE")=TRUE,"PE",IF(AND(IF(G30="",IF(F30="",IF(E30="","",E30),F30),G30)="",IF(J30="",IF(I30="",IF(H30="","",H30),I30),J30)="",IF(M30="",IF(L30="",IF(K30="","",K30),L30),M30)="",IF(P30="",IF(O30="",IF(N30="","",N30),O30),P30)="")=TRUE,"","P"))) | S30: Phụ thuộc TBD-01: chưa xác định màn nhắc việc trên ứng dụng di động (YC_NV_01 ghi nhận di động chưa có màn này) — chưa chạy được thì ghi BLOCKED
