Workbook

Sheet Trang bìa
E1: TẬP ĐOÀN CÔNG NGHIỆP VIỄN THÔNG QUÂN ĐỘI
E2: TỔNG CÔNG TY GIẢI PHÁP DOANH NGHIỆP VIETTEL
A9: <VOFFICE KHA>
A10: TÀI LIỆU KỊCH BẢN KIỂM THỬ CHỨC NĂNG
A11: NV_11 - Thêm ô Nhận để biết vào nhóm Phiếu trình trên trang chủ
C16: Mã dự án | D16: :
C17: Mã tài liệu | D17: :
A20: Người lập:
C21: <Tên người nhập> | F21: <Ngày lập>
C22: <Chức vụ>
A26: Người kiểm tra:
C27: <Tên người kiểm tra | F27: <Ngày kiểm tra>
C28: <Chức vụ>
A32: Người phê duyệt:
C33: <Tên người phê duyệt> | F33: <Ngày phê duyệt>
C34: <Chức vụ>
A37: BẢNG GHI NHẬN THAY ĐỔI TÀI LIỆU
A39: Ngày thay đổi | B39: Vị trí thay đổi | C39: Lý do | D39: Nguồn gốc | E39: Phiên bản cũ | F39: Mô tả thay đổi | G39: Phiên bản mới

Sheet Giới thiệu
A1: GIỚI THIỆU
A3: 1 - Giới thiệu
A8: 2 - Tài liệu tham khảo
A9: STT | B9: Tên tài liệu | C9: Tên file | D9: Phiên bản | E9: Đường dẫn
A10: 1
A15: 3 - Môi trường kiểm thử
A16: STT | B16: Trình duyệt | C16: Phiên bản | E16: Viết tắt
B17: Chrome | C17: 131 | E17: C
B18: Microsoft Edge | C18: 131 | E18: ME
B19: Cấu hình server test
B20: CPU: 4G, Duecore, Ram 8G, HDD: 320G
B21: Tool test | C21: Phiên bản | E21: Mục đích

Sheet Tổng hợp
A1: TỔNG HỢP KẾT QUẢ
A3: STT | B3: Tên màn hình/chức năng | C3: Số trường hợp kiểm thử đạt (P) | D3: Số trường hợp kiểm thử không đạt (F) | E3: Số trường hợp kiểm thử đang xem xét (PE) | F3: Số trường hợp kiểm thử chưa thực hiện | G3: Tổng số trường hợp kiểm thử | H3: Tỉ lệ trường hợp kiểm thử đạt (%P) | I3: Tỉ lệ trường hợp kiểm thử không đạt (%F) | J3: Tỉ lệ trường hợp kiểm thử đã thực hiện (%Cover)
A4: 1 | B4: ='NV_11_Web'!D2&" - Web" | C4: ='NV_11_Web'!D4 | D4: ='NV_11_Web'!D5 | E4: ='NV_11_Web'!D6 | F4: ='NV_11_Web'!D7 | G4: ='NV_11_Web'!D8 | H4: =IFERROR(C4/G4,0) | I4: =IFERROR(D4/G4,0) | J4: =IFERROR((C4+D4)/G4,0)
A12: Total | C12: =SUM(C4:C11) | D12: =SUM(D4:D11) | E12: =SUM(E4:E11) | F12: =SUM(F4:F11) | G12: =SUM(G4:G11) | H12: =IFERROR(C12/G12,0) | I12: =IFERROR(D12/G12,0) | J12: =IFERROR((C12+D12)/G12,0)

Sheet NV_11_Web
C1: KỊCH BẢN KIỂM THỬ *
C2: Tên màn hình/Tên chức năng | D2: NV_11_Thêm ô Nhận để biết vào nhóm Phiếu trình trên trang chủ
C3: Mã trường hợp kiểm thử | D3: NV_11
C4: Số trường hợp kiểm thử đạt (P) | D4: =COUNTIF($E$13:$E$51,"P")
C5: Số trường hợp kiểm thử không đạt (F) | D5: =COUNTIF($E$13:$E$51,"F")
C6: Số trường hợp kiểm thử đang xem xét (PE) | D6: =COUNTIF($Q$13:$Q$51,"PE")
C7: Số trường hợp kiểm thử chưa thực hiện | D7: =D8-D4-D5-D6
C8: Tổng số trường hợp kiểm thử | D8: =COUNTA($Q$13:$Q$51)
A10: Mã trường hợp kiểm thử | B10: Mục đích kiểm thử | C10: Các bước thực hiện | D10: Kết quả mong muốn | E10: PC | H10: Firefox | K10: <Tên trình duyệt 3> | N10: <Tên trình duyệt 4> | Q10: Kết quả hiện tại | R10: Mã lỗi | S10: Ghi chú
E11: Lần 1 | F11: Lần 2 | G11: Lần 3 | H11: Lần 1 | I11: Lần 2 | J11: Lần 3 | K11: Lần 1 | L11: Lần 2 | M11: Lần 3 | N11: Lần 1 | O11: Lần 2 | P11: Lần 3
B12: NV_11_Thêm ô Nhận để biết vào nhóm Phiếu trình trên trang chủ_Web
B13: A: Các bước thực hiện Pre- condition: 1. Truy cập link: <link môi trường test> 2. Login acc có vai trò lãnh đạo (at_ld/123), Văn thư (at_vt/123), Chuyên viên ( at_cv/123) 3. Phạm vi: Trang chủ >> thẻ "Phiếu trình" >> ô "Nhận để biết" (ô thứ 6, sau ô "Xin ý kiến") Khung người dùng góc phải >> Cấu hình trang chủ (dòng "Nhận để biết" dưới nhóm "Phiếu trình") Khung người dùng góc phải >> chế độ trang chủ đơn giản PHIẾU TRÌNH >> Phiếu trình nhận để biết (màn đích khi bấm ô) 4. Dữ liệu chuẩn bị (tạo bằng chức năng Phiếu trình, ghi lại tiêu đề phiếu để dùng lại): Cách tạo một phiếu trình đã phê duyệt rồi chuyển tiếp để biết (dùng lại cho mọi phiếu PT bên dưới): b1. at_vt đăng nhập >> PHIẾU TRÌNH >> Trình xin ý kiến >> Thêm mới b2. Nhập Đơn vị ban hành, Ngày trình, Nội dung trình, Cơ quan trình b3. Chọn người xin ý kiến là at_ld, hành động "Phê duyệt" >> Lưu >> Trình b4. at_ld đăng nhập >> PHIẾU TRÌNH >> Trình quyết định >> tab Chờ xử lý >> mở phiếu >> nhập ý kiến >> Phê duyệt (phiếu chuyển sang trạng thái "Đã phê duyệt") b5. at_vt >> PHIẾU TRÌNH >> Trình xin ý kiến >> chọn phiếu >> Chuyển tiếp >> chọn người nhận >> Gửi - PT1: at_vt chuyển để biết cho at_cv. Sau đó at_cv MỞ CHI TIẾT phiếu (để phiếu ở trạng thái đã đọc) - PT2: at_vt chuyển để biết cho at_cv. at_cv KHÔNG mở chi tiết (giữ chưa đọc, dòng in đậm) - PT3: at_vt chuyển để biết cho CẢ at_ld VÀ at_cv. Sau đó at_ld >> PHIẾU TRÌNH >> Phiếu trình nhận để biết >> chọn PT3 >> Chuyển tiếp >> chọn at_cv >> Gửi (at_cv nhận cùng một phiếu 2 lần) - PT4: at_vt chuyển để biết cho at_cv. Nhờ DEV/DBA cập nhật SUBMISSION_FORWARD.SEND_DATE của dòng này về quá 365 ngày (ví dụ sysdate-400). Không tạo được bằng giao diện - PT5: at_vt chuyển để biết cho at_ld => Số phiếu nhận để biết trong 365 ngày: at_cv = 3 (PT1, PT2, PT3) · at_ld = 2 (PT3, PT5) · at_vt = 0 - at_vt không được chuyển để biết phiếu nào, dùng làm tài khoản kiểm trường hợp số 0 B: Mô tả chức năng Thêm ô thứ 6 tên "Nhận để biết" vào cuối nhóm ô "Phiếu trình" trên trang chủ, sau ô "Xin ý kiến". Con số trên ô = tổng số phiếu trình trong hộp "Phiếu trình nhận để biết" của chính người đăng nhập, tính cả phiếu đã đọc và chưa đọc, mỗi phiếu tính 1 lần dù được chuyển nhiều lần, chỉ đếm phiếu có ngày chuyển trong 365 ngày gần nhất. Không có phiếu nào thì ô vẫn hiện và ghi số 0. Bấm vào ô mở màn "Phiếu trình nhận để biết" với bộ lọc mặc định của màn, không áp thêm bộ lọc. Ô mặc định bật cho mọi người dùng, tự bật/tắt được tại "Cấu hình trang chủ", và hiện cả ở chế độ trang chủ đơn giản cho mọi vai trò kể cả văn thư. Ô chỉ đọc: hiển thị và bấm ô không đánh dấu đã đọc, không đổi trạng thái phiếu. C: Các bảng tác động - SUBMISSION_FORWARD: RECEIVER_ID, SUBMISSION_FORM_ID, SEND_DATE, IS_READ (CHỈ ĐỌC - dùng để đếm) - SUBMISSION_FORM: SUBMISSION_FORM_ID, TITLE, STATUS (CHỈ ĐỌC) - HOME_WIDGET: thêm 1 dòng khai báo ô mới (PARENT_CODE = 'PHIEU_TRINH', SIMPLE_MODE = 3) - Cấu hình bật/tắt ô của từng người: không có bảng, chỉ nằm trong bộ nhớ đệm của máy chủ Không thêm bảng, không thêm cột, không cần migration dữ liệu nghiệp vụ.
A14: =IF(AND(C14="",C14=""),"",$D$3&"_"&ROW()-12-COUNTBLANK($C$13:C14)) | B14: Giao diện (Phần này viết các trường hợp kiểm thử cho giao diên chung và các giao diện cho các control)
A15: =IF(AND(C15="",C15=""),"",$D$3&"_"&ROW()-12-COUNTBLANK($C$13:C15)) | B15: Kiểm tra tổng thể giao diện thẻ "Phiếu trình" trên trang chủ | C15: 1. Đăng nhập vào at_cv/123 2. Hệ thống mở Trang chủ >> kéo tới thẻ "Phiếu trình" 3. Kiểm tra tiêu đề thẻ, bố cục các ô, font chữ, cỡ chữ, màu chữ, chính tả 4. Kiểm tra ô "Nhận để biết" dùng cùng kiểu trình bày với 5 ô còn lại (cùng kích thước, cùng cách đặt nhãn và số) | D15: 1. Bố cục - Thẻ "Phiếu trình" hiển thị 6 ô, xếp 2 cột 3 hàng, không có ô nào bị tràn hay xuống dòng lạ 2. Font chữ và màu chữ - Ô "Nhận để biết" dùng cùng font, cỡ chữ, cách trình bày nhãn và số như 5 ô còn lại 3. Chính tả - Nhãn ghi đúng "Nhận để biết", không có lỗi chính tả, không viết thành "Phiếu trình nhận để biết" | Q15: =IF(OR(IF(G15="",IF(F15="",IF(E15="","",E15),F15),G15)="F",IF(J15="",IF(I15="",IF(H15="","",H15),I15),J15)="F",IF(M15="",IF(L15="",IF(K15="","",K15),L15),M15)="F",IF(P15="",IF(O15="",IF(N15="","",N15),O15),P15)="F")=TRUE,"F",IF(OR(IF(G15="",IF(F15="",IF(E15="","",E15),F15),G15)="PE",IF(J15="",IF(I15="",IF(H15="","",H15),I15),J15)="PE",IF(M15="",IF(L15="",IF(K15="","",K15),L15),M15)="PE",IF(P15="",IF(O15="",IF(N15="","",N15),O15),P15)="PE")=TRUE,"PE",IF(AND(IF(G15="",IF(F15="",IF(E15="","",E15),F15),G15)="",IF(J15="",IF(I15="",IF(H15="","",H15),I15),J15)="",IF(M15="",IF(L15="",IF(K15="","",K15),L15),M15)="",IF(P15="",IF(O15="",IF(N15="","",N15),O15),P15)="")=TRUE,"","P")))
A16: =IF(AND(C16="",C16=""),"",$D$3&"_"&ROW()-12-COUNTBLANK($C$13:C16)) | B16: Kiểm tra vị trí và thứ tự ô "Nhận để biết" trong thẻ Phiếu trình | C16: 1. Đăng nhập vào at_cv/123 2. Trang chủ >> thẻ "Phiếu trình" 3. Đếm số ô và đọc tên các ô theo thứ tự từ trái sang phải, từ trên xuống dưới | D16: Thẻ hiển thị 6 ô theo đúng thứ tự: Chờ xử lý, Đang xử lý, Đã phê duyệt, Tất cả, Xin ý kiến, Nhận để biết. Ô "Nhận để biết" đứng cuối cùng, ngay sau ô "Xin ý kiến". 5 ô cũ giữ nguyên tên và thứ tự tương đối như trước khi sửa. | Q16: =IF(OR(IF(G16="",IF(F16="",IF(E16="","",E16),F16),G16)="F",IF(J16="",IF(I16="",IF(H16="","",H16),I16),J16)="F",IF(M16="",IF(L16="",IF(K16="","",K16),L16),M16)="F",IF(P16="",IF(O16="",IF(N16="","",N16),O16),P16)="F")=TRUE,"F",IF(OR(IF(G16="",IF(F16="",IF(E16="","",E16),F16),G16)="PE",IF(J16="",IF(I16="",IF(H16="","",H16),I16),J16)="PE",IF(M16="",IF(L16="",IF(K16="","",K16),L16),M16)="PE",IF(P16="",IF(O16="",IF(N16="","",N16),O16),P16)="PE")=TRUE,"PE",IF(AND(IF(G16="",IF(F16="",IF(E16="","",E16),F16),G16)="",IF(J16="",IF(I16="",IF(H16="","",H16),I16),J16)="",IF(M16="",IF(L16="",IF(K16="","",K16),L16),M16)="",IF(P16="",IF(O16="",IF(N16="","",N16),O16),P16)="")=TRUE,"","P")))
A17: =IF(AND(C17="",C17=""),"",$D$3&"_"&ROW()-12-COUNTBLANK($C$13:C17)) | B17: Kiểm tra dòng "Nhận để biết" trong màn Cấu hình trang chủ | C17: 1. Đăng nhập vào at_cv/123 2. Bấm khung người dùng ở góc phải trên >> chọn "Cấu hình trang chủ" 3. Tìm nhóm "Phiếu trình" trong danh sách 4. Đọc các dòng con của nhóm theo thứ tự và kiểm tra trạng thái ô tick của dòng "Nhận để biết" 5. Kiểm tra cột Thao tác của dòng "Nhận để biết" | D17: Nhóm "Phiếu trình" có 6 dòng con, dòng "Nhận để biết" nằm cuối, ngay sau dòng "Xin ý kiến". Ô tick của dòng "Nhận để biết" đang được tick sẵn. Cột Thao tác của dòng này để trống, không có biểu tượng xóa (chỉ ô do người dùng tự tạo mới có). | Q17: =IF(OR(IF(G17="",IF(F17="",IF(E17="","",E17),F17),G17)="F",IF(J17="",IF(I17="",IF(H17="","",H17),I17),J17)="F",IF(M17="",IF(L17="",IF(K17="","",K17),L17),M17)="F",IF(P17="",IF(O17="",IF(N17="","",N17),O17),P17)="F")=TRUE,"F",IF(OR(IF(G17="",IF(F17="",IF(E17="","",E17),F17),G17)="PE",IF(J17="",IF(I17="",IF(H17="","",H17),I17),J17)="PE",IF(M17="",IF(L17="",IF(K17="","",K17),L17),M17)="PE",IF(P17="",IF(O17="",IF(N17="","",N17),O17),P17)="PE")=TRUE,"PE",IF(AND(IF(G17="",IF(F17="",IF(E17="","",E17),F17),G17)="",IF(J17="",IF(I17="",IF(H17="","",H17),I17),J17)="",IF(M17="",IF(L17="",IF(K17="","",K17),L17),M17)="",IF(P17="",IF(O17="",IF(N17="","",N17),O17),P17)="")=TRUE,"","P")))
A18: =IF(AND(C18="",C18=""),"",$D$3&"_"&ROW()-12-COUNTBLANK($C$13:C18)) | B18: Kiểm tra cách trình bày ô ở chế độ trang chủ đơn giản | C18: 1. Đăng nhập vào at_cv/123 2. Bấm khung người dùng ở góc phải trên >> chọn chế độ trang chủ đơn giản 3. Kéo tới thẻ "Phiếu trình" 4. Kiểm tra cách trình bày của ô "Nhận để biết": dấu tròn màu bên trái nhãn, con số nằm trong viên thuốc bên phải | D18: Ô "Nhận để biết" hiển thị dạng một dòng: dấu tròn màu xám bên trái, nhãn "Nhận để biết", con số 3 trong viên thuốc bên phải. Ô "Chờ xử lý" giữ dấu tròn đỏ như hiện tại. Không hiển thị biểu tượng hình ảnh ở chế độ này. | Q18: =IF(OR(IF(G18="",IF(F18="",IF(E18="","",E18),F18),G18)="F",IF(J18="",IF(I18="",IF(H18="","",H18),I18),J18)="F",IF(M18="",IF(L18="",IF(K18="","",K18),L18),M18)="F",IF(P18="",IF(O18="",IF(N18="","",N18),O18),P18)="F")=TRUE,"F",IF(OR(IF(G18="",IF(F18="",IF(E18="","",E18),F18),G18)="PE",IF(J18="",IF(I18="",IF(H18="","",H18),I18),J18)="PE",IF(M18="",IF(L18="",IF(K18="","",K18),L18),M18)="PE",IF(P18="",IF(O18="",IF(N18="","",N18),O18),P18)="PE")=TRUE,"PE",IF(AND(IF(G18="",IF(F18="",IF(E18="","",E18),F18),G18)="",IF(J18="",IF(I18="",IF(H18="","",H18),I18),J18)="",IF(M18="",IF(L18="",IF(K18="","",K18),L18),M18)="",IF(P18="",IF(O18="",IF(N18="","",N18),O18),P18)="")=TRUE,"","P")))
A19: =IF(AND(C19="",C19=""),"",$D$3&"_"&ROW()-12-COUNTBLANK($C$13:C19)) | B19: Chức năng (Phần này viết các trường hợp kiểm thử kiểm tra các ràng buộc trong cơ sở dữ liệu và cho các luồng nghiệp vụ trong tài liệu giải pháp, tích hợp với các chức năng khác)
A20: =IF(AND(C20="",C20=""),"",$D$3&"_"&ROW()-12-COUNTBLANK($C$13:C20)) | B20: Con số trên ô "Nhận để biết"
A21: =IF(AND(C21="",C21=""),"",$D$3&"_"&ROW()-12-COUNTBLANK($C$13:C21)) | B21: Kiểm tra ô đếm cả phiếu đã đọc và phiếu chưa đọc | C21: 1. Đăng nhập vào at_cv/123 2. Trang chủ >> thẻ "Phiếu trình" >> đọc số trên ô "Nhận để biết" 3. PHIẾU TRÌNH >> Phiếu trình nhận để biết >> đếm số dòng và xem dòng nào in đậm | D21: Ô "Nhận để biết" hiển thị số 3 (PT1 đã đọc, PT2 chưa đọc, PT3 chưa đọc). Màn Phiếu trình nhận để biết hiển thị đúng 3 dòng, trong đó PT2 và PT3 in đậm, PT1 không in đậm. Số trên ô không trừ phiếu đã đọc, không hiển thị dạng "x/y". | Q21: =IF(OR(IF(G21="",IF(F21="",IF(E21="","",E21),F21),G21)="F",IF(J21="",IF(I21="",IF(H21="","",H21),I21),J21)="F",IF(M21="",IF(L21="",IF(K21="","",K21),L21),M21)="F",IF(P21="",IF(O21="",IF(N21="","",N21),O21),P21)="F")=TRUE,"F",IF(OR(IF(G21="",IF(F21="",IF(E21="","",E21),F21),G21)="PE",IF(J21="",IF(I21="",IF(H21="","",H21),I21),J21)="PE",IF(M21="",IF(L21="",IF(K21="","",K21),L21),M21)="PE",IF(P21="",IF(O21="",IF(N21="","",N21),O21),P21)="PE")=TRUE,"PE",IF(AND(IF(G21="",IF(F21="",IF(E21="","",E21),F21),G21)="",IF(J21="",IF(I21="",IF(H21="","",H21),I21),J21)="",IF(M21="",IF(L21="",IF(K21="","",K21),L21),M21)="",IF(P21="",IF(O21="",IF(N21="","",N21),O21),P21)="")=TRUE,"","P")))
A22: =IF(AND(C22="",C22=""),"",$D$3&"_"&ROW()-12-COUNTBLANK($C$13:C22)) | B22: Kiểm tra một phiếu được chuyển nhiều lần chỉ tính một | C22: 1. Đăng nhập vào at_cv/123 2. Trang chủ >> thẻ "Phiếu trình" >> ghi lại số trên ô "Nhận để biết" 3. PHIẾU TRÌNH >> Phiếu trình nhận để biết >> tìm phiếu PT3 (phiếu được at_vt và at_ld cùng chuyển cho at_cv) 4. Đếm số dòng của PT3 trong danh sách | D22: PT3 chỉ hiện 1 dòng trong danh sách (lấy lần chuyển mới nhất). Số trên ô là 3, không phải 4 - PT3 chỉ được tính 1 lần dù được hai người chuyển tới. | Q22: =IF(OR(IF(G22="",IF(F22="",IF(E22="","",E22),F22),G22)="F",IF(J22="",IF(I22="",IF(H22="","",H22),I22),J22)="F",IF(M22="",IF(L22="",IF(K22="","",K22),L22),M22)="F",IF(P22="",IF(O22="",IF(N22="","",N22),O22),P22)="F")=TRUE,"F",IF(OR(IF(G22="",IF(F22="",IF(E22="","",E22),F22),G22)="PE",IF(J22="",IF(I22="",IF(H22="","",H22),I22),J22)="PE",IF(M22="",IF(L22="",IF(K22="","",K22),L22),M22)="PE",IF(P22="",IF(O22="",IF(N22="","",N22),O22),P22)="PE")=TRUE,"PE",IF(AND(IF(G22="",IF(F22="",IF(E22="","",E22),F22),G22)="",IF(J22="",IF(I22="",IF(H22="","",H22),I22),J22)="",IF(M22="",IF(L22="",IF(K22="","",K22),L22),M22)="",IF(P22="",IF(O22="",IF(N22="","",N22),O22),P22)="")=TRUE,"","P")))
A23: =IF(AND(C23="",C23=""),"",$D$3&"_"&ROW()-12-COUNTBLANK($C$13:C23)) | B23: Kiểm tra phiếu được chuyển quá 365 ngày không được tính | C23: 1. Đăng nhập vào at_cv/123 2. Trang chủ >> thẻ "Phiếu trình" >> đọc số trên ô "Nhận để biết" 3. Bấm vào ô "Nhận để biết" để mở màn Phiếu trình nhận để biết 4. Đếm số dòng với bộ lọc mặc định và tìm phiếu PT4 5. Sửa bộ lọc Ngày gửi về khoảng bao trùm ngày chuyển của PT4 >> Tìm kiếm | D23: Số trên ô là 3, không tính PT4. Với bộ lọc mặc định, màn hiển thị 3 dòng và không có PT4 - số trên ô khớp số dòng nhìn thấy. Khi nới bộ lọc Ngày gửi, PT4 mới hiện ra; số trên ô vẫn là 3, không đổi theo bộ lọc người dùng tự chọn. | Q23: =IF(OR(IF(G23="",IF(F23="",IF(E23="","",E23),F23),G23)="F",IF(J23="",IF(I23="",IF(H23="","",H23),I23),J23)="F",IF(M23="",IF(L23="",IF(K23="","",K23),L23),M23)="F",IF(P23="",IF(O23="",IF(N23="","",N23),O23),P23)="F")=TRUE,"F",IF(OR(IF(G23="",IF(F23="",IF(E23="","",E23),F23),G23)="PE",IF(J23="",IF(I23="",IF(H23="","",H23),I23),J23)="PE",IF(M23="",IF(L23="",IF(K23="","",K23),L23),M23)="PE",IF(P23="",IF(O23="",IF(N23="","",N23),O23),P23)="PE")=TRUE,"PE",IF(AND(IF(G23="",IF(F23="",IF(E23="","",E23),F23),G23)="",IF(J23="",IF(I23="",IF(H23="","",H23),I23),J23)="",IF(M23="",IF(L23="",IF(K23="","",K23),L23),M23)="",IF(P23="",IF(O23="",IF(N23="","",N23),O23),P23)="")=TRUE,"","P"))) | S23: Cần DEV/DBA chỉnh SEND_DATE của PT4 về quá 365 ngày trước khi chạy (xem phần Dữ liệu chuẩn bị).
A24: =IF(AND(C24="",C24=""),"",$D$3&"_"&ROW()-12-COUNTBLANK($C$13:C24)) | B24: Kiểm tra người chưa từng được chuyển phiếu nào | C24: 1. Đăng nhập vào at_vt/123 (tài khoản không được chuyển để biết phiếu nào) 2. Trang chủ >> thẻ "Phiếu trình" 3. Kiểm tra ô "Nhận để biết" có hiển thị hay không và giá trị hiển thị 4. Bấm vào ô "Nhận để biết" | D24: Ô "Nhận để biết" VẪN hiển thị, ghi số 0. Ô không bị ẩn, không bị làm mờ, không hiển thị dấu gạch ngang hay chữ "Không có". Bấm vào ô vẫn mở được màn Phiếu trình nhận để biết, danh sách không có dòng nào. | Q24: =IF(OR(IF(G24="",IF(F24="",IF(E24="","",E24),F24),G24)="F",IF(J24="",IF(I24="",IF(H24="","",H24),I24),J24)="F",IF(M24="",IF(L24="",IF(K24="","",K24),L24),M24)="F",IF(P24="",IF(O24="",IF(N24="","",N24),O24),P24)="F")=TRUE,"F",IF(OR(IF(G24="",IF(F24="",IF(E24="","",E24),F24),G24)="PE",IF(J24="",IF(I24="",IF(H24="","",H24),I24),J24)="PE",IF(M24="",IF(L24="",IF(K24="","",K24),L24),M24)="PE",IF(P24="",IF(O24="",IF(N24="","",N24),O24),P24)="PE")=TRUE,"PE",IF(AND(IF(G24="",IF(F24="",IF(E24="","",E24),F24),G24)="",IF(J24="",IF(I24="",IF(H24="","",H24),I24),J24)="",IF(M24="",IF(L24="",IF(K24="","",K24),L24),M24)="",IF(P24="",IF(O24="",IF(N24="","",N24),O24),P24)="")=TRUE,"","P")))
A25: =IF(AND(C25="",C25=""),"",$D$3&"_"&ROW()-12-COUNTBLANK($C$13:C25)) | B25: Kiểm tra mỗi người chỉ thấy số của riêng mình | C25: 1. Đăng nhập vào at_cv/123 >> Trang chủ >> ghi lại số trên ô "Nhận để biết" >> Đăng xuất 2. Đăng nhập vào at_ld/123 >> Trang chủ >> ghi lại số trên ô "Nhận để biết" >> Đăng xuất 3. Đăng nhập vào at_vt/123 >> Trang chủ >> ghi lại số trên ô "Nhận để biết" | D25: at_cv hiển thị 3, at_ld hiển thị 2 (PT3 và PT5), at_vt hiển thị 0. Mỗi tài khoản chỉ đếm phiếu được chuyển cho chính mình, không cộng dồn phiếu của người khác. Ô hiển thị cho cả ba vai trò, không vai trò nào bị ẩn ô. | Q25: =IF(OR(IF(G25="",IF(F25="",IF(E25="","",E25),F25),G25)="F",IF(J25="",IF(I25="",IF(H25="","",H25),I25),J25)="F",IF(M25="",IF(L25="",IF(K25="","",K25),L25),M25)="F",IF(P25="",IF(O25="",IF(N25="","",N25),O25),P25)="F")=TRUE,"F",IF(OR(IF(G25="",IF(F25="",IF(E25="","",E25),F25),G25)="PE",IF(J25="",IF(I25="",IF(H25="","",H25),I25),J25)="PE",IF(M25="",IF(L25="",IF(K25="","",K25),L25),M25)="PE",IF(P25="",IF(O25="",IF(N25="","",N25),O25),P25)="PE")=TRUE,"PE",IF(AND(IF(G25="",IF(F25="",IF(E25="","",E25),F25),G25)="",IF(J25="",IF(I25="",IF(H25="","",H25),I25),J25)="",IF(M25="",IF(L25="",IF(K25="","",K25),L25),M25)="",IF(P25="",IF(O25="",IF(N25="","",N25),O25),P25)="")=TRUE,"","P")))
A26: =IF(AND(C26="",C26=""),"",$D$3&"_"&ROW()-12-COUNTBLANK($C$13:C26)) | B26: Đối chiếu số trên ô với dữ liệu trong cơ sở dữ liệu | C26: 1. Đăng nhập vào at_cv/123 >> Trang chủ >> ghi lại số trên ô "Nhận để biết" 2. Lấy EMPLOYEE_ID của at_cv (hỏi DEV hoặc xem màn Quản lý người dùng) 3. Chạy câu lệnh sau trên CSDL môi trường test (CHỈ ĐỌC, không ghi - đây là CSDL dùng chung): SELECT COUNT(*) FROM ( SELECT SF.SUBMISSION_FORM_ID FROM SUBMISSION_FORWARD SF WHERE SF.RECEIVER_ID = <EMPLOYEE_ID cua at_cv> AND SF.SEND_DATE >= TRUNC(SYSDATE) - 365 AND SF.SEND_DATE < TRUNC(SYSDATE) + 1 GROUP BY SF.SUBMISSION_FORM_ID ) 4. So sánh kết quả câu lệnh với số trên ô | D26: Kết quả câu lệnh bằng đúng số hiển thị trên ô (3). Câu lệnh chỉ đọc, không làm thay đổi dữ liệu. | Q26: =IF(OR(IF(G26="",IF(F26="",IF(E26="","",E26),F26),G26)="F",IF(J26="",IF(I26="",IF(H26="","",H26),I26),J26)="F",IF(M26="",IF(L26="",IF(K26="","",K26),L26),M26)="F",IF(P26="",IF(O26="",IF(N26="","",N26),O26),P26)="F")=TRUE,"F",IF(OR(IF(G26="",IF(F26="",IF(E26="","",E26),F26),G26)="PE",IF(J26="",IF(I26="",IF(H26="","",H26),I26),J26)="PE",IF(M26="",IF(L26="",IF(K26="","",K26),L26),M26)="PE",IF(P26="",IF(O26="",IF(N26="","",N26),O26),P26)="PE")=TRUE,"PE",IF(AND(IF(G26="",IF(F26="",IF(E26="","",E26),F26),G26)="",IF(J26="",IF(I26="",IF(H26="","",H26),I26),J26)="",IF(M26="",IF(L26="",IF(K26="","",K26),L26),M26)="",IF(P26="",IF(O26="",IF(N26="","",N26),O26),P26)="")=TRUE,"","P")))
A27: =IF(AND(C27="",C27=""),"",$D$3&"_"&ROW()-12-COUNTBLANK($C$13:C27)) | B27: Kiểm tra số trên ô cập nhật sau khi được chuyển thêm phiếu mới | C27: 1. Đăng nhập vào at_cv/123 >> Trang chủ >> ghi lại số trên ô "Nhận để biết" (3) 2. Đăng nhập at_vt/123 ở trình duyệt khác >> PHIẾU TRÌNH >> Trình xin ý kiến >> chọn PT5 (đã phê duyệt) >> Chuyển tiếp >> chọn at_cv >> Gửi 3. Quay lại tài khoản at_cv >> tải lại Trang chủ 4. Đọc lại số trên ô "Nhận để biết" | D27: Số trên ô tăng từ 3 lên 4. Màn Phiếu trình nhận để biết của at_cv có thêm dòng PT5, đang in đậm vì chưa đọc. Sau khi kiểm xong, trả lại dữ liệu như ban đầu để các testcase khác dùng đúng số 3. | Q27: =IF(OR(IF(G27="",IF(F27="",IF(E27="","",E27),F27),G27)="F",IF(J27="",IF(I27="",IF(H27="","",H27),I27),J27)="F",IF(M27="",IF(L27="",IF(K27="","",K27),L27),M27)="F",IF(P27="",IF(O27="",IF(N27="","",N27),O27),P27)="F")=TRUE,"F",IF(OR(IF(G27="",IF(F27="",IF(E27="","",E27),F27),G27)="PE",IF(J27="",IF(I27="",IF(H27="","",H27),I27),J27)="PE",IF(M27="",IF(L27="",IF(K27="","",K27),L27),M27)="PE",IF(P27="",IF(O27="",IF(N27="","",N27),O27),P27)="PE")=TRUE,"PE",IF(AND(IF(G27="",IF(F27="",IF(E27="","",E27),F27),G27)="",IF(J27="",IF(I27="",IF(H27="","",H27),I27),J27)="",IF(M27="",IF(L27="",IF(K27="","",K27),L27),M27)="",IF(P27="",IF(O27="",IF(N27="","",N27),O27),P27)="")=TRUE,"","P"))) | S27: Chạy testcase này sau các testcase đếm số, vì nó làm thay đổi số liệu chuẩn bị.
A28: =IF(AND(C28="",C28=""),"",$D$3&"_"&ROW()-12-COUNTBLANK($C$13:C28)) | B28: Bấm vào ô "Nhận để biết"
A29: =IF(AND(C29="",C29=""),"",$D$3&"_"&ROW()-12-COUNTBLANK($C$13:C29)) | B29: Kiểm tra điều hướng và bộ lọc mặc định khi bấm ô | C29: 1. Đăng nhập vào at_cv/123 2. Trang chủ >> thẻ "Phiếu trình" >> bấm vào ô "Nhận để biết" 3. Kiểm tra màn được mở và các ô lọc trên màn 4. Đếm số dòng trong danh sách | D29: Hệ thống mở màn "Phiếu trình nhận để biết" (đúng màn của menu PHIẾU TRÌNH >> Phiếu trình nhận để biết). Bộ lọc Ngày gửi mặc định từ hôm nay trừ 365 ngày đến hôm nay. Ô lọc Tiêu đề để trống, ô lọc Người gửi để trống, KHÔNG có bộ lọc chỉ phiếu chưa đọc. Danh sách hiển thị 3 dòng, PT2 và PT3 in đậm. | Q29: =IF(OR(IF(G29="",IF(F29="",IF(E29="","",E29),F29),G29)="F",IF(J29="",IF(I29="",IF(H29="","",H29),I29),J29)="F",IF(M29="",IF(L29="",IF(K29="","",K29),L29),M29)="F",IF(P29="",IF(O29="",IF(N29="","",N29),O29),P29)="F")=TRUE,"F",IF(OR(IF(G29="",IF(F29="",IF(E29="","",E29),F29),G29)="PE",IF(J29="",IF(I29="",IF(H29="","",H29),I29),J29)="PE",IF(M29="",IF(L29="",IF(K29="","",K29),L29),M29)="PE",IF(P29="",IF(O29="",IF(N29="","",N29),O29),P29)="PE")=TRUE,"PE",IF(AND(IF(G29="",IF(F29="",IF(E29="","",E29),F29),G29)="",IF(J29="",IF(I29="",IF(H29="","",H29),I29),J29)="",IF(M29="",IF(L29="",IF(K29="","",K29),L29),M29)="",IF(P29="",IF(O29="",IF(N29="","",N29),O29),P29)="")=TRUE,"","P")))
A30: =IF(AND(C30="",C30=""),"",$D$3&"_"&ROW()-12-COUNTBLANK($C$13:C30)) | B30: Kiểm tra bấm ô không làm phiếu thành đã đọc | C30: 1. Đăng nhập vào at_cv/123 2. Trang chủ >> ghi lại số trên ô "Nhận để biết" (3) và ghi lại phiếu nào đang in đậm 3. Bấm vào ô "Nhận để biết" để mở màn danh sách 4. KHÔNG mở chi tiết phiếu nào, quay lại Trang chủ 5. Mở lại màn Phiếu trình nhận để biết và kiểm tra lại các dòng in đậm | D30: PT2 và PT3 VẪN in đậm (vẫn là chưa đọc). Số trên ô vẫn là 3, không đổi. Không phát sinh dòng chuyển tiếp mới, không có thông báo hay SMS nào được gửi. | Q30: =IF(OR(IF(G30="",IF(F30="",IF(E30="","",E30),F30),G30)="F",IF(J30="",IF(I30="",IF(H30="","",H30),I30),J30)="F",IF(M30="",IF(L30="",IF(K30="","",K30),L30),M30)="F",IF(P30="",IF(O30="",IF(N30="","",N30),O30),P30)="F")=TRUE,"F",IF(OR(IF(G30="",IF(F30="",IF(E30="","",E30),F30),G30)="PE",IF(J30="",IF(I30="",IF(H30="","",H30),I30),J30)="PE",IF(M30="",IF(L30="",IF(K30="","",K30),L30),M30)="PE",IF(P30="",IF(O30="",IF(N30="","",N30),O30),P30)="PE")=TRUE,"PE",IF(AND(IF(G30="",IF(F30="",IF(E30="","",E30),F30),G30)="",IF(J30="",IF(I30="",IF(H30="","",H30),I30),J30)="",IF(M30="",IF(L30="",IF(K30="","",K30),L30),M30)="",IF(P30="",IF(O30="",IF(N30="","",N30),O30),P30)="")=TRUE,"","P")))
A31: =IF(AND(C31="",C31=""),"",$D$3&"_"&ROW()-12-COUNTBLANK($C$13:C31)) | B31: Kiểm tra bấm ô hai lần liên tiếp | C31: 1. Đăng nhập vào at_cv/123 2. Trang chủ >> thẻ "Phiếu trình" >> bấm vào ô "Nhận để biết" hai lần liên tiếp 3. Đếm số tab đang mở trên thanh tab | D31: Màn Phiếu trình nhận để biết chỉ được mở một lần, không mở trùng hai tab. Không hiện lỗi, dữ liệu trên màn vẫn đúng 3 dòng. | Q31: =IF(OR(IF(G31="",IF(F31="",IF(E31="","",E31),F31),G31)="F",IF(J31="",IF(I31="",IF(H31="","",H31),I31),J31)="F",IF(M31="",IF(L31="",IF(K31="","",K31),L31),M31)="F",IF(P31="",IF(O31="",IF(N31="","",N31),O31),P31)="F")=TRUE,"F",IF(OR(IF(G31="",IF(F31="",IF(E31="","",E31),F31),G31)="PE",IF(J31="",IF(I31="",IF(H31="","",H31),I31),J31)="PE",IF(M31="",IF(L31="",IF(K31="","",K31),L31),M31)="PE",IF(P31="",IF(O31="",IF(N31="","",N31),O31),P31)="PE")=TRUE,"PE",IF(AND(IF(G31="",IF(F31="",IF(E31="","",E31),F31),G31)="",IF(J31="",IF(I31="",IF(H31="","",H31),I31),J31)="",IF(M31="",IF(L31="",IF(K31="","",K31),L31),M31)="",IF(P31="",IF(O31="",IF(N31="","",N31),O31),P31)="")=TRUE,"","P")))
A32: =IF(AND(C32="",C32=""),"",$D$3&"_"&ROW()-12-COUNTBLANK($C$13:C32)) | B32: Bật / tắt ô tại màn Cấu hình trang chủ
A33: =IF(AND(C33="",C33=""),"",$D$3&"_"&ROW()-12-COUNTBLANK($C$13:C33)) | B33: Kiểm tra tắt ô "Nhận để biết" | C33: 1. Đăng nhập vào at_cv/123 2. Khung người dùng góc phải >> Cấu hình trang chủ 3. Bỏ tick dòng "Nhận để biết" dưới nhóm "Phiếu trình" 4. Bấm nút Lưu >> chọn OK ở popup xác nhận 5. Mở lại Trang chủ và đếm số ô của thẻ "Phiếu trình" | D33: Hiện thông báo lưu thành công. Thẻ "Phiếu trình" còn 5 ô: Chờ xử lý, Đang xử lý, Đã phê duyệt, Tất cả, Xin ý kiến. Không còn ô "Nhận để biết"; 5 ô còn lại giữ nguyên số đếm và vị trí như trước khi tắt. | Q33: =IF(OR(IF(G33="",IF(F33="",IF(E33="","",E33),F33),G33)="F",IF(J33="",IF(I33="",IF(H33="","",H33),I33),J33)="F",IF(M33="",IF(L33="",IF(K33="","",K33),L33),M33)="F",IF(P33="",IF(O33="",IF(N33="","",N33),O33),P33)="F")=TRUE,"F",IF(OR(IF(G33="",IF(F33="",IF(E33="","",E33),F33),G33)="PE",IF(J33="",IF(I33="",IF(H33="","",H33),I33),J33)="PE",IF(M33="",IF(L33="",IF(K33="","",K33),L33),M33)="PE",IF(P33="",IF(O33="",IF(N33="","",N33),O33),P33)="PE")=TRUE,"PE",IF(AND(IF(G33="",IF(F33="",IF(E33="","",E33),F33),G33)="",IF(J33="",IF(I33="",IF(H33="","",H33),I33),J33)="",IF(M33="",IF(L33="",IF(K33="","",K33),L33),M33)="",IF(P33="",IF(O33="",IF(N33="","",N33),O33),P33)="")=TRUE,"","P")))
A34: =IF(AND(C34="",C34=""),"",$D$3&"_"&ROW()-12-COUNTBLANK($C$13:C34)) | B34: Kiểm tra bật lại ô "Nhận để biết" | C34: 1. Đăng nhập vào at_cv/123 (đang ở trạng thái đã tắt ô ở testcase trước) 2. Khung người dùng góc phải >> Cấu hình trang chủ 3. Tick lại dòng "Nhận để biết" 4. Bấm nút Lưu >> chọn OK ở popup xác nhận 5. Mở lại Trang chủ | D34: Ô "Nhận để biết" hiện lại ở cuối thẻ "Phiếu trình", sau ô "Xin ý kiến". Số trên ô là 3, đúng như trước khi tắt. | Q34: =IF(OR(IF(G34="",IF(F34="",IF(E34="","",E34),F34),G34)="F",IF(J34="",IF(I34="",IF(H34="","",H34),I34),J34)="F",IF(M34="",IF(L34="",IF(K34="","",K34),L34),M34)="F",IF(P34="",IF(O34="",IF(N34="","",N34),O34),P34)="F")=TRUE,"F",IF(OR(IF(G34="",IF(F34="",IF(E34="","",E34),F34),G34)="PE",IF(J34="",IF(I34="",IF(H34="","",H34),I34),J34)="PE",IF(M34="",IF(L34="",IF(K34="","",K34),L34),M34)="PE",IF(P34="",IF(O34="",IF(N34="","",N34),O34),P34)="PE")=TRUE,"PE",IF(AND(IF(G34="",IF(F34="",IF(E34="","",E34),F34),G34)="",IF(J34="",IF(I34="",IF(H34="","",H34),I34),J34)="",IF(M34="",IF(L34="",IF(K34="","",K34),L34),M34)="",IF(P34="",IF(O34="",IF(N34="","",N34),O34),P34)="")=TRUE,"","P")))
A35: =IF(AND(C35="",C35=""),"",$D$3&"_"&ROW()-12-COUNTBLANK($C$13:C35)) | B35: Kiểm tra bỏ tick cả 6 ô của nhóm Phiếu trình | C35: 1. Đăng nhập vào at_cv/123 2. Khung người dùng góc phải >> Cấu hình trang chủ 3. Bỏ tick lần lượt cả 6 dòng con của nhóm "Phiếu trình" 4. Bấm Lưu >> OK 5. Mở lại Trang chủ 6. Quay lại Cấu hình trang chủ, tick lại cả 6 dòng >> Lưu >> OK để trả về trạng thái ban đầu | D35: Sau bước 5: thẻ "Phiếu trình" không hiển thị trên trang chủ, kể cả ô mới. Dòng nhóm "Phiếu trình" ở màn cấu hình cũng tự bỏ tick. Sau bước 6: thẻ hiển thị lại đủ 6 ô. | Q35: =IF(OR(IF(G35="",IF(F35="",IF(E35="","",E35),F35),G35)="F",IF(J35="",IF(I35="",IF(H35="","",H35),I35),J35)="F",IF(M35="",IF(L35="",IF(K35="","",K35),L35),M35)="F",IF(P35="",IF(O35="",IF(N35="","",N35),O35),P35)="F")=TRUE,"F",IF(OR(IF(G35="",IF(F35="",IF(E35="","",E35),F35),G35)="PE",IF(J35="",IF(I35="",IF(H35="","",H35),I35),J35)="PE",IF(M35="",IF(L35="",IF(K35="","",K35),L35),M35)="PE",IF(P35="",IF(O35="",IF(N35="","",N35),O35),P35)="PE")=TRUE,"PE",IF(AND(IF(G35="",IF(F35="",IF(E35="","",E35),F35),G35)="",IF(J35="",IF(I35="",IF(H35="","",H35),I35),J35)="",IF(M35="",IF(L35="",IF(K35="","",K35),L35),M35)="",IF(P35="",IF(O35="",IF(N35="","",N35),O35),P35)="")=TRUE,"","P")))
A36: =IF(AND(C36="",C36=""),"",$D$3&"_"&ROW()-12-COUNTBLANK($C$13:C36)) | B36: Kiểm tra người đã lưu cấu hình trang chủ riêng từ trước vẫn thấy ô mới | C36: 1. Đăng nhập vào at_ld/123 2. Khung người dùng góc phải >> Cấu hình trang chủ >> bỏ tick một ô bất kỳ của nhóm khác (ví dụ nhóm "Văn bản đến") >> Lưu >> OK (bước này giả lập người dùng đã từng tự sửa cấu hình trang chủ) 3. Nhờ DEV khai lại ô "Nhận để biết" hoặc khởi động lại ứng dụng để mô phỏng việc ô mới được thêm sau 4. Đăng nhập lại at_ld/123 >> Khung người dùng góc phải >> Cấu hình trang chủ 5. Kiểm tra dòng "Nhận để biết" và mở Trang chủ | D36: Dòng "Nhận để biết" có mặt trong danh sách và ĐANG ĐƯỢC TICK. Trang chủ của at_ld hiển thị ô "Nhận để biết" với số 2. Ô mà at_ld đã tự tắt trước đó vẫn ở trạng thái tắt, không bị bật lại. | Q36: =IF(OR(IF(G36="",IF(F36="",IF(E36="","",E36),F36),G36)="F",IF(J36="",IF(I36="",IF(H36="","",H36),I36),J36)="F",IF(M36="",IF(L36="",IF(K36="","",K36),L36),M36)="F",IF(P36="",IF(O36="",IF(N36="","",N36),O36),P36)="F")=TRUE,"F",IF(OR(IF(G36="",IF(F36="",IF(E36="","",E36),F36),G36)="PE",IF(J36="",IF(I36="",IF(H36="","",H36),I36),J36)="PE",IF(M36="",IF(L36="",IF(K36="","",K36),L36),M36)="PE",IF(P36="",IF(O36="",IF(N36="","",N36),O36),P36)="PE")=TRUE,"PE",IF(AND(IF(G36="",IF(F36="",IF(E36="","",E36),F36),G36)="",IF(J36="",IF(I36="",IF(H36="","",H36),I36),J36)="",IF(M36="",IF(L36="",IF(K36="","",K36),L36),M36)="",IF(P36="",IF(O36="",IF(N36="","",N36),O36),P36)="")=TRUE,"","P"))) | S36: Bước 3 cần DEV hỗ trợ; nếu môi trường test đã có sẵn tài khoản từng lưu cấu hình riêng thì dùng luôn tài khoản đó.
A37: =IF(AND(C37="",C37=""),"",$D$3&"_"&ROW()-12-COUNTBLANK($C$13:C37)) | B37: Chế độ trang chủ đơn giản
A38: =IF(AND(C38="",C38=""),"",$D$3&"_"&ROW()-12-COUNTBLANK($C$13:C38)) | B38: Kiểm tra ô hiển thị ở chế độ đơn giản với người không phải văn thư | C38: 1. Đăng nhập vào at_cv/123 2. Khung người dùng góc phải >> chọn chế độ trang chủ đơn giản 3. Kéo tới thẻ "Phiếu trình" và đếm số ô 4. Đọc số trên ô "Nhận để biết" | D38: Thẻ "Phiếu trình" hiển thị 2 ô: "Chờ xử lý" và "Nhận để biết". Ô "Nhận để biết" hiển thị số 3, bằng đúng số ở chế độ đầy đủ. Các ô Đang xử lý, Đã phê duyệt, Tất cả, Xin ý kiến vẫn không hiện ở chế độ này như hiện tại. | Q38: =IF(OR(IF(G38="",IF(F38="",IF(E38="","",E38),F38),G38)="F",IF(J38="",IF(I38="",IF(H38="","",H38),I38),J38)="F",IF(M38="",IF(L38="",IF(K38="","",K38),L38),M38)="F",IF(P38="",IF(O38="",IF(N38="","",N38),O38),P38)="F")=TRUE,"F",IF(OR(IF(G38="",IF(F38="",IF(E38="","",E38),F38),G38)="PE",IF(J38="",IF(I38="",IF(H38="","",H38),I38),J38)="PE",IF(M38="",IF(L38="",IF(K38="","",K38),L38),M38)="PE",IF(P38="",IF(O38="",IF(N38="","",N38),O38),P38)="PE")=TRUE,"PE",IF(AND(IF(G38="",IF(F38="",IF(E38="","",E38),F38),G38)="",IF(J38="",IF(I38="",IF(H38="","",H38),I38),J38)="",IF(M38="",IF(L38="",IF(K38="","",K38),L38),M38)="",IF(P38="",IF(O38="",IF(N38="","",N38),O38),P38)="")=TRUE,"","P")))
A39: =IF(AND(C39="",C39=""),"",$D$3&"_"&ROW()-12-COUNTBLANK($C$13:C39)) | B39: Kiểm tra ô hiển thị ở chế độ đơn giản với tài khoản văn thư | C39: 1. Đăng nhập vào at_vt/123 2. Khung người dùng góc phải >> chọn chế độ trang chủ đơn giản 3. Kéo tới thẻ "Phiếu trình" và đếm số ô 4. Đọc số trên ô "Nhận để biết" | D39: Thẻ "Phiếu trình" hiển thị 2 ô: "Chờ xử lý" và "Nhận để biết". Ô "Nhận để biết" hiển thị số 0 và không bị ẩn. Văn thư và người không phải văn thư đều thấy ô này ở chế độ đơn giản. | Q39: =IF(OR(IF(G39="",IF(F39="",IF(E39="","",E39),F39),G39)="F",IF(J39="",IF(I39="",IF(H39="","",H39),I39),J39)="F",IF(M39="",IF(L39="",IF(K39="","",K39),L39),M39)="F",IF(P39="",IF(O39="",IF(N39="","",N39),O39),P39)="F")=TRUE,"F",IF(OR(IF(G39="",IF(F39="",IF(E39="","",E39),F39),G39)="PE",IF(J39="",IF(I39="",IF(H39="","",H39),I39),J39)="PE",IF(M39="",IF(L39="",IF(K39="","",K39),L39),M39)="PE",IF(P39="",IF(O39="",IF(N39="","",N39),O39),P39)="PE")=TRUE,"PE",IF(AND(IF(G39="",IF(F39="",IF(E39="","",E39),F39),G39)="",IF(J39="",IF(I39="",IF(H39="","",H39),I39),J39)="",IF(M39="",IF(L39="",IF(K39="","",K39),L39),M39)="",IF(P39="",IF(O39="",IF(N39="","",N39),O39),P39)="")=TRUE,"","P")))
A40: =IF(AND(C40="",C40=""),"",$D$3&"_"&ROW()-12-COUNTBLANK($C$13:C40)) | B40: Trường hợp đặc biệt
A41: =IF(AND(C41="",C41=""),"",$D$3&"_"&ROW()-12-COUNTBLANK($C$13:C41)) | B41: Kiểm tra khi phép đếm quá thời gian chờ | C41: 1. Đăng nhập vào at_cv/123 2. Nhờ DEV mô phỏng phép đếm của thẻ "Phiếu trình" chạy quá 20 giây trên môi trường test 3. Tải lại Trang chủ >> thẻ "Phiếu trình" và chờ trang tải xong 4. Đọc số trên ô "Nhận để biết" và kiểm tra các thẻ khác của trang chủ | D41: Ô "Nhận để biết" hiển thị số 0. Trang chủ vẫn tải xong, không treo, không hiện thông báo lỗi cho người dùng. Các thẻ khác của trang chủ vẫn hiển thị bình thường. | Q41: =IF(OR(IF(G41="",IF(F41="",IF(E41="","",E41),F41),G41)="F",IF(J41="",IF(I41="",IF(H41="","",H41),I41),J41)="F",IF(M41="",IF(L41="",IF(K41="","",K41),L41),M41)="F",IF(P41="",IF(O41="",IF(N41="","",N41),O41),P41)="F")=TRUE,"F",IF(OR(IF(G41="",IF(F41="",IF(E41="","",E41),F41),G41)="PE",IF(J41="",IF(I41="",IF(H41="","",H41),I41),J41)="PE",IF(M41="",IF(L41="",IF(K41="","",K41),L41),M41)="PE",IF(P41="",IF(O41="",IF(N41="","",N41),O41),P41)="PE")=TRUE,"PE",IF(AND(IF(G41="",IF(F41="",IF(E41="","",E41),F41),G41)="",IF(J41="",IF(I41="",IF(H41="","",H41),I41),J41)="",IF(M41="",IF(L41="",IF(K41="","",K41),L41),M41)="",IF(P41="",IF(O41="",IF(N41="","",N41),O41),P41)="")=TRUE,"","P"))) | S41: Cần DEV hỗ trợ dựng tình huống; không tạo được bằng thao tác giao diện.
...
