Workbook

Sheet Trang bìa
E1: TẬP ĐOÀN CÔNG NGHIỆP VIỄN THÔNG QUÂN ĐỘI
E2: TỔNG CÔNG TY GIẢI PHÁP DOANH NGHIỆP VIETTEL
A9: <VOFFICE KHA>
A10: TÀI LIỆU KỊCH BẢN KIỂM THỬ CHỨC NĂNG
A11: NV_08 - Thêm hạn xử lý ở Danh sách người cùng nhận
C16: Mã dự án | D16: :
C17: Mã tài liệu | D17: :
A20: Người lập:
C21: <Tên người nhập> | F21: <Ngày lập>
C22: <Chức vụ>
A26: Người kiểm tra:
C27: <Tên người kiểm tra | F27: <Ngày kiểm tra>
C28: <Chức vụ>
A32: Người phê duyệt:
C33: <Tên người phê duyệt> | F33: <Ngày phê duyệt>
C34: <Chức vụ>
A37: BẢNG GHI NHẬN THAY ĐỔI TÀI LIỆU
A39: Ngày thay đổi | B39: Vị trí thay đổi | C39: Lý do | D39: Nguồn gốc | E39: Phiên bản cũ | F39: Mô tả thay đổi | G39: Phiên bản mới

Sheet Giới thiệu
A1: GIỚI THIỆU
A3: 1 - Giới thiệu
A8: 2 - Tài liệu tham khảo
A9: STT | B9: Tên tài liệu | C9: Tên file | D9: Phiên bản | E9: Đường dẫn
A10: 1
A15: 3 - Môi trường kiểm thử
A16: STT | B16: Trình duyệt | C16: Phiên bản | E16: Viết tắt
B17: Chrome | C17: 131 | E17: C
B18: Microsoft Edge | C18: 131 | E18: ME
B19: Cấu hình server test
B20: CPU: 4G, Duecore, Ram 8G, HDD: 320G
B21: Tool test | C21: Phiên bản | E21: Mục đích

Sheet Tổng hợp
A1: TỔNG HỢP KẾT QUẢ
A3: STT | B3: Tên màn hình/chức năng | C3: Số trường hợp kiểm thử đạt (P) | D3: Số trường hợp kiểm thử không đạt (F) | E3: Số trường hợp kiểm thử đang xem xét (PE) | F3: Số trường hợp kiểm thử chưa thực hiện | G3: Tổng số trường hợp kiểm thử | H3: Tỉ lệ trường hợp kiểm thử đạt (%P) | I3: Tỉ lệ trường hợp kiểm thử không đạt (%F) | J3: Tỉ lệ trường hợp kiểm thử đã thực hiện (%Cover)
A4: 1 | B4: ='NV_08_Web'!D2&" - Web" | C4: ='NV_08_Web'!D4 | D4: ='NV_08_Web'!D5 | E4: ='NV_08_Web'!D6 | F4: ='NV_08_Web'!D7 | G4: ='NV_08_Web'!D8 | H4: =IFERROR(C4/G4,0) | I4: =IFERROR(D4/G4,0) | J4: =IFERROR((C4+D4)/G4,0)
A5: 2 | B5: ='NV_08_App'!D2&" - App" | C5: ='NV_08_App'!D4 | D5: ='NV_08_App'!D5 | E5: ='NV_08_App'!D6 | F5: ='NV_08_App'!D7 | G5: ='NV_08_App'!D8 | H5: =IFERROR(C5/G5,0) | I5: =IFERROR(D5/G5,0) | J5: =IFERROR((C5+D5)/G5,0)
A12: Total | C12: =SUM(C4:C11) | D12: =SUM(D4:D11) | E12: =SUM(E4:E11) | F12: =SUM(F4:F11) | G12: =SUM(G4:G11) | H12: =IFERROR(C12/G12,0) | I12: =IFERROR(D12/G12,0) | J12: =IFERROR((C12+D12)/G12,0)

Sheet NV_08_Web
C1: KỊCH BẢN KIỂM THỬ *
C2: Tên màn hình/Tên chức năng | D2: NV_08_Thêm hạn xử lý ở Danh sách người cùng nhận
C3: Mã trường hợp kiểm thử | D3: NV_08
C4: Số trường hợp kiểm thử đạt (P) | D4: =COUNTIF($E$13:$E$52,"P")
C5: Số trường hợp kiểm thử không đạt (F) | D5: =COUNTIF($E$13:$E$52,"F")
C6: Số trường hợp kiểm thử đang xem xét (PE) | D6: =COUNTIF($Q$13:$Q$52,"PE")
C7: Số trường hợp kiểm thử chưa thực hiện | D7: =D8-D4-D5-D6
C8: Tổng số trường hợp kiểm thử | D8: =COUNTA($Q$13:$Q$52)
A10: Mã trường hợp kiểm thử | B10: Mục đích kiểm thử | C10: Các bước thực hiện | D10: Kết quả mong muốn | E10: PC | H10: Firefox | K10: <Tên trình duyệt 3> | N10: <Tên trình duyệt 4> | Q10: Kết quả hiện tại | R10: Mã lỗi | S10: Ghi chú
E11: Lần 1 | F11: Lần 2 | G11: Lần 3 | H11: Lần 1 | I11: Lần 2 | J11: Lần 3 | K11: Lần 1 | L11: Lần 2 | M11: Lần 3 | N11: Lần 1 | O11: Lần 2 | P11: Lần 3
B12: NV_08_Thêm hạn xử lý ở Danh sách người cùng nhận_Web
B13: A: Các bước thực hiện Pre- condition: 1. Truy cập hệ thống trên môi trường kiểm thử: <điền link môi trường test> 2. Tài khoản: Văn thư <acc VT>, Lãnh đạo <acc LĐ>, Chuyên viên <acc CV> 3. Dữ liệu chuẩn bị (tạo bằng chính chức năng Chuyển văn bản): - VB1: văn bản đến, chuyển 1 lần cho 2 cá nhân, CÓ nhập hạn xử lý - VB2: văn bản đến, chuyển cho 1 cá nhân, KHÔNG nhập hạn - VB3: văn bản đến, chuyển 2 lần với 2 hạn khác nhau, trong đó 1 lần chuyển cho đơn vị - VB4: văn bản đến có dòng nhận đã quá hạn, chưa hoàn thành - VB5: văn bản đã ban hành, đã chuyển đi - VB6: văn bản mật, đã chuyển cho người có quyền xem mật - VB7: văn bản chưa chuyển cho ai - VB8: văn bản có trên 5 dòng trong Danh sách người cùng nhận - VB9: văn bản qua 2 cấp chuyển, mỗi cấp một hạn khác nhau B: Mô tả chức năng Bổ sung cột "Hạn xử lý" vào panel "Danh sách người/ đơn vị cùng nhận" của màn chi tiết văn bản, đặt ngay sau cột "Thời gian chuyển". Mỗi dòng hiển thị hạn xử lý của chính dòng nhận đó. Không có hạn thì để trống. Không tô màu cảnh báo quá hạn. Cột chỉ đọc. Áp dụng cho văn bản đến và văn bản đã ban hành, trên Web và App. C: Các bảng tác động - DOCUMENT_IN_STAFF, cột DEADLINE_DATE (chỉ đọc) - DOCUMENT_IN_GROUP, cột DEADLINE_DATE (chỉ đọc) - DOCUMENT_PROCESS, dùng để xác định dòng cấp trên (chỉ đọc) Không thêm bảng, không thêm cột, không cần migration.
A14: =IF(AND(C14="",C14=""),"",$D$3&"_"&ROW()-12-COUNTBLANK($C$13:C14)) | B14: Giao diện (Phần này viết các trường hợp kiểm thử cho giao diên chung và các giao diện cho các control)
A15: =IF(AND(C15="",C15=""),"",$D$3&"_"&ROW()-12-COUNTBLANK($C$13:C15)) | B15: Kiểm tra tổng thể giao diện màn hình | C15: 1. Mở chi tiết văn bản VB1 2. Mở panel "Danh sách người/ đơn vị cùng nhận" 3. Kiểm tra title, bố cục, font chữ, chính tả của bảng | D15: 1. Bố cục - Form được bố trí hợp lý và dễ sử dụng 2. Font chữ và màu chữ: - Các text sử dụng cùng 1 loại font chữ, cỡ chữ - Màu chữ giống giao diện prototype 3. Chính tả: Không có lỗi về chính tả, cấu trúc câu, ngữ pháp trên màn hình | Q15: =IF(OR(IF(G15="",IF(F15="",IF(E15="","",E15),F15),G15)="F",IF(J15="",IF(I15="",IF(H15="","",H15),I15),J15)="F",IF(M15="",IF(L15="",IF(K15="","",K15),L15),M15)="F",IF(P15="",IF(O15="",IF(N15="","",N15),O15),P15)="F")=TRUE,"F",IF(OR(IF(G15="",IF(F15="",IF(E15="","",E15),F15),G15)="PE",IF(J15="",IF(I15="",IF(H15="","",H15),I15),J15)="PE",IF(M15="",IF(L15="",IF(K15="","",K15),L15),M15)="PE",IF(P15="",IF(O15="",IF(N15="","",N15),O15),P15)="PE")=TRUE,"PE",IF(AND(IF(G15="",IF(F15="",IF(E15="","",E15),F15),G15)="",IF(J15="",IF(I15="",IF(H15="","",H15),I15),J15)="",IF(M15="",IF(L15="",IF(K15="","",K15),L15),M15)="",IF(P15="",IF(O15="",IF(N15="","",N15),O15),P15)="")=TRUE,"","P")))
A16: =IF(AND(C16="",C16=""),"",$D$3&"_"&ROW()-12-COUNTBLANK($C$13:C16)) | B16: Kiểm tra vị trí và nhãn của cột Hạn xử lý | C16: 1. Mở chi tiết văn bản VB1 2. Mở panel "Danh sách người/ đơn vị cùng nhận" 3. Đếm số cột và kiểm tra thứ tự cột | D16: Bảng hiển thị 9 cột. Cột "Hạn xử lý" nằm ở vị trí thứ 3, ngay sau cột "Thời gian chuyển" và trước cột "Người chuyển". 7 cột cũ giữ nguyên tên và thứ tự tương đối. Nhãn cột đúng chính tả, cùng font và cỡ chữ với các nhãn cột còn lại. | Q16: =IF(OR(IF(G16="",IF(F16="",IF(E16="","",E16),F16),G16)="F",IF(J16="",IF(I16="",IF(H16="","",H16),I16),J16)="F",IF(M16="",IF(L16="",IF(K16="","",K16),L16),M16)="F",IF(P16="",IF(O16="",IF(N16="","",N16),O16),P16)="F")=TRUE,"F",IF(OR(IF(G16="",IF(F16="",IF(E16="","",E16),F16),G16)="PE",IF(J16="",IF(I16="",IF(H16="","",H16),I16),J16)="PE",IF(M16="",IF(L16="",IF(K16="","",K16),L16),M16)="PE",IF(P16="",IF(O16="",IF(N16="","",N16),O16),P16)="PE")=TRUE,"PE",IF(AND(IF(G16="",IF(F16="",IF(E16="","",E16),F16),G16)="",IF(J16="",IF(I16="",IF(H16="","",H16),I16),J16)="",IF(M16="",IF(L16="",IF(K16="","",K16),L16),M16)="",IF(P16="",IF(O16="",IF(N16="","",N16),O16),P16)="")=TRUE,"","P")))
A17: =IF(AND(C17="",C17=""),"",$D$3&"_"&ROW()-12-COUNTBLANK($C$13:C17)) | B17: Kiểm tra căn lề và định dạng hiển thị của cột Hạn xử lý | C17: 1. Mở chi tiết văn bản VB1 2. Quan sát nội dung các ô của cột Hạn xử lý | D17: Giá trị hiển thị dạng dd/MM/yyyy, ví dụ 15/10/2026. Không hiển thị giờ phút, khác với cột "Thời gian chuyển" bên cạnh. Nội dung căn giữa, cùng màu chữ với các cột khác, không in đậm, không tô màu nền. | Q17: =IF(OR(IF(G17="",IF(F17="",IF(E17="","",E17),F17),G17)="F",IF(J17="",IF(I17="",IF(H17="","",H17),I17),J17)="F",IF(M17="",IF(L17="",IF(K17="","",K17),L17),M17)="F",IF(P17="",IF(O17="",IF(N17="","",N17),O17),P17)="F")=TRUE,"F",IF(OR(IF(G17="",IF(F17="",IF(E17="","",E17),F17),G17)="PE",IF(J17="",IF(I17="",IF(H17="","",H17),I17),J17)="PE",IF(M17="",IF(L17="",IF(K17="","",K17),L17),M17)="PE",IF(P17="",IF(O17="",IF(N17="","",N17),O17),P17)="PE")=TRUE,"PE",IF(AND(IF(G17="",IF(F17="",IF(E17="","",E17),F17),G17)="",IF(J17="",IF(I17="",IF(H17="","",H17),I17),J17)="",IF(M17="",IF(L17="",IF(K17="","",K17),L17),M17)="",IF(P17="",IF(O17="",IF(N17="","",N17),O17),P17)="")=TRUE,"","P")))
A18: =IF(AND(C18="",C18=""),"",$D$3&"_"&ROW()-12-COUNTBLANK($C$13:C18)) | B18: Kiểm tra bảng không tràn ngang sau khi thêm cột | C18: 1. Mở chi tiết văn bản VB8 ở độ phân giải thường dùng 2. Thu nhỏ cửa sổ trình duyệt 3. Nhấn Ctrl và dấu trừ, Ctrl và dấu bằng để thu nhỏ, phóng to | D18: Bảng hiển thị đủ 9 cột, không phải cuộn ngang ở độ phân giải thường dùng. Thu nhỏ, phóng to không vỡ bố cục, không chồng chữ. Trỏ chuột vào ô tên đơn vị bị cắt chữ vẫn hiện đầy đủ nội dung. | Q18: =IF(OR(IF(G18="",IF(F18="",IF(E18="","",E18),F18),G18)="F",IF(J18="",IF(I18="",IF(H18="","",H18),I18),J18)="F",IF(M18="",IF(L18="",IF(K18="","",K18),L18),M18)="F",IF(P18="",IF(O18="",IF(N18="","",N18),O18),P18)="F")=TRUE,"F",IF(OR(IF(G18="",IF(F18="",IF(E18="","",E18),F18),G18)="PE",IF(J18="",IF(I18="",IF(H18="","",H18),I18),J18)="PE",IF(M18="",IF(L18="",IF(K18="","",K18),L18),M18)="PE",IF(P18="",IF(O18="",IF(N18="","",N18),O18),P18)="PE")=TRUE,"PE",IF(AND(IF(G18="",IF(F18="",IF(E18="","",E18),F18),G18)="",IF(J18="",IF(I18="",IF(H18="","",H18),I18),J18)="",IF(M18="",IF(L18="",IF(K18="","",K18),L18),M18)="",IF(P18="",IF(O18="",IF(N18="","",N18),O18),P18)="")=TRUE,"","P")))
A19: =IF(AND(C19="",C19=""),"",$D$3&"_"&ROW()-12-COUNTBLANK($C$13:C19)) | B19: Kiểm tra cột Hạn xử lý là cột chỉ đọc | C19: 1. Mở chi tiết văn bản VB1 2. Click vào một ô của cột Hạn xử lý 3. Double click vào ô đó | D19: Không có sự kiện nào xảy ra: không mở popup, không vào chế độ chỉnh sửa, không sửa được giá trị, không có chức năng gia hạn tại panel. | Q19: =IF(OR(IF(G19="",IF(F19="",IF(E19="","",E19),F19),G19)="F",IF(J19="",IF(I19="",IF(H19="","",H19),I19),J19)="F",IF(M19="",IF(L19="",IF(K19="","",K19),L19),M19)="F",IF(P19="",IF(O19="",IF(N19="","",N19),O19),P19)="F")=TRUE,"F",IF(OR(IF(G19="",IF(F19="",IF(E19="","",E19),F19),G19)="PE",IF(J19="",IF(I19="",IF(H19="","",H19),I19),J19)="PE",IF(M19="",IF(L19="",IF(K19="","",K19),L19),M19)="PE",IF(P19="",IF(O19="",IF(N19="","",N19),O19),P19)="PE")=TRUE,"PE",IF(AND(IF(G19="",IF(F19="",IF(E19="","",E19),F19),G19)="",IF(J19="",IF(I19="",IF(H19="","",H19),I19),J19)="",IF(M19="",IF(L19="",IF(K19="","",K19),L19),M19)="",IF(P19="",IF(O19="",IF(N19="","",N19),O19),P19)="")=TRUE,"","P")))
A20: =IF(AND(C20="",C20=""),"",$D$3&"_"&ROW()-12-COUNTBLANK($C$13:C20)) | B20: Chức năng (Phần này viết các trường hợp kiểm thử kiểm tra các ràng buộc trong cơ sở dữ liệu và cho các luồng nghiệp vụ trong tài liệu giải pháp, tích hợp với các chức năng khác)
A21: =IF(AND(C21="",C21=""),"",$D$3&"_"&ROW()-12-COUNTBLANK($C$13:C21)) | B21: Hiển thị hạn xử lý trên văn bản đến
A22: =IF(AND(C22="",C22=""),"",$D$3&"_"&ROW()-12-COUNTBLANK($C$13:C22)) | B22: Kiểm tra hiển thị hạn của dòng nhận là cá nhân | C22: 1. Chuyển VB1 cho chuyên viên A kèm hạn 15/10/2026 2. Mở chi tiết VB1 3. Mở panel người cùng nhận, xem dòng của chuyên viên A | D22: Cột Hạn xử lý của dòng chuyên viên A hiển thị đúng 15/10/2026, trùng với hạn đã nhập trong popup Chuyển văn bản. | Q22: =IF(OR(IF(G22="",IF(F22="",IF(E22="","",E22),F22),G22)="F",IF(J22="",IF(I22="",IF(H22="","",H22),I22),J22)="F",IF(M22="",IF(L22="",IF(K22="","",K22),L22),M22)="F",IF(P22="",IF(O22="",IF(N22="","",N22),O22),P22)="F")=TRUE,"F",IF(OR(IF(G22="",IF(F22="",IF(E22="","",E22),F22),G22)="PE",IF(J22="",IF(I22="",IF(H22="","",H22),I22),J22)="PE",IF(M22="",IF(L22="",IF(K22="","",K22),L22),M22)="PE",IF(P22="",IF(O22="",IF(N22="","",N22),O22),P22)="PE")=TRUE,"PE",IF(AND(IF(G22="",IF(F22="",IF(E22="","",E22),F22),G22)="",IF(J22="",IF(I22="",IF(H22="","",H22),I22),J22)="",IF(M22="",IF(L22="",IF(K22="","",K22),L22),M22)="",IF(P22="",IF(O22="",IF(N22="","",N22),O22),P22)="")=TRUE,"","P")))
A23: =IF(AND(C23="",C23=""),"",$D$3&"_"&ROW()-12-COUNTBLANK($C$13:C23)) | B23: Kiểm tra hiển thị hạn của dòng nhận là đơn vị | C23: 1. Chuyển VB3 cho một đơn vị kèm hạn 20/10/2026 2. Mở chi tiết VB3 3. Xem dòng có cột Người nhận trống, cột Đơn vị nhận có tên đơn vị | D23: Cột Hạn xử lý của dòng đơn vị hiển thị đúng 20/10/2026. Cột Người nhận vẫn để trống như hiện tại. | Q23: =IF(OR(IF(G23="",IF(F23="",IF(E23="","",E23),F23),G23)="F",IF(J23="",IF(I23="",IF(H23="","",H23),I23),J23)="F",IF(M23="",IF(L23="",IF(K23="","",K23),L23),M23)="F",IF(P23="",IF(O23="",IF(N23="","",N23),O23),P23)="F")=TRUE,"F",IF(OR(IF(G23="",IF(F23="",IF(E23="","",E23),F23),G23)="PE",IF(J23="",IF(I23="",IF(H23="","",H23),I23),J23)="PE",IF(M23="",IF(L23="",IF(K23="","",K23),L23),M23)="PE",IF(P23="",IF(O23="",IF(N23="","",N23),O23),P23)="PE")=TRUE,"PE",IF(AND(IF(G23="",IF(F23="",IF(E23="","",E23),F23),G23)="",IF(J23="",IF(I23="",IF(H23="","",H23),I23),J23)="",IF(M23="",IF(L23="",IF(K23="","",K23),L23),M23)="",IF(P23="",IF(O23="",IF(N23="","",N23),O23),P23)="")=TRUE,"","P")))
A24: =IF(AND(C24="",C24=""),"",$D$3&"_"&ROW()-12-COUNTBLANK($C$13:C24)) | B24: Kiểm tra dòng nhận không được giao hạn | C24: 1. Mở chi tiết văn bản VB2 (chuyển không nhập hạn) 2. Xem cột Hạn xử lý của dòng đó | D24: Ô Hạn xử lý để trống hoàn toàn. Không hiển thị chữ "Không có hạn", không hiển thị dấu gạch ngang, không hiển thị số 0. Không lấy hạn của sổ văn bản đến hay hạn của văn bản để điền thay. | Q24: =IF(OR(IF(G24="",IF(F24="",IF(E24="","",E24),F24),G24)="F",IF(J24="",IF(I24="",IF(H24="","",H24),I24),J24)="F",IF(M24="",IF(L24="",IF(K24="","",K24),L24),M24)="F",IF(P24="",IF(O24="",IF(N24="","",N24),O24),P24)="F")=TRUE,"F",IF(OR(IF(G24="",IF(F24="",IF(E24="","",E24),F24),G24)="PE",IF(J24="",IF(I24="",IF(H24="","",H24),I24),J24)="PE",IF(M24="",IF(L24="",IF(K24="","",K24),L24),M24)="PE",IF(P24="",IF(O24="",IF(N24="","",N24),O24),P24)="PE")=TRUE,"PE",IF(AND(IF(G24="",IF(F24="",IF(E24="","",E24),F24),G24)="",IF(J24="",IF(I24="",IF(H24="","",H24),I24),J24)="",IF(M24="",IF(L24="",IF(K24="","",K24),L24),M24)="",IF(P24="",IF(O24="",IF(N24="","",N24),O24),P24)="")=TRUE,"","P")))
A25: =IF(AND(C25="",C25=""),"",$D$3&"_"&ROW()-12-COUNTBLANK($C$13:C25)) | B25: Kiểm tra văn bản chuyển nhiều lần với nhiều hạn khác nhau | C25: 1. Mở chi tiết VB3 (lần 1 cho cá nhân hạn 10/10/2026, lần 2 cho đơn vị hạn 20/10/2026) 2. So sánh cột Hạn xử lý của từng dòng | D25: Dòng của lần chuyển 1 hiển thị 10/10/2026, dòng của lần chuyển 2 hiển thị 20/10/2026. Không dòng nào bị lấy hạn của dòng khác. Hệ thống không đồng nhất các dòng về một hạn. | Q25: =IF(OR(IF(G25="",IF(F25="",IF(E25="","",E25),F25),G25)="F",IF(J25="",IF(I25="",IF(H25="","",H25),I25),J25)="F",IF(M25="",IF(L25="",IF(K25="","",K25),L25),M25)="F",IF(P25="",IF(O25="",IF(N25="","",N25),O25),P25)="F")=TRUE,"F",IF(OR(IF(G25="",IF(F25="",IF(E25="","",E25),F25),G25)="PE",IF(J25="",IF(I25="",IF(H25="","",H25),I25),J25)="PE",IF(M25="",IF(L25="",IF(K25="","",K25),L25),M25)="PE",IF(P25="",IF(O25="",IF(N25="","",N25),O25),P25)="PE")=TRUE,"PE",IF(AND(IF(G25="",IF(F25="",IF(E25="","",E25),F25),G25)="",IF(J25="",IF(I25="",IF(H25="","",H25),I25),J25)="",IF(M25="",IF(L25="",IF(K25="","",K25),L25),M25)="",IF(P25="",IF(O25="",IF(N25="","",N25),O25),P25)="")=TRUE,"","P")))
A26: =IF(AND(C26="",C26=""),"",$D$3&"_"&ROW()-12-COUNTBLANK($C$13:C26)) | B26: Kiểm tra dòng của cấp chuyển trước trong chuỗi chuyển | C26: 1. Mở chi tiết VB9 bằng tài khoản chuyên viên nhận ở cấp 2 2. Xem dòng của cấp chuyển trước và dòng của chính mình | D26: Dòng cấp trên hiển thị hạn của cấp đó, dòng của mình hiển thị hạn của mình. Hai hạn độc lập, đúng theo từng lần chuyển. | Q26: =IF(OR(IF(G26="",IF(F26="",IF(E26="","",E26),F26),G26)="F",IF(J26="",IF(I26="",IF(H26="","",H26),I26),J26)="F",IF(M26="",IF(L26="",IF(K26="","",K26),L26),M26)="F",IF(P26="",IF(O26="",IF(N26="","",N26),O26),P26)="F")=TRUE,"F",IF(OR(IF(G26="",IF(F26="",IF(E26="","",E26),F26),G26)="PE",IF(J26="",IF(I26="",IF(H26="","",H26),I26),J26)="PE",IF(M26="",IF(L26="",IF(K26="","",K26),L26),M26)="PE",IF(P26="",IF(O26="",IF(N26="","",N26),O26),P26)="PE")=TRUE,"PE",IF(AND(IF(G26="",IF(F26="",IF(E26="","",E26),F26),G26)="",IF(J26="",IF(I26="",IF(H26="","",H26),I26),J26)="",IF(M26="",IF(L26="",IF(K26="","",K26),L26),M26)="",IF(P26="",IF(O26="",IF(N26="","",N26),O26),P26)="")=TRUE,"","P")))
A27: =IF(AND(C27="",C27=""),"",$D$3&"_"&ROW()-12-COUNTBLANK($C$13:C27)) | B27: Kiểm tra dòng đã quá hạn | C27: 1. Mở chi tiết VB4 có dòng nhận hạn nhỏ hơn ngày hiện tại 2. Quan sát dòng đó | D27: Hạn hiển thị bình thường như mọi dòng khác: không tô đỏ, không in đậm, không gắn biểu tượng cảnh báo, không có dòng chú thích quá hạn. | Q27: =IF(OR(IF(G27="",IF(F27="",IF(E27="","",E27),F27),G27)="F",IF(J27="",IF(I27="",IF(H27="","",H27),I27),J27)="F",IF(M27="",IF(L27="",IF(K27="","",K27),L27),M27)="F",IF(P27="",IF(O27="",IF(N27="","",N27),O27),P27)="F")=TRUE,"F",IF(OR(IF(G27="",IF(F27="",IF(E27="","",E27),F27),G27)="PE",IF(J27="",IF(I27="",IF(H27="","",H27),I27),J27)="PE",IF(M27="",IF(L27="",IF(K27="","",K27),L27),M27)="PE",IF(P27="",IF(O27="",IF(N27="","",N27),O27),P27)="PE")=TRUE,"PE",IF(AND(IF(G27="",IF(F27="",IF(E27="","",E27),F27),G27)="",IF(J27="",IF(I27="",IF(H27="","",H27),I27),J27)="",IF(M27="",IF(L27="",IF(K27="","",K27),L27),M27)="",IF(P27="",IF(O27="",IF(N27="","",N27),O27),P27)="")=TRUE,"","P")))
A28: =IF(AND(C28="",C28=""),"",$D$3&"_"&ROW()-12-COUNTBLANK($C$13:C28)) | B28: Đối chiếu hạn hiển thị với dữ liệu trong CSDL | C28: 1. Mở chi tiết VB3, ghi lại hạn của từng dòng 2. Chạy câu lệnh đọc: SELECT DOCUMENT_IN_STAFFID, DEADLINE_DATE FROM DOCUMENT_IN_STAFF WHERE DOCUMENTID = <id VB3>; SELECT DOCUMENT_IN_GROUP_ID, DEADLINE_DATE FROM DOCUMENT_IN_GROUP WHERE DOCUMENT_ID = <id VB3>; | D28: Hạn hiển thị trên từng dòng khớp tuyệt đối với cột DEADLINE_DATE của dòng nhận tương ứng. Dòng có DEADLINE_DATE rỗng thì ô trên màn hình để trống. | Q28: =IF(OR(IF(G28="",IF(F28="",IF(E28="","",E28),F28),G28)="F",IF(J28="",IF(I28="",IF(H28="","",H28),I28),J28)="F",IF(M28="",IF(L28="",IF(K28="","",K28),L28),M28)="F",IF(P28="",IF(O28="",IF(N28="","",N28),O28),P28)="F")=TRUE,"F",IF(OR(IF(G28="",IF(F28="",IF(E28="","",E28),F28),G28)="PE",IF(J28="",IF(I28="",IF(H28="","",H28),I28),J28)="PE",IF(M28="",IF(L28="",IF(K28="","",K28),L28),M28)="PE",IF(P28="",IF(O28="",IF(N28="","",N28),O28),P28)="PE")=TRUE,"PE",IF(AND(IF(G28="",IF(F28="",IF(E28="","",E28),F28),G28)="",IF(J28="",IF(I28="",IF(H28="","",H28),I28),J28)="",IF(M28="",IF(L28="",IF(K28="","",K28),L28),M28)="",IF(P28="",IF(O28="",IF(N28="","",N28),O28),P28)="")=TRUE,"","P"))) | S28: Điền id văn bản thật khi chạy. Chỉ dùng câu lệnh SELECT trên CSDL dùng chung.
A29: =IF(AND(C29="",C29=""),"",$D$3&"_"&ROW()-12-COUNTBLANK($C$13:C29)) | B29: Kiểm tra cột Hạn xử lý khi danh sách có nhiều trang | C29: 1. Mở chi tiết VB8 có trên 5 dòng người cùng nhận 2. Xem trang 1 3. Chuyển sang trang 2 và các trang sau | D29: Phân trang giữ nguyên 5 dòng một trang. Cột Hạn xử lý hiển thị ở mọi trang, giá trị đúng theo từng dòng, không bị lặp lại giá trị của trang trước. | Q29: =IF(OR(IF(G29="",IF(F29="",IF(E29="","",E29),F29),G29)="F",IF(J29="",IF(I29="",IF(H29="","",H29),I29),J29)="F",IF(M29="",IF(L29="",IF(K29="","",K29),L29),M29)="F",IF(P29="",IF(O29="",IF(N29="","",N29),O29),P29)="F")=TRUE,"F",IF(OR(IF(G29="",IF(F29="",IF(E29="","",E29),F29),G29)="PE",IF(J29="",IF(I29="",IF(H29="","",H29),I29),J29)="PE",IF(M29="",IF(L29="",IF(K29="","",K29),L29),M29)="PE",IF(P29="",IF(O29="",IF(N29="","",N29),O29),P29)="PE")=TRUE,"PE",IF(AND(IF(G29="",IF(F29="",IF(E29="","",E29),F29),G29)="",IF(J29="",IF(I29="",IF(H29="","",H29),I29),J29)="",IF(M29="",IF(L29="",IF(K29="","",K29),L29),M29)="",IF(P29="",IF(O29="",IF(N29="","",N29),O29),P29)="")=TRUE,"","P")))
A30: =IF(AND(C30="",C30=""),"",$D$3&"_"&ROW()-12-COUNTBLANK($C$13:C30)) | B30: Kiểm tra sau khi thu hồi một dòng đã chuyển | C30: 1. Mở chi tiết VB3 2. Thu hồi một dòng đã chuyển 3. Mở lại chi tiết và xem danh sách | D30: Dòng bị thu hồi không còn trong danh sách, đúng như hiện tại. Các dòng còn lại giữ nguyên hạn đúng của mình. | Q30: =IF(OR(IF(G30="",IF(F30="",IF(E30="","",E30),F30),G30)="F",IF(J30="",IF(I30="",IF(H30="","",H30),I30),J30)="F",IF(M30="",IF(L30="",IF(K30="","",K30),L30),M30)="F",IF(P30="",IF(O30="",IF(N30="","",N30),O30),P30)="F")=TRUE,"F",IF(OR(IF(G30="",IF(F30="",IF(E30="","",E30),F30),G30)="PE",IF(J30="",IF(I30="",IF(H30="","",H30),I30),J30)="PE",IF(M30="",IF(L30="",IF(K30="","",K30),L30),M30)="PE",IF(P30="",IF(O30="",IF(N30="","",N30),O30),P30)="PE")=TRUE,"PE",IF(AND(IF(G30="",IF(F30="",IF(E30="","",E30),F30),G30)="",IF(J30="",IF(I30="",IF(H30="","",H30),I30),J30)="",IF(M30="",IF(L30="",IF(K30="","",K30),L30),M30)="",IF(P30="",IF(O30="",IF(N30="","",N30),O30),P30)="")=TRUE,"","P")))
A31: =IF(AND(C31="",C31=""),"",$D$3&"_"&ROW()-12-COUNTBLANK($C$13:C31)) | B31: Văn bản đã ban hành
A32: =IF(AND(C32="",C32=""),"",$D$3&"_"&ROW()-12-COUNTBLANK($C$13:C32)) | B32: Kiểm tra hiển thị cột trên văn bản đã ban hành | C32: 1. Mở chi tiết văn bản VB5 đã ban hành 2. Mở panel người cùng nhận | D32: Cột Hạn xử lý vẫn hiển thị dù các dòng không có hạn. Các ô để trống. Cột không bị ẩn, không bị dồn cột. | Q32: =IF(OR(IF(G32="",IF(F32="",IF(E32="","",E32),F32),G32)="F",IF(J32="",IF(I32="",IF(H32="","",H32),I32),J32)="F",IF(M32="",IF(L32="",IF(K32="","",K32),L32),M32)="F",IF(P32="",IF(O32="",IF(N32="","",N32),O32),P32)="F")=TRUE,"F",IF(OR(IF(G32="",IF(F32="",IF(E32="","",E32),F32),G32)="PE",IF(J32="",IF(I32="",IF(H32="","",H32),I32),J32)="PE",IF(M32="",IF(L32="",IF(K32="","",K32),L32),M32)="PE",IF(P32="",IF(O32="",IF(N32="","",N32),O32),P32)="PE")=TRUE,"PE",IF(AND(IF(G32="",IF(F32="",IF(E32="","",E32),F32),G32)="",IF(J32="",IF(I32="",IF(H32="","",H32),I32),J32)="",IF(M32="",IF(L32="",IF(K32="","",K32),L32),M32)="",IF(P32="",IF(O32="",IF(N32="","",N32),O32),P32)="")=TRUE,"","P")))
A33: =IF(AND(C33="",C33=""),"",$D$3&"_"&ROW()-12-COUNTBLANK($C$13:C33)) | B33: Kiểm tra văn bản đã ban hành có dòng nhận được giao hạn | C33: 1. Chuyển tiếp VB5 cho một cá nhân kèm hạn 2. Mở lại chi tiết VB5 | D33: Dòng vừa chuyển hiển thị đúng hạn đã nhập, các dòng cũ vẫn để trống. | Q33: =IF(OR(IF(G33="",IF(F33="",IF(E33="","",E33),F33),G33)="F",IF(J33="",IF(I33="",IF(H33="","",H33),I33),J33)="F",IF(M33="",IF(L33="",IF(K33="","",K33),L33),M33)="F",IF(P33="",IF(O33="",IF(N33="","",N33),O33),P33)="F")=TRUE,"F",IF(OR(IF(G33="",IF(F33="",IF(E33="","",E33),F33),G33)="PE",IF(J33="",IF(I33="",IF(H33="","",H33),I33),J33)="PE",IF(M33="",IF(L33="",IF(K33="","",K33),L33),M33)="PE",IF(P33="",IF(O33="",IF(N33="","",N33),O33),P33)="PE")=TRUE,"PE",IF(AND(IF(G33="",IF(F33="",IF(E33="","",E33),F33),G33)="",IF(J33="",IF(I33="",IF(H33="","",H33),I33),J33)="",IF(M33="",IF(L33="",IF(K33="","",K33),L33),M33)="",IF(P33="",IF(O33="",IF(N33="","",N33),O33),P33)="")=TRUE,"","P")))
A34: =IF(AND(C34="",C34=""),"",$D$3&"_"&ROW()-12-COUNTBLANK($C$13:C34)) | B34: Các đường mở chi tiết văn bản
A35: =IF(AND(C35="",C35=""),"",$D$3&"_"&ROW()-12-COUNTBLANK($C$13:C35)) | B35: Kiểm tra mở chi tiết từ các hộp việc văn bản đến | C35: Lần lượt mở chi tiết cùng một văn bản từ: Chờ tiếp nhận, Chờ xử lý, Đã xử lý, Nhận để biết, Đề nghị trả lại, Đã trả lại, tab Tất cả | D35: Ở mọi hộp việc, panel đều có cột Hạn xử lý và giá trị giống nhau. | Q35: =IF(OR(IF(G35="",IF(F35="",IF(E35="","",E35),F35),G35)="F",IF(J35="",IF(I35="",IF(H35="","",H35),I35),J35)="F",IF(M35="",IF(L35="",IF(K35="","",K35),L35),M35)="F",IF(P35="",IF(O35="",IF(N35="","",N35),O35),P35)="F")=TRUE,"F",IF(OR(IF(G35="",IF(F35="",IF(E35="","",E35),F35),G35)="PE",IF(J35="",IF(I35="",IF(H35="","",H35),I35),J35)="PE",IF(M35="",IF(L35="",IF(K35="","",K35),L35),M35)="PE",IF(P35="",IF(O35="",IF(N35="","",N35),O35),P35)="PE")=TRUE,"PE",IF(AND(IF(G35="",IF(F35="",IF(E35="","",E35),F35),G35)="",IF(J35="",IF(I35="",IF(H35="","",H35),I35),J35)="",IF(M35="",IF(L35="",IF(K35="","",K35),L35),M35)="",IF(P35="",IF(O35="",IF(N35="","",N35),O35),P35)="")=TRUE,"","P")))
A36: =IF(AND(C36="",C36=""),"",$D$3&"_"&ROW()-12-COUNTBLANK($C$13:C36)) | B36: Kiểm tra mở chi tiết từ màn Tra cứu văn bản | C36: 1. Vào Tra cứu văn bản 2. Tìm và mở chi tiết VB3 3. Mở panel người cùng nhận | D36: Panel có cột Hạn xử lý, giá trị đúng, không lỗi màn hình. | Q36: =IF(OR(IF(G36="",IF(F36="",IF(E36="","",E36),F36),G36)="F",IF(J36="",IF(I36="",IF(H36="","",H36),I36),J36)="F",IF(M36="",IF(L36="",IF(K36="","",K36),L36),M36)="F",IF(P36="",IF(O36="",IF(N36="","",N36),O36),P36)="F")=TRUE,"F",IF(OR(IF(G36="",IF(F36="",IF(E36="","",E36),F36),G36)="PE",IF(J36="",IF(I36="",IF(H36="","",H36),I36),J36)="PE",IF(M36="",IF(L36="",IF(K36="","",K36),L36),M36)="PE",IF(P36="",IF(O36="",IF(N36="","",N36),O36),P36)="PE")=TRUE,"PE",IF(AND(IF(G36="",IF(F36="",IF(E36="","",E36),F36),G36)="",IF(J36="",IF(I36="",IF(H36="","",H36),I36),J36)="",IF(M36="",IF(L36="",IF(K36="","",K36),L36),M36)="",IF(P36="",IF(O36="",IF(N36="","",N36),O36),P36)="")=TRUE,"","P")))
A37: =IF(AND(C37="",C37=""),"",$D$3&"_"&ROW()-12-COUNTBLANK($C$13:C37)) | B37: Kiểm tra mở chi tiết từ màn Theo dõi văn bản đến đơn vị | C37: 1. Vào Theo dõi văn bản đến đơn vị bằng tài khoản lãnh đạo hoặc văn thư 2. Mở chi tiết một văn bản của đơn vị | D37: Panel có cột Hạn xử lý, giá trị đúng, không lỗi màn hình. | Q37: =IF(OR(IF(G37="",IF(F37="",IF(E37="","",E37),F37),G37)="F",IF(J37="",IF(I37="",IF(H37="","",H37),I37),J37)="F",IF(M37="",IF(L37="",IF(K37="","",K37),L37),M37)="F",IF(P37="",IF(O37="",IF(N37="","",N37),O37),P37)="F")=TRUE,"F",IF(OR(IF(G37="",IF(F37="",IF(E37="","",E37),F37),G37)="PE",IF(J37="",IF(I37="",IF(H37="","",H37),I37),J37)="PE",IF(M37="",IF(L37="",IF(K37="","",K37),L37),M37)="PE",IF(P37="",IF(O37="",IF(N37="","",N37),O37),P37)="PE")=TRUE,"PE",IF(AND(IF(G37="",IF(F37="",IF(E37="","",E37),F37),G37)="",IF(J37="",IF(I37="",IF(H37="","",H37),I37),J37)="",IF(M37="",IF(L37="",IF(K37="","",K37),L37),M37)="",IF(P37="",IF(O37="",IF(N37="","",N37),O37),P37)="")=TRUE,"","P")))
A38: =IF(AND(C38="",C38=""),"",$D$3&"_"&ROW()-12-COUNTBLANK($C$13:C38)) | B38: Kiểm tra mở chi tiết từ hồ sơ công việc và từ thông báo | C38: 1. Mở văn bản nằm trong một hồ sơ công việc 2. Mở văn bản từ chuông thông báo | D38: Cả hai đường vào đều hiển thị panel có cột Hạn xử lý, không lỗi. | Q38: =IF(OR(IF(G38="",IF(F38="",IF(E38="","",E38),F38),G38)="F",IF(J38="",IF(I38="",IF(H38="","",H38),I38),J38)="F",IF(M38="",IF(L38="",IF(K38="","",K38),L38),M38)="F",IF(P38="",IF(O38="",IF(N38="","",N38),O38),P38)="F")=TRUE,"F",IF(OR(IF(G38="",IF(F38="",IF(E38="","",E38),F38),G38)="PE",IF(J38="",IF(I38="",IF(H38="","",H38),I38),J38)="PE",IF(M38="",IF(L38="",IF(K38="","",K38),L38),M38)="PE",IF(P38="",IF(O38="",IF(N38="","",N38),O38),P38)="PE")=TRUE,"PE",IF(AND(IF(G38="",IF(F38="",IF(E38="","",E38),F38),G38)="",IF(J38="",IF(I38="",IF(H38="","",H38),I38),J38)="",IF(M38="",IF(L38="",IF(K38="","",K38),L38),M38)="",IF(P38="",IF(O38="",IF(N38="","",N38),O38),P38)="")=TRUE,"","P")))
A39: =IF(AND(C39="",C39=""),"",$D$3&"_"&ROW()-12-COUNTBLANK($C$13:C39)) | B39: Theo vai trò người xem
A40: =IF(AND(C40="",C40=""),"",$D$3&"_"&ROW()-12-COUNTBLANK($C$13:C40)) | B40: Kiểm tra hiển thị với vai trò Văn thư | C40: 1. Đăng nhập tài khoản văn thư 2. Mở chi tiết văn bản của đơn vị và văn bản cá nhân 3. Mở panel người cùng nhận | D40: Văn thư nhìn thấy cột Hạn xử lý ở cả hai loại văn bản, giá trị đúng theo từng dòng. | Q40: =IF(OR(IF(G40="",IF(F40="",IF(E40="","",E40),F40),G40)="F",IF(J40="",IF(I40="",IF(H40="","",H40),I40),J40)="F",IF(M40="",IF(L40="",IF(K40="","",K40),L40),M40)="F",IF(P40="",IF(O40="",IF(N40="","",N40),O40),P40)="F")=TRUE,"F",IF(OR(IF(G40="",IF(F40="",IF(E40="","",E40),F40),G40)="PE",IF(J40="",IF(I40="",IF(H40="","",H40),I40),J40)="PE",IF(M40="",IF(L40="",IF(K40="","",K40),L40),M40)="PE",IF(P40="",IF(O40="",IF(N40="","",N40),O40),P40)="PE")=TRUE,"PE",IF(AND(IF(G40="",IF(F40="",IF(E40="","",E40),F40),G40)="",IF(J40="",IF(I40="",IF(H40="","",H40),I40),J40)="",IF(M40="",IF(L40="",IF(K40="","",K40),L40),M40)="",IF(P40="",IF(O40="",IF(N40="","",N40),O40),P40)="")=TRUE,"","P")))
A41: =IF(AND(C41="",C41=""),"",$D$3&"_"&ROW()-12-COUNTBLANK($C$13:C41)) | B41: Kiểm tra hiển thị với vai trò Lãnh đạo | C41: 1. Đăng nhập tài khoản lãnh đạo 2. Mở chi tiết VB1 3. Mở panel người cùng nhận | D41: Lãnh đạo nhìn thấy cột Hạn xử lý với giá trị giống hệt khi xem bằng tài khoản khác. | Q41: =IF(OR(IF(G41="",IF(F41="",IF(E41="","",E41),F41),G41)="F",IF(J41="",IF(I41="",IF(H41="","",H41),I41),J41)="F",IF(M41="",IF(L41="",IF(K41="","",K41),L41),M41)="F",IF(P41="",IF(O41="",IF(N41="","",N41),O41),P41)="F")=TRUE,"F",IF(OR(IF(G41="",IF(F41="",IF(E41="","",E41),F41),G41)="PE",IF(J41="",IF(I41="",IF(H41="","",H41),I41),J41)="PE",IF(M41="",IF(L41="",IF(K41="","",K41),L41),M41)="PE",IF(P41="",IF(O41="",IF(N41="","",N41),O41),P41)="PE")=TRUE,"PE",IF(AND(IF(G41="",IF(F41="",IF(E41="","",E41),F41),G41)="",IF(J41="",IF(I41="",IF(H41="","",H41),I41),J41)="",IF(M41="",IF(L41="",IF(K41="","",K41),L41),M41)="",IF(P41="",IF(O41="",IF(N41="","",N41),O41),P41)="")=TRUE,"","P")))
...

Sheet NV_08_App
C1: KỊCH BẢN KIỂM THỬ *
C2: Tên màn hình/Tên chức năng | D2: NV_08_Thêm hạn xử lý ở Danh sách người cùng nhận
C3: Mã trường hợp kiểm thử | D3: NV_08
C4: Số trường hợp kiểm thử đạt (P) | D4: =COUNTIF($E$13:$E$30,"P")
C5: Số trường hợp kiểm thử không đạt (F) | D5: =COUNTIF($E$13:$E$30,"F")
C6: Số trường hợp kiểm thử đang xem xét (PE) | D6: =COUNTIF($Q$13:$Q$30,"PE")
C7: Số trường hợp kiểm thử chưa thực hiện | D7: =D8-D4-D5-D6
C8: Tổng số trường hợp kiểm thử | D8: =COUNTA($Q$13:$Q$30)
A10: Mã trường hợp kiểm thử | B10: Mục đích kiểm thử | C10: Các bước thực hiện | D10: Kết quả mong muốn | E10: Mobile | H10: Tablet | K10: <Tên trình duyệt 3> | N10: <Tên trình duyệt 4> | Q10: Kết quả hiện tại | R10: Mã lỗi | S10: Ghi chú
E11: Lần 1 | F11: Lần 2 | G11: Lần 3 | H11: Lần 1 | I11: Lần 2 | J11: Lần 3 | K11: Lần 1 | L11: Lần 2 | M11: Lần 3 | N11: Lần 1 | O11: Lần 2 | P11: Lần 3
B12: NV_08_Thêm hạn xử lý ở Danh sách người cùng nhận_App
B13: A: Các bước thực hiện Pre- condition: 1. Cài ứng dụng di động bản có hỗ trợ cột Hạn xử lý, trỏ về môi trường kiểm thử: <điền link môi trường test> 2. Tài khoản: Văn thư <acc VT>, Lãnh đạo <acc LĐ>, Chuyên viên <acc CV> 3. Dùng lại bộ dữ liệu VB1 đến VB9 đã chuẩn bị ở sheet Web Lưu ý: phần giao diện App phụ thuộc điểm cần chốt TBD-01 của đặc tả (đội di động xác nhận hiển thị ở đâu và từ phiên bản nào). Nếu App chưa làm trong đợt này thì để trống kết quả và ghi lý do ở cột Ghi chú. B: Mô tả chức năng Mục Người cùng nhận trong màn chi tiết văn bản trên ứng dụng di động hiển thị thêm hạn xử lý của từng dòng, theo cùng quy tắc với Web. C: Các bảng tác động - DOCUMENT_IN_STAFF, cột DEADLINE_DATE (chỉ đọc) - DOCUMENT_IN_GROUP, cột DEADLINE_DATE (chỉ đọc) Không thêm bảng, không thêm cột.
A14: =IF(AND(C14="",C14=""),"",$D$3&"_"&ROW()-12-COUNTBLANK($C$13:C14)) | B14: Giao diện (Phần này viết các trường hợp kiểm thử cho giao diên chung và các giao diện cho các control)
A15: =IF(AND(C15="",C15=""),"",$D$3&"_"&ROW()-12-COUNTBLANK($C$13:C15)) | B15: Kiểm tra tổng thể giao diện màn chi tiết văn bản trên ứng dụng | C15: 1. Mở chi tiết văn bản VB1 trên ứng dụng 2. Mở mục Người cùng nhận 3. Kiểm tra bố cục, font chữ, chính tả | D15: 1. Bố cục - Form được bố trí hợp lý và dễ sử dụng 2. Font chữ và màu chữ: - Các text sử dụng cùng 1 loại font chữ, cỡ chữ - Màu chữ giống giao diện prototype 3. Chính tả: Không có lỗi về chính tả, cấu trúc câu, ngữ pháp trên màn hình | Q15: =IF(OR(IF(G15="",IF(F15="",IF(E15="","",E15),F15),G15)="F",IF(J15="",IF(I15="",IF(H15="","",H15),I15),J15)="F",IF(M15="",IF(L15="",IF(K15="","",K15),L15),M15)="F",IF(P15="",IF(O15="",IF(N15="","",N15),O15),P15)="F")=TRUE,"F",IF(OR(IF(G15="",IF(F15="",IF(E15="","",E15),F15),G15)="PE",IF(J15="",IF(I15="",IF(H15="","",H15),I15),J15)="PE",IF(M15="",IF(L15="",IF(K15="","",K15),L15),M15)="PE",IF(P15="",IF(O15="",IF(N15="","",N15),O15),P15)="PE")=TRUE,"PE",IF(AND(IF(G15="",IF(F15="",IF(E15="","",E15),F15),G15)="",IF(J15="",IF(I15="",IF(H15="","",H15),I15),J15)="",IF(M15="",IF(L15="",IF(K15="","",K15),L15),M15)="",IF(P15="",IF(O15="",IF(N15="","",N15),O15),P15)="")=TRUE,"","P"))) | S15: Phụ thuộc TBD-01: đội di động chốt vị trí hiển thị và phiên bản áp dụng.
A16: =IF(AND(C16="",C16=""),"",$D$3&"_"&ROW()-12-COUNTBLANK($C$13:C16)) | B16: Kiểm tra vị trí hiển thị của thông tin Hạn xử lý | C16: 1. Mở chi tiết VB1 trên ứng dụng 2. Mở mục Người cùng nhận | D16: Mỗi dòng người cùng nhận hiển thị thêm thông tin Hạn xử lý, đặt cạnh thời gian chuyển, theo đúng thiết kế màn hình đã duyệt cho ứng dụng. | Q16: =IF(OR(IF(G16="",IF(F16="",IF(E16="","",E16),F16),G16)="F",IF(J16="",IF(I16="",IF(H16="","",H16),I16),J16)="F",IF(M16="",IF(L16="",IF(K16="","",K16),L16),M16)="F",IF(P16="",IF(O16="",IF(N16="","",N16),O16),P16)="F")=TRUE,"F",IF(OR(IF(G16="",IF(F16="",IF(E16="","",E16),F16),G16)="PE",IF(J16="",IF(I16="",IF(H16="","",H16),I16),J16)="PE",IF(M16="",IF(L16="",IF(K16="","",K16),L16),M16)="PE",IF(P16="",IF(O16="",IF(N16="","",N16),O16),P16)="PE")=TRUE,"PE",IF(AND(IF(G16="",IF(F16="",IF(E16="","",E16),F16),G16)="",IF(J16="",IF(I16="",IF(H16="","",H16),I16),J16)="",IF(M16="",IF(L16="",IF(K16="","",K16),L16),M16)="",IF(P16="",IF(O16="",IF(N16="","",N16),O16),P16)="")=TRUE,"","P"))) | S16: Phụ thuộc TBD-01: đội di động chốt vị trí hiển thị và phiên bản áp dụng.
A17: =IF(AND(C17="",C17=""),"",$D$3&"_"&ROW()-12-COUNTBLANK($C$13:C17)) | B17: Kiểm tra định dạng ngày của hạn xử lý | C17: 1. Mở chi tiết VB1 2. Quan sát giá trị hạn | D17: Hạn hiển thị dạng dd/MM/yyyy, không có giờ phút, giống Web. | Q17: =IF(OR(IF(G17="",IF(F17="",IF(E17="","",E17),F17),G17)="F",IF(J17="",IF(I17="",IF(H17="","",H17),I17),J17)="F",IF(M17="",IF(L17="",IF(K17="","",K17),L17),M17)="F",IF(P17="",IF(O17="",IF(N17="","",N17),O17),P17)="F")=TRUE,"F",IF(OR(IF(G17="",IF(F17="",IF(E17="","",E17),F17),G17)="PE",IF(J17="",IF(I17="",IF(H17="","",H17),I17),J17)="PE",IF(M17="",IF(L17="",IF(K17="","",K17),L17),M17)="PE",IF(P17="",IF(O17="",IF(N17="","",N17),O17),P17)="PE")=TRUE,"PE",IF(AND(IF(G17="",IF(F17="",IF(E17="","",E17),F17),G17)="",IF(J17="",IF(I17="",IF(H17="","",H17),I17),J17)="",IF(M17="",IF(L17="",IF(K17="","",K17),L17),M17)="",IF(P17="",IF(O17="",IF(N17="","",N17),O17),P17)="")=TRUE,"","P"))) | S17: Phụ thuộc TBD-01: đội di động chốt vị trí hiển thị và phiên bản áp dụng.
A18: =IF(AND(C18="",C18=""),"",$D$3&"_"&ROW()-12-COUNTBLANK($C$13:C18)) | B18: Chức năng (Phần này viết các trường hợp kiểm thử kiểm tra các ràng buộc trong cơ sở dữ liệu và cho các luồng nghiệp vụ trong tài liệu giải pháp, tích hợp với các chức năng khác)
A19: =IF(AND(C19="",C19=""),"",$D$3&"_"&ROW()-12-COUNTBLANK($C$13:C19)) | B19: Hiển thị hạn xử lý
A20: =IF(AND(C20="",C20=""),"",$D$3&"_"&ROW()-12-COUNTBLANK($C$13:C20)) | B20: Kiểm tra hạn của dòng nhận là cá nhân | C20: 1. Mở chi tiết VB1 trên ứng dụng 2. Xem dòng của chuyên viên A | D20: Hiển thị đúng hạn đã nhập khi chuyển, trùng với giá trị hiển thị trên Web. | Q20: =IF(OR(IF(G20="",IF(F20="",IF(E20="","",E20),F20),G20)="F",IF(J20="",IF(I20="",IF(H20="","",H20),I20),J20)="F",IF(M20="",IF(L20="",IF(K20="","",K20),L20),M20)="F",IF(P20="",IF(O20="",IF(N20="","",N20),O20),P20)="F")=TRUE,"F",IF(OR(IF(G20="",IF(F20="",IF(E20="","",E20),F20),G20)="PE",IF(J20="",IF(I20="",IF(H20="","",H20),I20),J20)="PE",IF(M20="",IF(L20="",IF(K20="","",K20),L20),M20)="PE",IF(P20="",IF(O20="",IF(N20="","",N20),O20),P20)="PE")=TRUE,"PE",IF(AND(IF(G20="",IF(F20="",IF(E20="","",E20),F20),G20)="",IF(J20="",IF(I20="",IF(H20="","",H20),I20),J20)="",IF(M20="",IF(L20="",IF(K20="","",K20),L20),M20)="",IF(P20="",IF(O20="",IF(N20="","",N20),O20),P20)="")=TRUE,"","P"))) | S20: Phụ thuộc TBD-01: đội di động chốt vị trí hiển thị và phiên bản áp dụng.
A21: =IF(AND(C21="",C21=""),"",$D$3&"_"&ROW()-12-COUNTBLANK($C$13:C21)) | B21: Kiểm tra hạn của dòng nhận là đơn vị | C21: 1. Mở chi tiết VB3 trên ứng dụng 2. Xem dòng của đơn vị nhận | D21: Hiển thị đúng hạn giao cho đơn vị đó, trùng với giá trị trên Web. | Q21: =IF(OR(IF(G21="",IF(F21="",IF(E21="","",E21),F21),G21)="F",IF(J21="",IF(I21="",IF(H21="","",H21),I21),J21)="F",IF(M21="",IF(L21="",IF(K21="","",K21),L21),M21)="F",IF(P21="",IF(O21="",IF(N21="","",N21),O21),P21)="F")=TRUE,"F",IF(OR(IF(G21="",IF(F21="",IF(E21="","",E21),F21),G21)="PE",IF(J21="",IF(I21="",IF(H21="","",H21),I21),J21)="PE",IF(M21="",IF(L21="",IF(K21="","",K21),L21),M21)="PE",IF(P21="",IF(O21="",IF(N21="","",N21),O21),P21)="PE")=TRUE,"PE",IF(AND(IF(G21="",IF(F21="",IF(E21="","",E21),F21),G21)="",IF(J21="",IF(I21="",IF(H21="","",H21),I21),J21)="",IF(M21="",IF(L21="",IF(K21="","",K21),L21),M21)="",IF(P21="",IF(O21="",IF(N21="","",N21),O21),P21)="")=TRUE,"","P"))) | S21: Phụ thuộc TBD-01: đội di động chốt vị trí hiển thị và phiên bản áp dụng.
A22: =IF(AND(C22="",C22=""),"",$D$3&"_"&ROW()-12-COUNTBLANK($C$13:C22)) | B22: Kiểm tra dòng không được giao hạn | C22: 1. Mở chi tiết VB2 trên ứng dụng 2. Xem dòng đó | D22: Chỗ hiển thị hạn để trống, không hiện chữ thay thế, không hiện ngày mặc định. | Q22: =IF(OR(IF(G22="",IF(F22="",IF(E22="","",E22),F22),G22)="F",IF(J22="",IF(I22="",IF(H22="","",H22),I22),J22)="F",IF(M22="",IF(L22="",IF(K22="","",K22),L22),M22)="F",IF(P22="",IF(O22="",IF(N22="","",N22),O22),P22)="F")=TRUE,"F",IF(OR(IF(G22="",IF(F22="",IF(E22="","",E22),F22),G22)="PE",IF(J22="",IF(I22="",IF(H22="","",H22),I22),J22)="PE",IF(M22="",IF(L22="",IF(K22="","",K22),L22),M22)="PE",IF(P22="",IF(O22="",IF(N22="","",N22),O22),P22)="PE")=TRUE,"PE",IF(AND(IF(G22="",IF(F22="",IF(E22="","",E22),F22),G22)="",IF(J22="",IF(I22="",IF(H22="","",H22),I22),J22)="",IF(M22="",IF(L22="",IF(K22="","",K22),L22),M22)="",IF(P22="",IF(O22="",IF(N22="","",N22),O22),P22)="")=TRUE,"","P"))) | S22: Phụ thuộc TBD-01: đội di động chốt vị trí hiển thị và phiên bản áp dụng.
A23: =IF(AND(C23="",C23=""),"",$D$3&"_"&ROW()-12-COUNTBLANK($C$13:C23)) | B23: Kiểm tra văn bản chuyển nhiều lần với nhiều hạn khác nhau | C23: 1. Mở chi tiết VB3 trên ứng dụng 2. So sánh hạn giữa các dòng | D23: Mỗi dòng giữ hạn riêng, giống kết quả trên Web. | Q23: =IF(OR(IF(G23="",IF(F23="",IF(E23="","",E23),F23),G23)="F",IF(J23="",IF(I23="",IF(H23="","",H23),I23),J23)="F",IF(M23="",IF(L23="",IF(K23="","",K23),L23),M23)="F",IF(P23="",IF(O23="",IF(N23="","",N23),O23),P23)="F")=TRUE,"F",IF(OR(IF(G23="",IF(F23="",IF(E23="","",E23),F23),G23)="PE",IF(J23="",IF(I23="",IF(H23="","",H23),I23),J23)="PE",IF(M23="",IF(L23="",IF(K23="","",K23),L23),M23)="PE",IF(P23="",IF(O23="",IF(N23="","",N23),O23),P23)="PE")=TRUE,"PE",IF(AND(IF(G23="",IF(F23="",IF(E23="","",E23),F23),G23)="",IF(J23="",IF(I23="",IF(H23="","",H23),I23),J23)="",IF(M23="",IF(L23="",IF(K23="","",K23),L23),M23)="",IF(P23="",IF(O23="",IF(N23="","",N23),O23),P23)="")=TRUE,"","P"))) | S23: Phụ thuộc TBD-01: đội di động chốt vị trí hiển thị và phiên bản áp dụng.
A24: =IF(AND(C24="",C24=""),"",$D$3&"_"&ROW()-12-COUNTBLANK($C$13:C24)) | B24: Kiểm tra văn bản đã ban hành | C24: 1. Mở chi tiết VB5 trên ứng dụng 2. Xem mục Người cùng nhận | D24: Mục vẫn hiển thị, phần hạn để trống, không lỗi hiển thị. | Q24: =IF(OR(IF(G24="",IF(F24="",IF(E24="","",E24),F24),G24)="F",IF(J24="",IF(I24="",IF(H24="","",H24),I24),J24)="F",IF(M24="",IF(L24="",IF(K24="","",K24),L24),M24)="F",IF(P24="",IF(O24="",IF(N24="","",N24),O24),P24)="F")=TRUE,"F",IF(OR(IF(G24="",IF(F24="",IF(E24="","",E24),F24),G24)="PE",IF(J24="",IF(I24="",IF(H24="","",H24),I24),J24)="PE",IF(M24="",IF(L24="",IF(K24="","",K24),L24),M24)="PE",IF(P24="",IF(O24="",IF(N24="","",N24),O24),P24)="PE")=TRUE,"PE",IF(AND(IF(G24="",IF(F24="",IF(E24="","",E24),F24),G24)="",IF(J24="",IF(I24="",IF(H24="","",H24),I24),J24)="",IF(M24="",IF(L24="",IF(K24="","",K24),L24),M24)="",IF(P24="",IF(O24="",IF(N24="","",N24),O24),P24)="")=TRUE,"","P"))) | S24: Phụ thuộc TBD-01: đội di động chốt vị trí hiển thị và phiên bản áp dụng.
A25: =IF(AND(C25="",C25=""),"",$D$3&"_"&ROW()-12-COUNTBLANK($C$13:C25)) | B25: Kiểm tra theo vai trò người xem | C25: 1. Lần lượt đăng nhập tài khoản văn thư, lãnh đạo, chuyên viên 2. Mở chi tiết VB1 | D25: Cả ba vai trò đều thấy hạn xử lý với giá trị giống nhau. | Q25: =IF(OR(IF(G25="",IF(F25="",IF(E25="","",E25),F25),G25)="F",IF(J25="",IF(I25="",IF(H25="","",H25),I25),J25)="F",IF(M25="",IF(L25="",IF(K25="","",K25),L25),M25)="F",IF(P25="",IF(O25="",IF(N25="","",N25),O25),P25)="F")=TRUE,"F",IF(OR(IF(G25="",IF(F25="",IF(E25="","",E25),F25),G25)="PE",IF(J25="",IF(I25="",IF(H25="","",H25),I25),J25)="PE",IF(M25="",IF(L25="",IF(K25="","",K25),L25),M25)="PE",IF(P25="",IF(O25="",IF(N25="","",N25),O25),P25)="PE")=TRUE,"PE",IF(AND(IF(G25="",IF(F25="",IF(E25="","",E25),F25),G25)="",IF(J25="",IF(I25="",IF(H25="","",H25),I25),J25)="",IF(M25="",IF(L25="",IF(K25="","",K25),L25),M25)="",IF(P25="",IF(O25="",IF(N25="","",N25),O25),P25)="")=TRUE,"","P"))) | S25: Phụ thuộc TBD-01: đội di động chốt vị trí hiển thị và phiên bản áp dụng.
A26: =IF(AND(C26="",C26=""),"",$D$3&"_"&ROW()-12-COUNTBLANK($C$13:C26)) | B26: An toàn thông tin (Các trường hợp kiểm thử đảm bảo an toàn thông tin theo hướng dẫn kiểm thử an toàn thông tin)
A27: =IF(AND(C27="",C27=""),"",$D$3&"_"&ROW()-12-COUNTBLANK($C$13:C27)) | B27: N/A - Chỉ bổ sung một thông tin hiển thị chỉ đọc, không thêm ô nhập liệu trên ứng dụng.
A28: =IF(AND(C28="",C28=""),"",$D$3&"_"&ROW()-12-COUNTBLANK($C$13:C28)) | B28: Kiểm tra ảnh hưởng (Các trường hợp kiểm thử ảnh hưởng từ chức năng)
A29: =IF(AND(C29="",C29=""),"",$D$3&"_"&ROW()-12-COUNTBLANK($C$13:C29)) | B29: Kiểm tra tương thích với bản ứng dụng cũ | C29: 1. Dùng bản ứng dụng hiện hành chưa cập nhật 2. Mở chi tiết văn bản VB1 và VB3 | D29: Ứng dụng mở chi tiết văn bản bình thường, không văng, không báo lỗi. Chỉ không hiển thị hạn xử lý, các thông tin khác đầy đủ như trước. | Q29: =IF(OR(IF(G29="",IF(F29="",IF(E29="","",E29),F29),G29)="F",IF(J29="",IF(I29="",IF(H29="","",H29),I29),J29)="F",IF(M29="",IF(L29="",IF(K29="","",K29),L29),M29)="F",IF(P29="",IF(O29="",IF(N29="","",N29),O29),P29)="F")=TRUE,"F",IF(OR(IF(G29="",IF(F29="",IF(E29="","",E29),F29),G29)="PE",IF(J29="",IF(I29="",IF(H29="","",H29),I29),J29)="PE",IF(M29="",IF(L29="",IF(K29="","",K29),L29),M29)="PE",IF(P29="",IF(O29="",IF(N29="","",N29),O29),P29)="PE")=TRUE,"PE",IF(AND(IF(G29="",IF(F29="",IF(E29="","",E29),F29),G29)="",IF(J29="",IF(I29="",IF(H29="","",H29),I29),J29)="",IF(M29="",IF(L29="",IF(K29="","",K29),L29),M29)="",IF(P29="",IF(O29="",IF(N29="","",N29),O29),P29)="")=TRUE,"","P"))) | S29: Phụ thuộc TBD-01: đội di động chốt vị trí hiển thị và phiên bản áp dụng.
A30: =IF(AND(C30="",C30=""),"",$D$3&"_"&ROW()-12-COUNTBLANK($C$13:C30)) | B30: Kiểm tra các đường mở chi tiết văn bản trên ứng dụng | C30: 1. Mở từ danh sách văn bản đến 2. Mở từ thông báo đẩy 3. Mở từ trang chủ | D30: Cả ba đường vào đều mở được chi tiết, mục Người cùng nhận hiển thị đúng, không lỗi. | Q30: =IF(OR(IF(G30="",IF(F30="",IF(E30="","",E30),F30),G30)="F",IF(J30="",IF(I30="",IF(H30="","",H30),I30),J30)="F",IF(M30="",IF(L30="",IF(K30="","",K30),L30),M30)="F",IF(P30="",IF(O30="",IF(N30="","",N30),O30),P30)="F")=TRUE,"F",IF(OR(IF(G30="",IF(F30="",IF(E30="","",E30),F30),G30)="PE",IF(J30="",IF(I30="",IF(H30="","",H30),I30),J30)="PE",IF(M30="",IF(L30="",IF(K30="","",K30),L30),M30)="PE",IF(P30="",IF(O30="",IF(N30="","",N30),O30),P30)="PE")=TRUE,"PE",IF(AND(IF(G30="",IF(F30="",IF(E30="","",E30),F30),G30)="",IF(J30="",IF(I30="",IF(H30="","",H30),I30),J30)="",IF(M30="",IF(L30="",IF(K30="","",K30),L30),M30)="",IF(P30="",IF(O30="",IF(N30="","",N30),O30),P30)="")=TRUE,"","P"))) | S30: Phụ thuộc TBD-01: đội di động chốt vị trí hiển thị và phiên bản áp dụng.
